Workbook
Name ANALISE2: #REF!
Name ANALISE2: #REF!
Name ANALISE2: #REF!
Name ANALISE2: #REF!
Name ANALISE2: #REF!
Name ANALISE2: #REF!
Name CalendárioAno1: #REF!
Name CalendárioAno1: #REF!
Name CalendárioAno1: #REF!
Name CalendárioAno1: #REF!
Name CalendárioAno10: #REF!
Name CalendárioAno10: #REF!
Name CalendárioAno10: #REF!
Name CalendárioAno10: #REF!
Name CalendárioAno11: #REF!
Name CalendárioAno11: #REF!
Name CalendárioAno11: #REF!
Name CalendárioAno11: #REF!
Name CalendárioAno12: #REF!
Name CalendárioAno12: #REF!
Name CalendárioAno12: #REF!
Name CalendárioAno12: #REF!
Name CalendárioAno2: #REF!
Name CalendárioAno2: #REF!
Name CalendárioAno2: #REF!
Name CalendárioAno2: #REF!
Name CalendárioAno3: #REF!
Name CalendárioAno3: #REF!
Name CalendárioAno3: #REF!
Name CalendárioAno3: #REF!
Name CalendárioAno4: #REF!
Name CalendárioAno4: #REF!
Name CalendárioAno4: #REF!
Name CalendárioAno4: #REF!
Name CalendárioAno5: #REF!
Name CalendárioAno5: #REF!
Name CalendárioAno5: #REF!
Name CalendárioAno5: #REF!
Name CalendárioAno6: #REF!
Name CalendárioAno6: #REF!
Name CalendárioAno6: #REF!
Name CalendárioAno6: #REF!
Name CalendárioAno7: #REF!
Name CalendárioAno7: #REF!
Name CalendárioAno7: #REF!
Name CalendárioAno7: #REF!
Name CalendárioAno8: #REF!
Name CalendárioAno8: #REF!
Name CalendárioAno8: #REF!
Name CalendárioAno8: #REF!
Name CalendárioAno9: #REF!
Name CalendárioAno9: #REF!
Name CalendárioAno9: #REF!
Name CalendárioAno9: #REF!
Name CaléndárioMês1: #REF!
Name CaléndárioMês1: #REF!
Name CaléndárioMês1: #REF!
Name CaléndárioMês1: #REF!
Name CaléndárioMês10: #REF!
Name CaléndárioMês10: #REF!

Sheet ANÁLISE GERAL ITAPIPOCA
C2: ITAPIPOCA | Q2: Itapipoca
D3: JAN | E3: FEV | F3: MAR | G3: ABR | H3: MAI | I3: JUN | J3: JUL | K3: AGO | L3: SET | M3: OUT | N3: NOV | O3: DEZ | P3: TOTAL | Q3: Ano | R3: Fat. Máx | S3: Fat. Mín | T3: Média de Faturamento | U3: Tícket Médio | V3: Peças por Atendimento
C4: 2023 | D4: 19874 | E4: 14184.94 | F4: 31306.95 | G4: 24315 | H4: 61782.5 | I4: 42011 | J4: 33355 | K4: 41895 | L4: 33729.1 | M4: 32190 | N4: 66009 | O4: 93436 | P4: =SUM(D4:O4) -> 494088.49 | Q4: 2023 | R4: =MAX(D4:O4) -> 93436 | S4: =MIN(D4:O4) -> 14184.94 | T4: =AVERAGE(D4:O4) -> 41174.041
C5: 2024 | D5: 18528 | E5: 25658.7 | F5: 48575.6 | G5: 66407.9 | H5: 68016.9 | I5: 53766.9 | J5: 76693 | K5: 55215.5 | L5: =104015.6-60621 -> 43394.6 | M5: 30796 | N5: 69122.2 | O5: 108361.6 | P5: =SUM(D5:O5) -> 664536.9 | Q5: 2024 | R5: =MAX(D5:O5) -> 108361.6 | S5: =MIN(D5:O5) -> 18528 | T5: =AVERAGE(D5:O5) -> 55378.075
C6: TAXA DE CRESCIMENTO 2023/2024 | D6: =D5/D4-1 -> -0.067726678 | E6: =E5/E4-1 -> 0.80886912 | F6: =F5/F4-1 -> 0.55159158 | G6: =G5/G4-1 -> 1.7311495 | H6: =H5/H4-1 -> 0.10090883 | I6: =I5/I4-1 -> 0.27982909 | J6: =J5/J4-1 -> 1.2992955 | K6: =K5/K4-1 -> 0.31794964 | ... P6: =P5/P4-1 -> 0.34497547 | Q6: 2025 | R6: =MAX(D9:O9) -> 215342.03 | S6: =MIN(D9:O9) -> 19820 | T6: =AVERAGE(D9:K9) -> 64475.35 | U6: 288.94 | V6: 1.991
C7: TAXA DE CRESCIMENTO ESPERADA 2025 | D7: 0.2 | E7: 0.2 | F7: 0.2 | G7: 0.2 | H7: 0.2 | I7: 0.2 | J7: 0.2 | K7: 0.2 | L7: 0.2 | M7: 0.2 | N7: 0.2 | O7: 0.2 | P7: 0.2
C8: FATURAMENTO ESPERADO 2025 | D8: =D5*(100%+D7) -> 22233.6 | E8: =E5*(100%+E7) -> 30790.44 | F8: =F5*(100%+F7) -> 58290.72 | G8: =G5*(100%+G7) -> 79689.48 | H8: =H5*(100%+H7) -> 81620.28 | I8: =I5*(100%+I7) -> 64520.28 | J8: =J5*(100%+J7) -> 92031.6 | K8: =K5*(100%+K7) -> 66258.6 | ... P8: =P5*(100%+P7) -> 797444.28
C9: FATURAMENTO REAL | D9: 19820 | E9: 35317 | F9: 38451.9 | G9: 82472.9 | H9: 99000 | I9: 62464 | J9: 101707.4 | K9: 76569.6 | L9: 37405.7 | M9: 77294 | N9: 109996.8 | O9: 215342.03 | P9: =SUM(D9:O9)+Q10 -> 1222683.3 | Q9: =P9/P5-1 -> 0.83990284
C10: DIFRENÇA | D10: =D9/D8-1 -> -0.10855642 | E10: =E9/E8-1 -> 0.14701186 | F10: =F9/F8-1 -> -0.34034268 | G10: =G9/G8-1 -> 0.034928324 | H10: =H9/H8-1 -> 0.21293384 | I10: =I9/I8-1 -> -0.031870289 | J10: =J9/J8-1 -> 0.10513563 | K10: =K9/K8-1 -> 0.15561753 | ... P10: =P9/P8-1 -> 0.53325237 | Q10: 266842
R12: 2024 | S12: JAN - JUL | T12: =SUM(D5:K5) -> 412862.5
D13: JAN | E13: FEV | F13: MAR | G13: ABR | H13: MAI | I13: JUN | J13: JUL | K13: AGO | L13: SET | M13: OUT | N13: NOV | O13: DEZ | R13: 2025 | S13: JAN - JUL | T13: =P9 -> 1222683.3 | U13: =T13/T12 -> 2.9614783
C14: MÍNIMA | D14: 15000 | E14: 25000 | F14: 45000 | G14: 30000 | H14: 40000 | I14: 40000 | J14: 40000 | K14: 30000 | L14: 30000 | M14: 30000 | N14: 30000 | O14: 50000
C15: TOP 1 | D15: 20000 | E15: 35000 | F15: 55000 | G15: 40000 | H15: 50000 | I15: 60000 | J15: 50000 | K15: 40000 | L15: 40000 | M15: 40000 | N15: 50000 | O15: 80000 | R15: 2025 | S15: JAN - JUL | T15: =SUM(D8:K8) -> 495435 | U15: =T13/T15 -> 2.4678986
C16: TOP 2 | D16: 25000 | E16: 45000 | F16: 65000 | G16: 50000 | H16: 60000 | I16: 80000 | J16: 60000 | K16: 50000 | L16: 50000 | M16: 50000 | N16: 70000 | O16: 130000
C17: MASTER | D17: 30000 | E17: 50000 | F17: 80000 | G17: 60000 | H17: 80000 | I17: 100000 | J17: 80000 | K17: 60000 | L17: 60000 | M17: 70000 | N17: 90000 | O17: 180000
C19: MÍNIMA | D19: =IF($D$9>D14,"BATEU","NÃO BATEU") -> BATEU | E19: =IF($E$9>E14,"BATEU","NÃO BATEU") -> BATEU | F19: =IF($F$9>F14,"BATEU","NÃO BATEU") -> NÃO BATEU | G19: =IF($G$9>G14,"BATEU","NÃO BATEU") -> BATEU | H19: =IF($H$9>H14,"BATEU","NÃO BATEU") -> BATEU | I19: =IF($I$9>I14,"BATEU","NÃO BATEU") -> BATEU | J19: =IF($J$9>J14,"BATEU","NÃO BATEU") -> BATEU | K19: =IF($K$9>K14,"BATEU","NÃO BATEU") -> BATEU | L19: =IF($L$9>L14,"BATEU","NÃO BATEU") -> BATEU | M19: =IF($M$9>M14,"BATEU","NÃO BATEU") -> BATEU | N19: =IF($N$9>N14,"BATEU","NÃO BATEU") -> BATEU | O19: =IF($O$9>O14,"BATEU","NÃO BATEU") -> BATEU
C20: TOP 1 | D20: =IF($D$9>D15,"BATEU","NÃO BATEU") -> NÃO BATEU | E20: =IF($E$9>E15,"BATEU","NÃO BATEU") -> BATEU | F20: =IF($F$9>F15,"BATEU","NÃO BATEU") -> NÃO BATEU | G20: =IF($G$9>G15,"BATEU","NÃO BATEU") -> BATEU | H20: =IF($H$9>H15,"BATEU","NÃO BATEU") -> BATEU | I20: =IF($I$9>I15,"BATEU","NÃO BATEU") -> BATEU | J20: =IF($J$9>J15,"BATEU","NÃO BATEU") -> BATEU | K20: =IF($K$9>K15,"BATEU","NÃO BATEU") -> BATEU | L20: =IF($L$9>L15,"BATEU","NÃO BATEU") -> NÃO BATEU | M20: =IF($M$9>M15,"BATEU","NÃO BATEU") -> BATEU | N20: =IF($N$9>N15,"BATEU","NÃO BATEU") -> BATEU | O20: =IF($O$9>O15,"BATEU","NÃO BATEU") -> BATEU
C21: TOP 2 | D21: =IF($D$9>D16,"BATEU","NÃO BATEU") -> NÃO BATEU | E21: =IF($E$9>E16,"BATEU","NÃO BATEU") -> NÃO BATEU | F21: =IF($F$9>F16,"BATEU","NÃO BATEU") -> NÃO BATEU | G21: =IF($G$9>G16,"BATEU","NÃO BATEU") -> BATEU | H21: =IF($H$9>H16,"BATEU","NÃO BATEU") -> BATEU | I21: =IF($I$9>I16,"BATEU","NÃO BATEU") -> NÃO BATEU | J21: =IF($J$9>J16,"BATEU","NÃO BATEU") -> BATEU | K21: =IF($K$9>K16,"BATEU","NÃO BATEU") -> BATEU | L21: =IF($L$9>L16,"BATEU","NÃO BATEU") -> NÃO BATEU | M21: =IF($M$9>M16,"BATEU","NÃO BATEU") -> BATEU | N21: =IF($N$9>N16,"BATEU","NÃO BATEU") -> BATEU | O21: =IF($O$9>O16,"BATEU","NÃO BATEU") -> BATEU
C22: MASTER | D22: =IF($D$9>D17,"BATEU","NÃO BATEU") -> NÃO BATEU | E22: =IF($E$9>E17,"BATEU","NÃO BATEU") -> NÃO BATEU | F22: =IF($F$9>F17,"BATEU","NÃO BATEU") -> NÃO BATEU | G22: =IF($G$9>G17,"BATEU","NÃO BATEU") -> BATEU | H22: =IF($H$9>H17,"BATEU","NÃO BATEU") -> BATEU | I22: =IF($I$9>I17,"BATEU","NÃO BATEU") -> NÃO BATEU | J22: =IF($J$9>J17,"BATEU","NÃO BATEU") -> BATEU | K22: =IF($K$9>K17,"BATEU","NÃO BATEU") -> BATEU | L22: =IF($L$9>L17,"BATEU","NÃO BATEU") -> NÃO BATEU | M22: =IF($M$9>M17,"BATEU","NÃO BATEU") -> BATEU | N22: =IF($N$9>N17,"BATEU","NÃO BATEU") -> BATEU | O22: =IF($O$9>O17,"BATEU","NÃO BATEU") -> BATEU
N24: NOV | O24: DEZ - Individual | P24: DEZ - Geral
N25: =N14/3 -> 10000 | O25: 16700 | P25: 50000
N26: 17000 | O26: 26700 | P26: 80000
N27: 23500 | O27: 43400 | P27: 130000
N28: =N17/3 -> 30000 | O28: =O17/3 -> 60000 | P28: 180000

Sheet METAS - ITAPIPOCA
B2: VENDAS - METAS INDIVIDUAIS
B3: META MÍNIMA | C3: TOP 1 | D3: TOP 2 | E3: MASTER
B4: =VENDAS_VENDEDOR!J3 -> 13333.333 | C4: =VENDAS_VENDEDOR!K3 -> 16666.667 | D4: =VENDAS_VENDEDOR!L3 -> 20000 | E4: =VENDAS_VENDEDOR!M3 -> 26666.667
B6: VENDAS - ONLINE
B7: META MÍNIMA | C7: TOP 1 | D7: TOP 2 | E7: MASTER
B8: =VENDAS_VENDEDOR!O3 -> 0 | C8: =VENDAS_VENDEDOR!P3 -> 0 | D8: =VENDAS_VENDEDOR!Q3 -> 0 | E8: =VENDAS_VENDEDOR!R3 -> 0
B10: MÍNIMO
B11: MÍNIMA | C11: =H32 -> TOTAL
B12: SEMANA 1 | E12: SEMANA 2 | H12: SEMANA 3
B13: DOMINGO | C13: =ITAPIPOCA!O36 | E13: DOMINGO | F13: =ITAPIPOCA!R36 | H13: DOMINGO | I13: =ITAPIPOCA!U36 -> 0
B14: SEGUNDA-FEIRA | C14: =ITAPIPOCA!O37 | E14: SEGUNDA-FEIRA | F14: =ITAPIPOCA!R37 -> 1463.3179 | H14: SEGUNDA-FEIRA | I14: =ITAPIPOCA!U37 -> 1463.3179
B15: TERÇA-FEIRA | C15: =ITAPIPOCA!O38 | E15: TERÇA-FEIRA | F15: =ITAPIPOCA!R38 -> 1283.5179 | H15: TERÇA-FEIRA | I15: =ITAPIPOCA!U38 -> 1283.5179
B16: QUARTA-FEIRA | C16: =ITAPIPOCA!O39 -> 816.83042 | E16: QUARTA-FEIRA | F16: =ITAPIPOCA!R39 -> 816.83042 | H16: QUARTA-FEIRA | I16: =ITAPIPOCA!U39 -> 816.83042
B17: QUINTA-FEIRA | C17: =ITAPIPOCA!O40 -> 1528.5557 | E17: QUINTA-FEIRA | F17: =ITAPIPOCA!R40 -> 1528.5557 | H17: QUINTA-FEIRA | I17: =ITAPIPOCA!U40 -> 1528.5557
B18: SEXTA-FEIRA | C18: =ITAPIPOCA!O41 -> 2893.2242 | E18: SEXTA-FEIRA | F18: =ITAPIPOCA!R41 -> 2893.2242 | H18: SEXTA-FEIRA | I18: =ITAPIPOCA!U41 -> 2893.2242
B19: SÁBADO | C19: =ITAPIPOCA!O42 -> 1428.2074 | E19: SÁBADO | F19: =ITAPIPOCA!R42 -> 1428.2074 | H19: SÁBADO | I19: =ITAPIPOCA!U42 -> 1428.2074
B21: TOTAL | C21: =SUM(C14:C19) -> 6666.8177 | E21: TOTAL | F21: =SUM(F14:F19) -> 9413.6535 | H21: TOTAL | I21: =SUM(I14:I19) -> 9413.6535
B23: SEMANA 4 | E23: SEMANA 5 | H23: SEMANA 6
B24: DOMINGO | C24: =ITAPIPOCA!O47 -> 0 | E24: DOMINGO | F24: =ITAPIPOCA!R47 -> 0 | H24: DOMINGO | I24: =ITAPIPOCA!U47 -> 0
B25: SEGUNDA-FEIRA | C25: =ITAPIPOCA!O48 -> 1463.3179 | E25: SEGUNDA-FEIRA | F25: =ITAPIPOCA!R48 -> 1463.3179 | H25: SEGUNDA-FEIRA | I25: =ITAPIPOCA!U48
B26: TERÇA-FEIRA | C26: =ITAPIPOCA!O49 -> 1283.5179 | E26: TERÇA-FEIRA | F26: =ITAPIPOCA!R49 -> 1283.5179 | H26: TERÇA-FEIRA | I26: =ITAPIPOCA!U49
B27: QUARTA-FEIRA | C27: =ITAPIPOCA!O50 -> 816.83042 | E27: QUARTA-FEIRA | F27: =ITAPIPOCA!R50 -> 816.83042 | H27: QUARTA-FEIRA | I27: =ITAPIPOCA!U50
B28: QUINTA-FEIRA | C28: =ITAPIPOCA!O51 -> 1528.5557 | E28: QUINTA-FEIRA | F28: =ITAPIPOCA!R51 -> 1528.5557 | H28: QUINTA-FEIRA | I28: =ITAPIPOCA!U51
B29: SEXTA-FEIRA | C29: =ITAPIPOCA!O52 -> 2893.2242 | E29: SEXTA-FEIRA | F29: =ITAPIPOCA!R52 | H29: SEXTA-FEIRA | I29: =ITAPIPOCA!U52
B30: SÁBADO | C30: =ITAPIPOCA!O53 -> 1428.2074 | E30: SÁBADO | F30: =ITAPIPOCA!R53 | H30: SÁBADO | I30: =ITAPIPOCA!U53
B32: TOTAL | C32: =SUM(C25:C30) -> 9413.6535 | E32: TOTAL | F32: =SUM(F25:F30) -> 5092.2219 | H32: TOTAL | I32: =SUM(I25:I30) -> 0
H33: TOTAL DO MÊS | I33: =C21+F21+I21+C32+F32+I32 -> 40000
B35: TOP 1
B36: TOP 1 | C36: =H57 -> TOTAL
B37: SEMANA 1 | E37: SEMANA 2 | H37: SEMANA 3
B38: DOMINGO | C38: =ITAPIPOCA!Y36 | E38: DOMINGO | F38: =ITAPIPOCA!AB36 | H38: DOMINGO | I38: =ITAPIPOCA!AE36 -> 0
B39: SEGUNDA-FEIRA | C39: =ITAPIPOCA!Y37 | E39: SEGUNDA-FEIRA | F39: =ITAPIPOCA!AB37 -> 1829.1474 | H39: SEGUNDA-FEIRA | I39: =ITAPIPOCA!AE37 -> 1829.1474
B40: TERÇA-FEIRA | C40: =ITAPIPOCA!Y38 | E40: TERÇA-FEIRA | F40: =ITAPIPOCA!AB38 -> 1604.3973 | H40: TERÇA-FEIRA | I40: =ITAPIPOCA!AE38 -> 1604.3973
B41: QUARTA-FEIRA | C41: =ITAPIPOCA!Y39 -> 1021.038 | E41: QUARTA-FEIRA | F41: =ITAPIPOCA!AB39 -> 1021.038 | H41: QUARTA-FEIRA | I41: =ITAPIPOCA!AE39 -> 1021.038
B42: QUINTA-FEIRA | C42: =ITAPIPOCA!Y40 -> 1910.6946 | E42: QUINTA-FEIRA | F42: =ITAPIPOCA!AB40 -> 1910.6946 | H42: QUINTA-FEIRA | I42: =ITAPIPOCA!AE40 -> 1910.6946
B43: SEXTA-FEIRA | C43: =ITAPIPOCA!Y41 -> 3616.5303 | E43: SEXTA-FEIRA | F43: =ITAPIPOCA!AB41 -> 3616.5303 | H43: SEXTA-FEIRA | I43: =ITAPIPOCA!AE41 -> 3616.5303
B44: SÁBADO | C44: =ITAPIPOCA!Y42 -> 1785.2592 | E44: SÁBADO | F44: =ITAPIPOCA!AB42 -> 1785.2592 | H44: SÁBADO | I44: =ITAPIPOCA!AE42 -> 1785.2592
B46: TOTAL | C46: =SUM(C39:C44) -> 8333.5221 | E46: TOTAL | F46: =SUM(F39:F44) -> 11767.067 | H46: TOTAL | I46: =SUM(I39:I44) -> 11767.067
B48: SEMANA 4 | E48: SEMANA 5 | H48: SEMANA 6
B49: DOMINGO | C49: =ITAPIPOCA!Y47 -> 0 | E49: DOMINGO | F49: =ITAPIPOCA!AB47 | H49: DOMINGO | I49: =ITAPIPOCA!AE47
...

Sheet METAS -  SOBRAL (P VENDEDOR)
B2: CENÁRIO 1
B3: MÍNIMA | C3: =H22 -> 110000
B4: SEMANA 1 | E4: SEMANA 2 | H4: SEMANA 3
B5: SEGUNDA-FEIRA | E5: SEGUNDA-FEIRA | F5: 1996.5956 | H5: SEGUNDA-FEIRA | I5: 1996.5956
B6: TERÇA-FEIRA | E6: TERÇA-FEIRA | F6: 3171.2935 | H6: TERÇA-FEIRA | I6: 3171.2935
B7: QUARTA-FEIRA | E7: QUARTA-FEIRA | F7: 3430.6474 | H7: QUARTA-FEIRA | I7: 3430.6474
B8: QUINTA-FEIRA | C8: 5310.086 | E8: QUINTA-FEIRA | F8: 5310.086 | H8: QUINTA-FEIRA | I8: 5310.086
B9: SEXTA-FEIRA | C9: 4632.6457 | E9: SEXTA-FEIRA | F9: 4632.6457 | H9: SEXTA-FEIRA | I9: 4632.6457
B10: SÁBADO | C10: 5301.2718 | E10: SÁBADO | F10: 5301.2718 | H10: SÁBADO | I10: 5301.2718
B12: TOTAL | C12: =SUM(C5:C10) -> 15244.003 | E12: TOTAL | F12: =SUM(F5:F10) -> 23842.54 | H12: TOTAL | I12: =SUM(I5:I10) -> 23842.54
B14: SEMANA 4 | E14: SEMANA 5
B15: SEGUNDA-FEIRA | C15: 1996.5956 | E15: SEGUNDA-FEIRA | F15: 1996.5956
B16: TERÇA-FEIRA | C16: 3171.2935 | E16: TERÇA-FEIRA | F16: 3171.2935
B17: QUARTA-FEIRA | C17: 3430.6474 | E17: QUARTA-FEIRA | F17: 3430.6474
B18: QUINTA-FEIRA | C18: 5310.086 | E18: QUINTA-FEIRA | F18: 5310.086
B19: SEXTA-FEIRA | C19: 4632.6457 | E19: SEXTA-FEIRA | F19: 4632.6457
B20: SÁBADO | C20: 5301.2718 | E20: SÁBADO | F20: =5301.27182076037-614.16 -> 4687.1118
H21: TOTAL DO MÊS
B22: TOTAL | C22: =SUM(C15:C20) -> 23842.54 | E22: TOTAL | F22: =SUM(F15:F20) -> 23228.38 | H22: =F22+C22+C12+F12+I12 -> 110000
B24: CENÁRIO 2
B25: TOP 1 | C25: =H44*3 -> #VALUE!
B26: SEMANA 1 | E26: SEMANA 2 | H26: SEMANA 3
B27: SEGUNDA-FEIRA | C27: ='METAS - ITAPIPOCA'!C39/2 -> #VALUE! | E27: SEGUNDA-FEIRA | F27: ='METAS - ITAPIPOCA'!F39/3 -> 609.71581 | H27: SEGUNDA-FEIRA | I27: ='METAS - ITAPIPOCA'!I39/3 -> 609.71581
B28: TERÇA-FEIRA | C28: ='METAS - ITAPIPOCA'!C40/2 -> #VALUE! | E28: TERÇA-FEIRA | F28: ='METAS - ITAPIPOCA'!F40/3 -> 534.79911 | H28: TERÇA-FEIRA | I28: ='METAS - ITAPIPOCA'!I40/3 -> 534.79911
B29: QUARTA-FEIRA | C29: ='METAS - ITAPIPOCA'!C41/2 -> 510.51901 | E29: QUARTA-FEIRA | F29: ='METAS - ITAPIPOCA'!F41/3 -> 340.34601 | H29: QUARTA-FEIRA | I29: ='METAS - ITAPIPOCA'!I41/3 -> 340.34601
B30: QUINTA-FEIRA | C30: ='METAS - ITAPIPOCA'!C42/3 -> 636.89819 | E30: QUINTA-FEIRA | F30: ='METAS - ITAPIPOCA'!F42/3 -> 636.89819 | H30: QUINTA-FEIRA | I30: ='METAS - ITAPIPOCA'!I42/3 -> 636.89819
B31: SEXTA-FEIRA | C31: ='METAS - ITAPIPOCA'!C43/3 -> 1205.5101 | E31: SEXTA-FEIRA | F31: ='METAS - ITAPIPOCA'!F43/3 -> 1205.5101 | H31: SEXTA-FEIRA | I31: ='METAS - ITAPIPOCA'!I43/3 -> 1205.5101
B32: SÁBADO | C32: ='METAS - ITAPIPOCA'!C44/3 -> 595.08641 | E32: SÁBADO | F32: ='METAS - ITAPIPOCA'!F44/3 -> 595.08641 | H32: SÁBADO | I32: ='METAS - ITAPIPOCA'!I44/3 -> 595.08641
B34: TOTAL | C34: =SUM(C27:C32) -> #VALUE! | E34: TOTAL | F34: =SUM(F27:F32) -> 3922.3556 | H34: TOTAL | I34: =SUM(I27:I32) -> 3922.3556
B36: SEMANA 4 | E36: SEMANA 5
B37: SEGUNDA-FEIRA | C37: ='METAS - ITAPIPOCA'!C50/3 -> 609.71581 | E37: SEGUNDA-FEIRA | F37: ='METAS - ITAPIPOCA'!F50/3 -> 609.71581
B38: TERÇA-FEIRA | C38: ='METAS - ITAPIPOCA'!C51/3 -> 534.79911 | E38: TERÇA-FEIRA | F38: ='METAS - ITAPIPOCA'!F51/3 -> 534.79911
B39: QUARTA-FEIRA | C39: ='METAS - ITAPIPOCA'!C52/3 -> 340.34601 | E39: QUARTA-FEIRA | F39: ='METAS - ITAPIPOCA'!F52/3 -> 340.34601
B40: QUINTA-FEIRA | C40: ='METAS - ITAPIPOCA'!C53/3 -> 636.89819 | E40: QUINTA-FEIRA | F40: ='METAS - ITAPIPOCA'!F53/3 -> 636.89819
B41: SEXTA-FEIRA | C41: ='METAS - ITAPIPOCA'!C54/3 -> 1205.5101 | E41: SEXTA-FEIRA | F41: ='METAS - ITAPIPOCA'!F54/3 -> #VALUE!
B42: SÁBADO | C42: ='METAS - ITAPIPOCA'!C55/3 -> 595.08641 | E42: SÁBADO | F42: ='METAS - ITAPIPOCA'!F55/3 -> #VALUE!
H43: TOTAL DO MÊS
B44: TOTAL | C44: =SUM(C37:C42) -> 3922.3556 | E44: TOTAL | F44: =SUM(F37:F42) -> #VALUE! | H44: =F44+C44+C34+F34+I34 -> #VALUE!
B46: CENÁRIO 3
B47: TOP 2 | C47: =H66*3 -> #VALUE!
...

Sheet VENDAS
I1: MÊS | J1: 4
I2: ANO | J2: 2026
L3: METAS POR DIA - DIFERENÇA | R3: VENDAS /SEMANA | Y3: VENDAS /SEMANA - ITAPIPOCA | AF3: Valores > 0 | AG3: Valores realizados sufientes para suprir a meta. O valor negativo significa a diferença superada na semana.
B4: CÓDIGO | C4: DATA | D4: DIA DA SEMANA | E4: VALOR REALIZADO | F4: SEMANA | G4: META MÍNIMA | H4: TOP 1 | I4: TOP 2 | J4: MASTER | L4: DATA | M4: META MÍNIMA | N4: TOP 1 | O4: TOP2 | P4: MASTER | R4: SEMANA | S4: VALOR REALIZADO | T4: META MÍNIMA | U4: TOP 1 | V4: TOP2 | W4: MASTER | Y4: SEMANA | Z4: VALOR REALIZADO | AA4: META MÍNIMA | AB4: TOP 1 | AC4: TOP2 | AD4: MASTER
B5: 1 | C5: =DATE($J$2,$J$1,B5) -> 46113 | D5: =UPPER(TEXT(C5,"dddd")) -> QUARTA-FEIRA | E5: 3532 | F5: ="Semana " & INT((DAY(C5)+WEEKDAY(DATE(YEAR(C5),MONTH(C5),1),1)-2)/7)+1 -> Semana 1 | G5: ='METAS - ITAPIPOCA'!C16 -> 816.83042 | H5: ='METAS - ITAPIPOCA'!C41 -> 1021.038 | I5: ='METAS - ITAPIPOCA'!C66 -> 1225.2456 | J5: ='METAS - ITAPIPOCA'!C90 -> 1633.6608 | L5: =C5 -> 46113 | M5: =$E$5-G5 -> 2715.1696 | N5: =$E$5-H5 -> 2510.962 | O5: =$E$5-I5 -> 2306.7544 | P5: =$E$5-J5 -> 1898.3392 | R5: Semana 1 | S5: =SUMIF($F$5:$F$43,R5,$E$5:$E$43) -> 15437 | T5: =SUM('METAS - ITAPIPOCA'!C14:C19) -> 6666.8177 | U5: =SUM('METAS - ITAPIPOCA'!C39:C44) -> 8333.5221 | V5: =SUM('METAS - ITAPIPOCA'!C64:C69) -> 10000.227 | W5: =SUM('METAS - ITAPIPOCA'!C88:C93) -> 13333.635 | Y5: 1 | Z5: =S5 -> 15437 | AA5: =$S$5-T5 -> 8770.1823 | AB5: =$S$5-U5 -> 7103.4779 | AC5: =$S$5-V5 -> 5436.7735 | AD5: =$S$5-W5 -> 2103.3646 | AF5: Valores < 0 | AG5: Valores realizados não sufientes para suprir a meta. O valor positivo significa a diferença não alcançada.
B6: 2 | C6: =DATE($J$2,$J$1,B6) -> 46114 | D6: =UPPER(TEXT(C6,"dddd")) -> QUINTA-FEIRA | E6: 7946 | F6: ="Semana " & INT((DAY(C6)+WEEKDAY(DATE(YEAR(C6),MONTH(C6),1),1)-2)/7)+1 -> Semana 1 | G6: ='METAS - ITAPIPOCA'!C17 -> 1528.5557 | H6: ='METAS - ITAPIPOCA'!C42 -> 1910.6946 | I6: ='METAS - ITAPIPOCA'!C67 -> 2292.8335 | J6: ='METAS - ITAPIPOCA'!C91 -> 3057.1113 | L6: =C6 -> 46114 | M6: =$E$6-G6 -> 6417.4443 | N6: =$E$6-H6 -> 6035.3054 | O6: =$E$6-I6 -> 5653.1665 | P6: =$E$6-J6 -> 4888.8887 | R6: Semana 2 | S6: =SUMIF($F$5:$F$43,R6,$E$5:$E$43) -> 38229 | T6: =SUM('METAS - ITAPIPOCA'!F14:F19) -> 9413.6535 | U6: =SUM('METAS - ITAPIPOCA'!F39:F44) -> 11767.067 | V6: =SUM('METAS - ITAPIPOCA'!F64:F69) -> 14120.48 | W6: =SUM('METAS - ITAPIPOCA'!F88:F93) -> 18827.307 | Y6: 2 | Z6: =S6 -> 38229 | AA6: =IF(Z6="","",$S$6-T6) -> 28815.347 | AB6: =IF(AA6="","",$S$6-U6) -> 26461.933 | AC6: =IF(AB6="","",$S$6-V6) -> 24108.52 | AD6: =IF(AC6="","",$S$6-W6) -> 19401.693
B7: 3 | C7: =DATE($J$2,$J$1,B7) -> 46115 | D7: =UPPER(TEXT(C7,"dddd")) -> SEXTA-FEIRA | F7: ="Semana " & INT((DAY(C7)+WEEKDAY(DATE(YEAR(C7),MONTH(C7),1),1)-2)/7)+1 -> Semana 1 | G7: ='METAS - ITAPIPOCA'!C18 -> 2893.2242 | H7: ='METAS - ITAPIPOCA'!C43 -> 3616.5303 | I7: ='METAS - ITAPIPOCA'!C68 -> 4339.8363 | J7: ='METAS - ITAPIPOCA'!C92 -> 5786.4485 | L7: =C7 -> 46115 | M7: =$E$7-G7 -> -2893.2242 | N7: =$E$7-H7 -> -3616.5303 | O7: =$E$7-I7 -> -4339.8363 | P7: =$E$7-J7 -> -5786.4485 | R7: Semana 3 | S7: =SUMIF($F$5:$F$43,R7,$E$5:$E$43) -> 23982 | T7: =SUM('METAS - ITAPIPOCA'!I14:I19) -> 9413.6535 | U7: =SUM('METAS - ITAPIPOCA'!I39:I44) -> 11767.067 | V7: =SUM('METAS - ITAPIPOCA'!I64:I69) -> 14120.48 | W7: =SUM('METAS - ITAPIPOCA'!I88:I93) -> 18827.307 | Y7: 3 | Z7: =S7 -> 23982 | AA7: =IF(Z7="","",$S$7-T7) -> 14568.347 | AB7: =IF(AA7="","",$S$7-U7) -> 12214.933 | AC7: =IF(AB7="","",$S$7-V7) -> 9861.5198 | AD7: =IF(AC7="","",$S$7-W7) -> 5154.693
B8: 4 | C8: =DATE($J$2,$J$1,B8) -> 46116 | D8: =UPPER(TEXT(C8,"dddd")) -> SÁBADO | E8: 3959 | F8: ="Semana " & INT((DAY(C8)+WEEKDAY(DATE(YEAR(C8),MONTH(C8),1),1)-2)/7)+1 -> Semana 1 | G8: ='METAS - ITAPIPOCA'!C19 -> 1428.2074 | H8: ='METAS - ITAPIPOCA'!C44 -> 1785.2592 | I8: ='METAS - ITAPIPOCA'!C69 -> 2142.3111 | J8: ='METAS - ITAPIPOCA'!C93 -> 2856.4148 | L8: =C8 -> 46116 | M8: =$E$8-G8 -> 2530.7926 | N8: =$E$8-H8 -> 2173.7408 | O8: =$E$8-I8 -> 1816.6889 | P8: =$E$8-J8 -> 1102.5852 | R8: Semana 4 | S8: =SUMIF($F$5:$F$43,R8,$E$5:$E$43) -> 15441 | T8: =SUM('METAS - ITAPIPOCA'!C25:C30) -> 9413.6535 | U8: =SUM('METAS - ITAPIPOCA'!C50:C55) -> 11767.067 | V8: =SUM('METAS - ITAPIPOCA'!C75:C80) -> 14120.48 | W8: =SUM('METAS - ITAPIPOCA'!C99:C104) -> 18827.307 | Y8: 4 | Z8: =S8 -> 15441 | AA8: =IF(Z8="","",$S$8-T8) -> 6027.3465 | AB8: =IF(AA8="","",$S$8-U8) -> 3673.9331 | AC8: =IF(AB8="","",$S$8-V8) -> 1320.5198 | AD8: =IF(AC8="","",$S$8-W8) -> -3386.307
B9: 5 | C9: =DATE($J$2,$J$1,B9) -> 46117 | D9: =UPPER(TEXT(C9,"dddd")) -> DOMINGO | F9: ="Semana " & INT((DAY(C9)+WEEKDAY(DATE(YEAR(C9),MONTH(C9),1),1)-2)/7)+1 -> Semana 2 | G9: ='METAS - ITAPIPOCA'!F13 | H9: ='METAS - ITAPIPOCA'!F38 | I9: ='METAS - ITAPIPOCA'!F63 | J9: ='METAS - ITAPIPOCA'!F87 | L9: =C9 -> 46117 | M9: =$E$9-G9 -> #VALUE! | N9: =$E$9-H9 -> #VALUE! | O9: =$E$9-I9 -> #VALUE! | P9: =$E$9-J9 -> #VALUE! | R9: Semana 5 | S9: =SUMIF($F$5:$F$43,R9,$E$5:$E$43) -> 8040 | T9: =SUM('METAS - ITAPIPOCA'!F25:F30) -> 5092.2219 | U9: =SUM('METAS - ITAPIPOCA'!F50:F55) -> 6365.2773 | V9: =SUM('METAS - ITAPIPOCA'!F75:F80) -> 7638.3328 | W9: =SUM('METAS - ITAPIPOCA'!F99:F104) -> 10184.444 | Y9: 5 | Z9: =S9 -> 8040 | AA9: =IF(Z9="","",$S$9-T9) -> 2947.7781 | AB9: =IF(AA9="","",$S$9-U9) -> 1674.7227 | AC9: =IF(AB9="","",$S$9-V9) -> 401.66719 | AD9: =IF(AC9="","",$S$9-W9) -> -2144.4438
B10: 6 | C10: =DATE($J$2,$J$1,B10) -> 46118 | D10: =UPPER(TEXT(C10,"dddd")) -> SEGUNDA-FEIRA | E10: 4814 | F10: ="Semana " & INT((DAY(C10)+WEEKDAY(DATE(YEAR(C10),MONTH(C10),1),1)-2)/7)+1 -> Semana 2 | G10: ='METAS - ITAPIPOCA'!F14 -> 1463.3179 | H10: ='METAS - ITAPIPOCA'!F39 -> 1829.1474 | I10: ='METAS - ITAPIPOCA'!F64 -> 2194.9769 | J10: ='METAS - ITAPIPOCA'!F88 -> 2926.6359 | L10: =C10 -> 46118 | M10: =E10-G10 -> 3350.6821 | N10: =$E$10-H10 -> 2984.8526 | O10: =$E$10-I10 -> 2619.0231 | P10: =$E$10-J10 -> 1887.3641
B11: 7 | C11: =DATE($J$2,$J$1,B11) -> 46119 | D11: =UPPER(TEXT(C11,"dddd")) -> TERÇA-FEIRA | E11: 3787 | F11: ="Semana " & INT((DAY(C11)+WEEKDAY(DATE(YEAR(C11),MONTH(C11),1),1)-2)/7)+1 -> Semana 2 | G11: ='METAS - ITAPIPOCA'!F15 -> 1283.5179 | H11: ='METAS - ITAPIPOCA'!F40 -> 1604.3973 | I11: ='METAS - ITAPIPOCA'!F65 -> 1925.2768 | J11: ='METAS - ITAPIPOCA'!F89 -> 2567.0357 | L11: =C11 -> 46119 | M11: =$E$11-G11 -> 2503.4821 | N11: =$E$11-H11 -> 2182.6027 | O11: =$E$11-I11 -> 1861.7232 | P11: =$E$11-J11 -> 1219.9643
B12: 8 | C12: =DATE($J$2,$J$1,B12) -> 46120 | D12: =UPPER(TEXT(C12,"dddd")) -> QUARTA-FEIRA | E12: 4045 | F12: ="Semana " & INT((DAY(C12)+WEEKDAY(DATE(YEAR(C12),MONTH(C12),1),1)-2)/7)+1 -> Semana 2 | G12: ='METAS - ITAPIPOCA'!F16 -> 816.83042 | H12: ='METAS - ITAPIPOCA'!F41 -> 1021.038 | I12: ='METAS - ITAPIPOCA'!F66 -> 1225.2456 | J12: ='METAS - ITAPIPOCA'!F90 -> 1633.6608 | L12: =C12 -> 46120 | M12: =E12-G12 -> 3228.1696 | N12: =$E$12-H12 -> 3023.962 | O12: =$E$12-I12 -> 2819.7544 | P12: =$E$12-J12 -> 2411.3392
B13: 9 | C13: =DATE($J$2,$J$1,B13) -> 46121 | D13: =UPPER(TEXT(C13,"dddd")) -> QUINTA-FEIRA | E13: 10087 | F13: ="Semana " & INT((DAY(C13)+WEEKDAY(DATE(YEAR(C13),MONTH(C13),1),1)-2)/7)+1 -> Semana 2 | G13: ='METAS - ITAPIPOCA'!F17 -> 1528.5557 | H13: ='METAS - ITAPIPOCA'!F42 -> 1910.6946 | I13: ='METAS - ITAPIPOCA'!F67 -> 2292.8335 | J13: ='METAS - ITAPIPOCA'!F91 -> 3057.1113 | L13: =C13 -> 46121 | M13: =E13-G13 -> 8558.4443 | N13: =$E$13-H13 -> 8176.3054 | O13: =$E$13-I13 -> 7794.1665 | P13: =$E$13-J13 -> 7029.8887
B14: 10 | C14: =DATE($J$2,$J$1,B14) -> 46122 | D14: =UPPER(TEXT(C14,"dddd")) -> SEXTA-FEIRA | E14: 8347 | F14: ="Semana " & INT((DAY(C14)+WEEKDAY(DATE(YEAR(C14),MONTH(C14),1),1)-2)/7)+1 -> Semana 2 | G14: ='METAS - ITAPIPOCA'!F18 -> 2893.2242 | H14: ='METAS - ITAPIPOCA'!F43 -> 3616.5303 | I14: ='METAS - ITAPIPOCA'!F68 -> 4339.8363 | J14: ='METAS - ITAPIPOCA'!F92 -> 5786.4485 | L14: =C14 -> 46122 | M14: =E14-G14 -> 5453.7758 | N14: =$E$14-H14 -> 4730.4697 | O14: =$E$14-I14 -> 4007.1637 | P14: =$E$14-J14 -> 2560.5515
B15: 11 | C15: =DATE($J$2,$J$1,B15) -> 46123 | D15: =UPPER(TEXT(C15,"dddd")) -> SÁBADO | E15: 7149 | F15: ="Semana " & INT((DAY(C15)+WEEKDAY(DATE(YEAR(C15),MONTH(C15),1),1)-2)/7)+1 -> Semana 2 | G15: ='METAS - ITAPIPOCA'!F19 -> 1428.2074 | H15: ='METAS - ITAPIPOCA'!F44 -> 1785.2592 | I15: ='METAS - ITAPIPOCA'!F69 -> 2142.3111 | J15: ='METAS - ITAPIPOCA'!F93 -> 2856.4148 | L15: =C15 -> 46123 | M15: =E15-G15 -> 5720.7926 | N15: =$E$15-H15 -> 5363.7408 | O15: =$E$15-I15 -> 5006.6889 | P15: =$E$15-J15 -> 4292.5852
B16: 12 | C16: =DATE($J$2,$J$1,B16) -> 46124 | D16: =UPPER(TEXT(C16,"dddd")) -> DOMINGO | F16: ="Semana " & INT((DAY(C16)+WEEKDAY(DATE(YEAR(C16),MONTH(C16),1),1)-2)/7)+1 -> Semana 3 | G16: ='METAS - ITAPIPOCA'!I13 -> 0 | H16: ='METAS - ITAPIPOCA'!I38 -> 0 | I16: ='METAS - ITAPIPOCA'!I63 -> 0 | J16: ='METAS - ITAPIPOCA'!I87 -> 0 | L16: =C16 -> 46124 | M16: =E16-G16 -> 0 | N16: =$E$16-H16 -> 0 | O16: =$E$16-I16 -> 0 | P16: =$E$16-J16 -> 0
B17: 13 | C17: =DATE($J$2,$J$1,B17) -> 46125 | D17: =UPPER(TEXT(C17,"dddd")) -> SEGUNDA-FEIRA | E17: 3039 | F17: ="Semana " & INT((DAY(C17)+WEEKDAY(DATE(YEAR(C17),MONTH(C17),1),1)-2)/7)+1 -> Semana 3 | G17: ='METAS - ITAPIPOCA'!I14 -> 1463.3179 | H17: ='METAS - ITAPIPOCA'!I39 -> 1829.1474 | I17: ='METAS - ITAPIPOCA'!I64 -> 2194.9769 | J17: ='METAS - ITAPIPOCA'!I88 -> 2926.6359 | L17: =C17 -> 46125 | M17: =E17-G17 -> 1575.6821 | N17: =$E$17-H17 -> 1209.8526 | O17: =$E$17-I17 -> 844.02308 | P17: =$E$17-J17 -> 112.3641
B18: 14 | C18: =DATE($J$2,$J$1,B18) -> 46126 | D18: =UPPER(TEXT(C18,"dddd")) -> TERÇA-FEIRA | E18: 1122 | F18: ="Semana " & INT((DAY(C18)+WEEKDAY(DATE(YEAR(C18),MONTH(C18),1),1)-2)/7)+1 -> Semana 3 | G18: ='METAS - ITAPIPOCA'!I15 -> 1283.5179 | H18: ='METAS - ITAPIPOCA'!I40 -> 1604.3973 | I18: ='METAS - ITAPIPOCA'!I65 -> 1925.2768 | J18: ='METAS - ITAPIPOCA'!I89 -> 2567.0357 | L18: =C18 -> 46126 | M18: =$E$18-G18 -> -161.51785 | N18: =$E$18-H18 -> -482.39732 | O18: =$E$18-I18 -> -803.27678 | P18: =$E$18-J18 -> -1445.0357
B19: 15 | C19: =DATE($J$2,$J$1,B19) -> 46127 | D19: =UPPER(TEXT(C19,"dddd")) -> QUARTA-FEIRA | E19: 3872 | F19: ="Semana " & INT((DAY(C19)+WEEKDAY(DATE(YEAR(C19),MONTH(C19),1),1)-2)/7)+1 -> Semana 3 | G19: ='METAS - ITAPIPOCA'!I16 -> 816.83042 | H19: ='METAS - ITAPIPOCA'!I41 -> 1021.038 | I19: ='METAS - ITAPIPOCA'!I66 -> 1225.2456 | J19: ='METAS - ITAPIPOCA'!I90 -> 1633.6608 | L19: =C19 -> 46127 | M19: =E19-G19 -> 3055.1696 | N19: =$E$19-H19 -> 2850.962 | O19: =$E$19-I19 -> 2646.7544 | P19: =$E$19-J19 -> 2238.3392
B20: 16 | C20: =DATE($J$2,$J$1,B20) -> 46128 | D20: =UPPER(TEXT(C20,"dddd")) -> QUINTA-FEIRA | E20: 4792 | F20: ="Semana " & INT((DAY(C20)+WEEKDAY(DATE(YEAR(C20),MONTH(C20),1),1)-2)/7)+1 -> Semana 3 | G20: ='METAS - ITAPIPOCA'!I17 -> 1528.5557 | H20: ='METAS - ITAPIPOCA'!I42 -> 1910.6946 | I20: ='METAS - ITAPIPOCA'!I67 -> 2292.8335 | J20: ='METAS - ITAPIPOCA'!I91 -> 3057.1113 | L20: =C20 -> 46128 | M20: =E20-G20 -> 3263.4443 | N20: =$E$20-H20 -> 2881.3054 | O20: =$E$20-I20 -> 2499.1665 | P20: =$E$20-J20 -> 1734.8887
B21: 17 | C21: =DATE($J$2,$J$1,B21) -> 46129 | D21: =UPPER(TEXT(C21,"dddd")) -> SEXTA-FEIRA | E21: 6008 | F21: ="Semana " & INT((DAY(C21)+WEEKDAY(DATE(YEAR(C21),MONTH(C21),1),1)-2)/7)+1 -> Semana 3 | G21: ='METAS - ITAPIPOCA'!I18 -> 2893.2242 | H21: ='METAS - ITAPIPOCA'!I43 -> 3616.5303 | I21: ='METAS - ITAPIPOCA'!I68 -> 4339.8363 | J21: ='METAS - ITAPIPOCA'!I92 -> 5786.4485 | L21: =C21 -> 46129 | M21: =E21-G21 -> 3114.7758 | N21: =$E$21-H21 -> 2391.4697 | O21: =$E$21-I21 -> 1668.1637 | P21: =$E$21-J21 -> 221.55155
B22: 18 | C22: =DATE($J$2,$J$1,B22) -> 46130 | D22: =UPPER(TEXT(C22,"dddd")) -> SÁBADO | E22: 5149 | F22: ="Semana " & INT((DAY(C22)+WEEKDAY(DATE(YEAR(C22),MONTH(C22),1),1)-2)/7)+1 -> Semana 3 | G22: ='METAS - ITAPIPOCA'!I19 -> 1428.2074 | H22: ='METAS - ITAPIPOCA'!I44 -> 1785.2592 | I22: ='METAS - ITAPIPOCA'!I69 -> 2142.3111 | J22: ='METAS - ITAPIPOCA'!I93 -> 2856.4148 | L22: =C22 -> 46130 | M22: =E22-G22 -> 3720.7926 | N22: =$E$22-H22 -> 3363.7408 | O22: =$E$22-I22 -> 3006.6889 | P22: =$E$22-J22 -> 2292.5852
B23: 19 | C23: =DATE($J$2,$J$1,B23) -> 46131 | D23: =UPPER(TEXT(C23,"dddd")) -> DOMINGO | F23: ="Semana " & INT((DAY(C23)+WEEKDAY(DATE(YEAR(C23),MONTH(C23),1),1)-2)/7)+1 -> Semana 4 | G23: ='METAS - ITAPIPOCA'!C24 -> 0 | H23: ='METAS - ITAPIPOCA'!C49 -> 0 | I23: ='METAS - ITAPIPOCA'!C74 -> 0 | J23: ='METAS - ITAPIPOCA'!C98 -> 0 | L23: =C23 -> 46131 | M23: =E23-G23 -> 0 | N23: =$E$23-H23 -> 0 | O23: =$E$23-I23 -> 0 | P23: =$E$23-J23 -> 0
B24: 20 | C24: =DATE($J$2,$J$1,B24) -> 46132 | D24: =UPPER(TEXT(C24,"dddd")) -> SEGUNDA-FEIRA | E24: 3058 | F24: ="Semana " & INT((DAY(C24)+WEEKDAY(DATE(YEAR(C24),MONTH(C24),1),1)-2)/7)+1 -> Semana 4 | G24: ='METAS - ITAPIPOCA'!C25 -> 1463.3179 | H24: ='METAS - ITAPIPOCA'!C50 -> 1829.1474 | I24: ='METAS - ITAPIPOCA'!C75 -> 2194.9769 | J24: ='METAS - ITAPIPOCA'!C99 -> 2926.6359 | L24: =C24 -> 46132 | M24: =E24-G24 -> 1594.6821 | N24: =$E$24-H24 -> 1228.8526 | O24: =$E$24-I24 -> 863.02308 | P24: =$E$24-J24 -> 131.3641
B25: 21 | C25: =DATE($J$2,$J$1,B25) -> 46133 | D25: =UPPER(TEXT(C25,"dddd")) -> TERÇA-FEIRA | F25: ="Semana " & INT((DAY(C25)+WEEKDAY(DATE(YEAR(C25),MONTH(C25),1),1)-2)/7)+1 -> Semana 4 | G25: ='METAS - ITAPIPOCA'!C26 -> 1283.5179 | H25: ='METAS - ITAPIPOCA'!C51 -> 1604.3973 | I25: ='METAS - ITAPIPOCA'!C76 -> 1925.2768 | J25: ='METAS - ITAPIPOCA'!C100 -> 2567.0357 | L25: =C25 -> 46133 | M25: =$E$25-G25 -> -1283.5179 | N25: =$E$25-H25 -> -1604.3973 | O25: =$E$25-I25 -> -1925.2768 | P25: =$E$25-J25 -> -2567.0357
B26: 22 | C26: =DATE($J$2,$J$1,B26) -> 46134 | D26: =UPPER(TEXT(C26,"dddd")) -> QUARTA-FEIRA | E26: 3068 | F26: ="Semana " & INT((DAY(C26)+WEEKDAY(DATE(YEAR(C26),MONTH(C26),1),1)-2)/7)+1 -> Semana 4 | G26: ='METAS - ITAPIPOCA'!C27 -> 816.83042 | H26: ='METAS - ITAPIPOCA'!C52 -> 1021.038 | I26: ='METAS - ITAPIPOCA'!C77 -> 1225.2456 | J26: ='METAS - ITAPIPOCA'!C101 -> 1633.6608 | L26: =C26 -> 46134 | M26: =E26-G26 -> 2251.1696 | N26: =$E$26-H26 -> 2046.962 | O26: =$E$26-I26 -> 1842.7544 | P26: =$E$26-J26 -> 1434.3392
B27: 23 | C27: =DATE($J$2,$J$1,B27) -> 46135 | D27: =UPPER(TEXT(C27,"dddd")) -> QUINTA-FEIRA | E27: 3403 | F27: ="Semana " & INT((DAY(C27)+WEEKDAY(DATE(YEAR(C27),MONTH(C27),1),1)-2)/7)+1 -> Semana 4 | G27: ='METAS - ITAPIPOCA'!C28 -> 1528.5557 | H27: ='METAS - ITAPIPOCA'!C53 -> 1910.6946 | I27: ='METAS - ITAPIPOCA'!C78 -> 2292.8335 | J27: ='METAS - ITAPIPOCA'!C102 -> 3057.1113 | L27: =C27 -> 46135 | M27: =E27-G27 -> 1874.4443 | N27: =$E$27-H27 -> 1492.3054 | O27: =$E$27-I27 -> 1110.1665 | P27: =$E$27-J27 -> 345.88869
B28: 24 | C28: =DATE($J$2,$J$1,B28) -> 46136 | D28: =UPPER(TEXT(C28,"dddd")) -> SEXTA-FEIRA | E28: 2895 | F28: ="Semana " & INT((DAY(C28)+WEEKDAY(DATE(YEAR(C28),MONTH(C28),1),1)-2)/7)+1 -> Semana 4 | G28: ='METAS - ITAPIPOCA'!C29 -> 2893.2242 | H28: ='METAS - ITAPIPOCA'!C54 -> 3616.5303 | I28: ='METAS - ITAPIPOCA'!C79 -> 4339.8363 | J28: ='METAS - ITAPIPOCA'!C103 -> 5786.4485 | L28: =C28 -> 46136 | M28: =E28-G28 -> 1.7757737 | N28: =$E$28-H28 -> -721.53028 | O28: =$E$28-I28 -> -1444.8363 | P28: =$E$28-J28 -> -2891.4485
B29: 25 | C29: =DATE($J$2,$J$1,B29) -> 46137 | D29: =UPPER(TEXT(C29,"dddd")) -> SÁBADO | E29: 3017 | F29: ="Semana " & INT((DAY(C29)+WEEKDAY(DATE(YEAR(C29),MONTH(C29),1),1)-2)/7)+1 -> Semana 4 | G29: ='METAS - ITAPIPOCA'!C30 -> 1428.2074 | H29: ='METAS - ITAPIPOCA'!C55 -> 1785.2592 | I29: ='METAS - ITAPIPOCA'!C80 -> 2142.3111 | J29: ='METAS - ITAPIPOCA'!C104 -> 2856.4148 | L29: =C29 -> 46137 | M29: =E29-G29 -> 1588.7926 | N29: =E29-H29 -> 1231.7408 | O29: =E29-I29 -> 874.68893 | P29: =E29-J29 -> 160.58524
B30: 26 | C30: =DATE($J$2,$J$1,B30) -> 46138 | D30: =UPPER(TEXT(C30,"dddd")) -> DOMINGO | F30: ="Semana " & INT((DAY(C30)+WEEKDAY(DATE(YEAR(C30),MONTH(C30),1),1)-2)/7)+1 -> Semana 5 | G30: ='METAS - ITAPIPOCA'!F24 -> 0 | H30: ='METAS - ITAPIPOCA'!F49 | I30: ='METAS - ITAPIPOCA'!F74 | J30: ='METAS - ITAPIPOCA'!F98 | L30: =C30 -> 46138 | M30: =E30-G30 -> 0 | N30: =E30-H30 -> #VALUE! | O30: =E30-I30 -> #VALUE! | P30: =E30-J30 -> #VALUE!
B31: 27 | C31: =DATE($J$2,$J$1,B31) -> 46139 | D31: =UPPER(TEXT(C31,"dddd")) -> SEGUNDA-FEIRA | E31: 2053 | F31: ="Semana " & INT((DAY(C31)+WEEKDAY(DATE(YEAR(C31),MONTH(C31),1),1)-2)/7)+1 -> Semana 5 | G31: ='METAS - ITAPIPOCA'!F25 -> 1463.3179 | H31: ='METAS - ITAPIPOCA'!F50 -> 1829.1474 | I31: ='METAS - ITAPIPOCA'!F75 -> 2194.9769 | J31: ='METAS - ITAPIPOCA'!F99 -> 2926.6359 | L31: =C31 -> 46139 | M31: =E31-G31 -> 589.68205 | N31: =E31-H31 -> 223.85256 | O31: =E31-I31 -> -141.97692 | P31: =E31-J31 -> -873.6359
B32: 28 | C32: =DATE($J$2,$J$1,B32) -> 46140 | D32: =UPPER(TEXT(C32,"dddd")) -> TERÇA-FEIRA | E32: 1289 | F32: ="Semana " & INT((DAY(C32)+WEEKDAY(DATE(YEAR(C32),MONTH(C32),1),1)-2)/7)+1 -> Semana 5 | G32: ='METAS - ITAPIPOCA'!F26 -> 1283.5179 | H32: ='METAS - ITAPIPOCA'!F51 -> 1604.3973 | I32: ='METAS - ITAPIPOCA'!F76 -> 1925.2768 | J32: ='METAS - ITAPIPOCA'!F100 -> 2567.0357 | L32: =C32 -> 46140 | M32: =E32-G32 -> 5.4821474 | N32: =E32-H32 -> -315.39732 | O32: =E32-I32 -> -636.27678 | P32: =E32-J32 -> -1278.0357
B33: 29 | C33: =DATE($J$2,$J$1,B33) -> 46141 | D33: =UPPER(TEXT(C33,"dddd")) -> QUARTA-FEIRA | E33: 1597 | F33: ="Semana " & INT((DAY(C33)+WEEKDAY(DATE(YEAR(C33),MONTH(C33),1),1)-2)/7)+1 -> Semana 5 | G33: ='METAS - ITAPIPOCA'!F27 -> 816.83042 | H33: ='METAS - ITAPIPOCA'!F52 -> 1021.038 | I33: ='METAS - ITAPIPOCA'!F77 -> 1225.2456 | J33: ='METAS - ITAPIPOCA'!F101 -> 1633.6608 | L33: =C33 -> 46141 | M33: =E33-G33 -> 780.16958 | N33: =E33-H33 -> 575.96197 | O33: =E33-I33 -> 371.75437 | P33: =E33-J33 -> -36.660843
B34: 30 | C34: =DATE($J$2,$J$1,B34) -> 46142 | D34: =UPPER(TEXT(C34,"dddd")) -> QUINTA-FEIRA | E34: 3101 | F34: ="Semana " & INT((DAY(C34)+WEEKDAY(DATE(YEAR(C34),MONTH(C34),1),1)-2)/7)+1 -> Semana 5 | G34: ='METAS - ITAPIPOCA'!F28 -> 1528.5557 | H34: ='METAS - ITAPIPOCA'!F53 -> 1910.6946 | I34: ='METAS - ITAPIPOCA'!F78 -> 2292.8335 | J34: ='METAS - ITAPIPOCA'!F102 -> 3057.1113 | L34: =C34 -> 46142 | M34: =E34-G34 -> 1572.4443 | N34: =E34-H34 -> 1190.3054 | O34: =E34-I34 -> 808.16652 | P34: =E34-J34 -> 43.888694
B35: 31 | C35: =DATE($J$2,$J$1,B35) -> 46143 | D35: =UPPER(TEXT(C35,"dddd")) -> SEXTA-FEIRA | F35: ="Semana " & INT((DAY(C35)+WEEKDAY(DATE(YEAR(C35),MONTH(C35),1),1)-2)/7)+1 -> Semana 1 | L35: =C35 -> 46143 | M35: =E35-G35 -> 0 | N35: =E35-H35 -> 0 | O35: =E35-I35 -> 0 | P35: =E35-J35 -> 0
C36: Total | E36: =SUBTOTAL(109,Tabela37[VALOR REALIZADO]) -> 101129 | G36: =SUBTOTAL(109,Tabela37[META MÍNIMA]) -> 40000 | H36: =SUBTOTAL(109,Tabela37[TOP 1]) -> 50000 | I36: =SUBTOTAL(109,Tabela37[TOP 2]) -> 60000 | J36: =SUBTOTAL(109,Tabela37[MASTER]) -> 80000

Sheet Planilha5
D3: DIA DA SEMANA | E3: VALOR | F3: %
D4: DOMINGO | E4: 0 | F4: 0
D5: SEGUNDA-FEIRA | E5: 4332 | F5: 0.076795711
D6: TERÇA-FEIRA | E6: 7344 | F6: 0.13019107
D7: QUARTA-FEIRA | E7: 8009 | F7: 0.14197988
D8: QUINTA-FEIRA | E8: 12828 | F8: 0.22740891
D9: SEXTA-FEIRA | E9: 11091 | F9: 0.19661617
D10: SÁBADO | E10: 12805.4 | F10: 0.22700826
D11: Total Geral | E11: 56409.4 | F11: 1

Sheet Folha1

Sheet RESUMO
B18: DIA DA SEMANA | C18: VENDA | D18: %
B19: SEGUNDA-FEIRA | C19: =SUMIF(Tabela37[DIA DA SEMANA],RESUMO!B19,Tabela37[VALOR REALIZADO]) -> 12964 | D19: =C19/$C$25 -> 0.1281927
B20: TERÇA-FEIRA | C20: =SUMIF(Tabela37[DIA DA SEMANA],RESUMO!B20,Tabela37[VALOR REALIZADO]) -> 6198 | D20: =C20/$C$25 -> 0.061288058
B21: QUARTA-FEIRA | C21: =SUMIF(Tabela37[DIA DA SEMANA],RESUMO!B21,Tabela37[VALOR REALIZADO]) -> 16114 | D21: =C21/$C$25 -> 0.15934104
B22: QUINTA-FEIRA | C22: =SUMIF(Tabela37[DIA DA SEMANA],RESUMO!B22,Tabela37[VALOR REALIZADO]) -> 29329 | D22: =C22/$C$25 -> 0.29001572
B23: SEXTA-FEIRA | C23: =SUMIF(Tabela37[DIA DA SEMANA],RESUMO!B23,Tabela37[VALOR REALIZADO]) -> 17250 | D23: =C23/$C$25 -> 0.17057422
B24: SÁBADO | C24: =SUMIF(Tabela37[DIA DA SEMANA],RESUMO!B24,Tabela37[VALOR REALIZADO]) -> 19274 | D24: =C24/$C$25 -> 0.19058826
B25: TOTAL | C25: =SUM(C19:C24) -> 101129 | D25: =C25/$C$25 -> 1
B27: REALIZADO | C27: =Tabela37[[#Totals],[VALOR REALIZADO]] -> 101129
B28: DIVISÃO DAS METAS | C28: VALOR | D28: DIFERENÇA | E28: % ALCANCE DA META
B29: META MÍNIMA | C29: =Tabela37[[#Totals],[META MÍNIMA]] -> 40000 | D29: =$C$27-C29 -> 61129 | E29: =$C$27/C29 -> 2.528225
B30: TOP 1 | C30: =Tabela37[[#Totals],[TOP 1]] -> 50000 | D30: =$C$27-C30 -> 51129 | E30: =$C$27/C30 -> 2.02258
B31: TOP2 | C31: =Tabela37[[#Totals],[TOP 2]] -> 60000 | D31: =$C$27-C31 -> 41129 | E31: =$C$27/C31 -> 1.6854833
B32: MASTER | C32: =Tabela37[[#Totals],[MASTER]] -> 80000 | D32: =$C$27-C32 -> 21129 | E32: =$C$27/C32 -> 1.2641125
B34: MELHOR VENDA DIÁRIA | C34: =MAX(Tabela37[VALOR REALIZADO]) -> 10087
B35: MELHOR SEMANA | C35: =MAX(VENDAS!S5:S9) -> 38229

Sheet AUXILIAR
C2: METAS INDIVIDUAIS
C3: Rótulos de Linha | D3: META INDIVIDUAL | F3: VENDEDOR | G3: META INDIVIDUAL
C4: Total Geral | F4: CRIS | G4: =SUMIF(VENDAS_VENDEDOR[[#Data],[#Totals],[VENDEDOR]],AUXILIAR!F4,VENDAS_VENDEDOR[VALOR REALIZADO]) -> 0
F5: VITÓRIA | G5: =SUMIF(VENDAS_VENDEDOR[[#Data],[#Totals],[VENDEDOR]],AUXILIAR!F5,VENDAS_VENDEDOR[VALOR REALIZADO]) -> 0
F6: NARA | G6: =SUMIF(VENDAS_VENDEDOR[[#Data],[#Totals],[VENDEDOR]],AUXILIAR!F6,VENDAS_VENDEDOR[VALOR REALIZADO]) -> 0
F7: SHERON | G7: =SUMIF(VENDAS_VENDEDOR[[#Data],[#Totals],[VENDEDOR]],AUXILIAR!F7,VENDAS_VENDEDOR[VALOR REALIZADO]) -> 0

Sheet Planilha2 (2)

Sheet IMAGENS (2)
D3: NOME | E3: FOTO | H3: NOME | I3: FOTO
D4: SHERON | E4: #VALUE! | H4: SHERON | I4: #VALUE!
D5: CRIS | E5: #VALUE! | H5: CRIS | I5: #VALUE!
D6: NARA | E6: #VALUE! | H6: NARA | I6: #VALUE!

Sheet VENDEDORES
A1: MELHOR VENDEDORA

Sheet GERAL TOTAL
B2: ITAPIPOCA
C3: JAN | D3: FEV | E3: MAR | F3: ABR | G3: MAI | H3: JUN | I3: JUL | J3: AGO | K3: SET | L3: OUT | M3: NOV | N3: DEZ | O3: TOTAL
B4: 2023 | C4: 19874 | D4: 14184.94 | E4: 31306.95 | F4: 24315 | G4: 61782.5 | H4: 42011 | I4: 33355 | J4: 41895 | K4: 33729.1 | L4: 32190 | M4: 66009 | N4: 93436 | O4: =SUM(C4:N4) -> 494088.49
B5: 2024 | C5: 18528 | D5: 25658.7 | E5: 48575.6 | F5: 66407.9 | G5: 68016.9 | H5: 53766.9 | I5: 76693 | J5: 55215.5 | K5: 104015.6 | L5: 30796 | M5: 69122.2 | N5: 108361.6 | O5: =SUM(C5:N5) -> 725157.9
B6: TAXA DE CRESCIMENTO 2023/2024 | C6: =C5/C4-1 -> -0.067726678 | D6: =D5/D4-1 -> 0.80886912 | E6: =E5/E4-1 -> 0.55159158 | F6: =F5/F4-1 -> 1.7311495 | G6: =G5/G4-1 -> 0.10090883 | H6: =H5/H4-1 -> 0.27982909 | I6: =I5/I4-1 -> 1.2992955 | J6: =J5/J4-1 -> 0.31794964 | ... O6: =O5/O4-1 -> 0.46766807
B7: TAXA DE CRESCIMENTO ESPERADA 2025 | C7: 0.2 | D7: 0.2 | E7: 0.2 | F7: 0.2 | G7: 0.2 | H7: 0.2 | I7: 0.2 | J7: 0.2 | K7: 0.2 | L7: 0.2 | M7: 0.2 | N7: 0.2 | O7: 0.2
B8: FATURAMENTO ESPERADO 2025 | C8: =C5*(100%+C7) -> 22233.6 | D8: =D5*(100%+D7) -> 30790.44 | E8: =E5*(100%+E7) -> 58290.72 | F8: =F5*(100%+F7) -> 79689.48 | G8: =G5*(100%+G7) -> 81620.28 | H8: =H5*(100%+H7) -> 64520.28 | I8: =I5*(100%+I7) -> 92031.6 | J8: =J5*(100%+J7) -> 66258.6 | ... N8: =N5*(100%+N7) -> 130033.92 | O8: =SUM(C8:N8) -> 870189.48
B9: FATURAMENTO REAL | C9: 19820 | D9: 35317 | E9: 38451.9 | F9: 82472.9 | G9: 99000 | H9: 62464 | I9: 101707.4 | J9: 76569.6 | O9: =SUM(C9:N9) -> 515802.8
B10: DIFRENÇA | C10: =C9/C8-1 -> -0.10855642 | D10: =D9/D8-1 -> 0.14701186 | E10: =E9/E8-1 -> -0.34034268 | F10: =F9/F8-1 -> 0.034928324 | G10: =G9/G8-1 -> 0.21293384 | H10: =H9/H8-1 -> -0.031870289 | I10: =I9/I8-1 -> 0.10513563 | J10: =J9/J8-1 -> 0.15561753 | ... O10: =O9/O8-1 -> -0.40725231
B12: SOBRAL
C13: JAN | D13: FEV | E13: MAR | F13: ABR | G13: MAI | H13: JUN | I13: JUL | J13: AGO | K13: SET | L13: OUT | M13: NOV | N13: DEZ | O13: TOTAL
B14: 2023 | C14: 69665 | D14: 66339.9 | E14: 112868.2 | F14: 110771 | G14: 76196 | H14: 124891 | I14: 97317.4 | J14: 95136 | K14: 116125 | L14: 144644.1 | M14: 228425.88 | N14: 278369.22 | O14: =SUM(C14:N14) -> 1520748.7
B15: 2024 | C15: 56409.4 | D15: 119124.91 | E15: 152166.95 | F15: 86346 | G15: 175012.98 | H15: 151309.9 | I15: 266098.3 | J15: 188534.8 | K15: 142266.7 | L15: 232186.56 | M15: 185973.04 | N15: 273769.1 | O15: =SUM(C15:N15) -> 2029198.6
B16: TAXA DE CRESCIMENTO 2023/2024 | C16: =C15/C14-1 -> -0.19027632 | D16: =D15/D14-1 -> 0.79567515 | E16: =E15/E14-1 -> 0.34818266 | F16: =F15/F14-1 -> -0.22049995 | G16: =G15/G14-1 -> 1.2968788 | H16: =H15/H14-1 -> 0.21153566 | I16: =I15/I14-1 -> 1.7343343 | J16: =J15/J14-1 -> 0.98173983 | ... O16: =O15/O14-1 -> 0.33434185
B17: TAXA DE CRESCIMENTO ESPERADA 2025 | C17: 0.2 | D17: 0.2 | E17: 0.2 | F17: 0.2 | G17: 0.2 | H17: 0.2 | I17: 0.2 | J17: 0.2 | K17: 0.2 | L17: 0.2 | M17: 0.2 | N17: 0.2 | O17: 0.2
B18: FATURAMENTO ESPERADO 2025 | C18: =C15*(100%+C17) -> 67691.28 | D18: =D15*(100%+D17) -> 142949.89 | E18: =E15*(100%+E17) -> 182600.34 | F18: =F15*(100%+F17) -> 103615.2 | G18: =G15*(100%+G17) -> 210015.58 | H18: =H15*(100%+H17) -> 181571.88 | I18: =I15*(100%+I17) -> 319317.96 | J18: =J15*(100%+J17) -> 226241.76 | ... N18: =N15*(100%+N17) -> 328522.92 | O18: =SUM(C18:N18) -> 2435038.4
B19: FATURAMENTO REAL | C19: 74329 | D19: 119813.5 | E19: 234836.65 | F19: 119501 | G19: 173353 | H19: 168340.47 | I19: 186236.1 | O19: =SUM(C19:N19) -> 1076409.7
B20: DIFRENÇA | C20: =C19/C18-1 -> 0.098058716 | D20: =D19/D18-1 -> -0.16184966 | E20: =E19/E18-1 -> 0.28606907 | F20: =F19/F18-1 -> 0.15331534 | G20: =G19/G18-1 -> -0.17457075 | H20: =H19/H18-1 -> -0.072871471 | I20: =I19/I18-1 -> -0.4167691 | J20: =J19/J18-1 -> -1 | ... O20: =O19/O18-1 -> -0.55794959
B22: SOBRAL - ITAPIPOCA
C23: JAN | D23: FEV | E23: MAR | F23: ABR | G23: MAI | H23: JUN | I23: JUL | J23: AGO | K23: SET | L23: OUT | M23: NOV | N23: DEZ | O23: TOTAL
B24: 2023 | C24: =C4+C14 -> 89539 | D24: =D4+D14 -> 80524.84 | E24: =E4+E14 -> 144175.15 | F24: =F4+F14 -> 135086 | G24: =G4+G14 -> 137978.5 | H24: =H4+H14 -> 166902 | I24: =I4+I14 -> 130672.4 | J24: =J4+J14 -> 137031 | ... N24: =N4+N14 -> 371805.22 | O24: =SUM(C24:N24) -> 2014837.2
B25: 2024 | C25: =C5+C15 -> 74937.4 | D25: =D5+D15 -> 144783.61 | E25: =E5+E15 -> 200742.55 | F25: =F5+F15 -> 152753.9 | G25: =G5+G15 -> 243029.88 | H25: =H5+H15 -> 205076.8 | I25: =I5+I15 -> 342791.3 | J25: =J5+J15 -> 243750.3 | ... N25: =N5+N15 -> 382130.7 | O25: =SUM(C25:N25) -> 2754356.5
B26: TAXA DE CRESCIMENTO 2023/2024 | C26: =C25/C24-1 -> -0.16307531 | D26: =D25/D24-1 -> 0.79799935 | E26: =E25/E24-1 -> 0.39235194 | F26: =F25/F24-1 -> 0.13079002 | G26: =G25/G24-1 -> 0.7613605 | H26: =H25/H24-1 -> 0.22872584 | I26: =I25/I24-1 -> 1.6232877 | J26: =J25/J24-1 -> 0.77879677 | ... O26: =O25/O24-1 -> 0.36703678
B27: TAXA DE CRESCIMENTO ESPERADA 2025 | C27: 0.2 | D27: 0.2 | E27: 0.2 | F27: 0.2 | G27: 0.2 | H27: 0.2 | I27: 0.2 | J27: 0.2 | K27: 0.2 | L27: 0.2 | M27: 0.2 | N27: 0.2 | O27: 0.2
B28: FATURAMENTO ESPERADO 2025 | C28: =C18+C8 -> 89924.88 | D28: =D18+D8 -> 173740.33 | E28: =E18+E8 -> 240891.06 | F28: =F18+F8 -> 183304.68 | G28: =G18+G8 -> 291635.86 | H28: =H18+H8 -> 246092.16 | I28: =I18+I8 -> 411349.56 | J28: =J18+J8 -> 292500.36 | ... N28: =N18+N8 -> 458556.84 | O28: =SUM(C28:N28) -> 3305227.8
B29: FATURAMENTO REAL | C29: =C9+C19 -> 94149 | D29: =D9+D19 -> 155130.5 | E29: =E9+E19 -> 273288.55 | F29: =F9+F19 -> 201973.9 | G29: =G9+G19 -> 272353 | H29: =H9+H19 -> 230804.47 | I29: =I9+I19 -> 287943.5 | O29: =SUM(C29:N29) -> 1515642.9
B30: DIFRENÇA | C30: =C29/C28-1 -> 0.046973874 | D30: =D29/D28-1 -> -0.10711291 | E30: =E29/E28-1 -> 0.13449021 | F30: =F29/F28-1 -> 0.10184803 | G30: =G29/G28-1 -> -0.066119634 | H30: =H29/H28-1 -> -0.062121808 | I30: =I29/I28-1 -> -0.3000029 | J30: =J29/J28-1 -> -1 | ... O30: =O29/O28-1 -> -0.54144071

Sheet VENDAS_VENDEDOR
J1: VENDAS - METAS INDIVIDUAIS | O1: VENDAS - ONLINE | T1: QUANTIDADE DE VENDEDORAS | U1: % ONLINE
J2: META MÍNIMA | K2: TOP 1 | L2: TOP 2 | M2: MASTER | O2: META MÍNIMA | P2: TOP 1 | Q2: TOP 2 | R2: MASTER | T2: 3 | U2: 0.2
B3: METAS POR DIA | G3: AIANE | J3: =Q6 -> 13333.333 | K3: =Q7 -> 16666.667 | L3: =Q8 -> 20000 | M3: =Q9 -> 26666.667 | O3: =R6 -> 0 | P3: =R7 -> 0 | Q3: =R8 -> 0 | R3: =R9 -> 0
B4: DATA | C4: DIA DA SEMANA | D4: VALOR REALIZADO | E4: VENDEDOR | G4: BIANCA
B5: =Tabela37[[#This Row],[DATA]] -> 46113 | C5: =UPPER(TEXT(B5,"dddd")) -> QUARTA-FEIRA | D5: 39142 | E5: AIANE | G5: LUCIJANE | Q5: META VENDEDORA | R5: ONLINE
B6: =Tabela37[[#This Row],[DATA]] -> 46114 | C6: =UPPER(TEXT(B6,"dddd")) -> QUINTA-FEIRA | E6: AIANE | G6: ALINE | H6: VENDAS /MÊS DIFERENÇA | P6: MÍNIMA | Q6: =(ITAPIPOCA!K2-VENDAS_VENDEDOR!R6)/3 -> 13333.333 | R6: 0 | S6: =Q6*3 -> 40000
B7: =Tabela37[[#This Row],[DATA]] -> 46115 | C7: =UPPER(TEXT(B7,"dddd")) -> SEXTA-FEIRA | E7: AIANE | G7: LOJA | H7: VENDEDORA | I7: VALOR REALIZADO | J7: META MÍNIMA | K7: TOP 1 | L7: TOP 2 | M7: MASTER | P7: TOP 1 | Q7: =(ITAPIPOCA!K7-VENDAS_VENDEDOR!R7)/3 -> 16666.667 | R7: 0 | S7: =Q7*3 -> 50000
B8: =Tabela37[[#This Row],[DATA]] -> 46116 | C8: =UPPER(TEXT(B8,"dddd")) -> SÁBADO | E8: AIANE | H8: AIANE | I8: =SUMIFS($D$5:$D$128,$E$5:$E$128,H8) -> 39142 | J8: =I8-$J$3 -> 25808.667 | K8: =I8-$K$3 -> 22475.333 | L8: =I8-$L$3 -> 19142 | M8: =I8-$M$3 -> 12475.333 | P8: TOP 2 | Q8: =(ITAPIPOCA!K13-VENDAS_VENDEDOR!R8)/3 -> 20000 | R8: 0 | S8: =Q8*3 -> 60000
B9: =Tabela37[[#This Row],[DATA]] -> 46117 | C9: =UPPER(TEXT(B9,"dddd")) -> DOMINGO | E9: AIANE | H9: LUCIJANE | I9: =SUMIFS($D$5:$D$128,$E$5:$E$128,H9) -> 25432 | J9: =I9-$J$3 -> 12098.667 | K9: =I9-$K$3 -> 8765.3333 | L9: =I9-$L$3 -> 5432 | M9: =I9-$M$3 -> -1234.6667 | P9: MASTER | Q9: =(ITAPIPOCA!K19-VENDAS_VENDEDOR!R9)/3 -> 26666.667 | R9: 0 | S9: =Q9*3 -> 80000
B10: =Tabela37[[#This Row],[DATA]] -> 46118 | C10: =UPPER(TEXT(B10,"dddd")) -> SEGUNDA-FEIRA | E10: AIANE | H10: ALINE | I10: =SUMIFS($D$5:$D$128,$E$5:$E$128,H10) -> 36555 | J10: =I10-$J$3 -> 23221.667 | K10: =I10-$K$3 -> 19888.333 | L10: =I10-$L$3 -> 16555 | M10: =I10-$M$3 -> 9888.3333
B11: =Tabela37[[#This Row],[DATA]] -> 46119 | C11: =UPPER(TEXT(B11,"dddd")) -> TERÇA-FEIRA | E11: AIANE
B12: =Tabela37[[#This Row],[DATA]] -> 46120 | C12: =UPPER(TEXT(B12,"dddd")) -> QUARTA-FEIRA | E12: AIANE
B13: =Tabela37[[#This Row],[DATA]] -> 46121 | C13: =UPPER(TEXT(B13,"dddd")) -> QUINTA-FEIRA | E13: AIANE | I13: STATUS META
B14: =Tabela37[[#This Row],[DATA]] -> 46122 | C14: =UPPER(TEXT(B14,"dddd")) -> SEXTA-FEIRA | E14: AIANE | I14: VENDEDORA | J14: META MÍNIMA | K14: TOP 1 | L14: TOP 2 | M14: MASTER
B15: =Tabela37[[#This Row],[DATA]] -> 46123 | C15: =UPPER(TEXT(B15,"dddd")) -> SÁBADO | E15: AIANE | I15: AIANE | J15: =IF(J8>0,"BATEU","NÃO ALCANÇADO") -> BATEU | K15: =IF(K8>0,"BATEU","NÃO ALCANÇADO") -> BATEU | L15: =IF(L8>0,"BATEU","NÃO ALCANÇADO") -> BATEU | M15: =IF(M8>0,"BATEU","NÃO ALCANÇADO") -> BATEU
B16: =Tabela37[[#This Row],[DATA]] -> 46124 | C16: =UPPER(TEXT(B16,"dddd")) -> DOMINGO | E16: AIANE | I16: ALINE | J16: =IF(J9>0,"BATEU","NÃO ALCANÇADO") -> BATEU | K16: =IF(K9>0,"BATEU","NÃO ALCANÇADO") -> BATEU | L16: =IF(L9>0,"BATEU","NÃO ALCANÇADO") -> BATEU | M16: =IF(M9>0,"BATEU","NÃO ALCANÇADO") -> NÃO ALCANÇADO
B17: =Tabela37[[#This Row],[DATA]] -> 46125 | C17: =UPPER(TEXT(B17,"dddd")) -> SEGUNDA-FEIRA | E17: AIANE | I17: LUCIJANE | J17: =IF(J10>0,"BATEU","NÃO ALCANÇADO") -> BATEU | K17: =IF(K10>0,"BATEU","NÃO ALCANÇADO") -> BATEU | L17: =IF(L10>0,"BATEU","NÃO ALCANÇADO") -> BATEU | M17: =IF(M10>0,"BATEU","NÃO ALCANÇADO") -> BATEU
B18: =Tabela37[[#This Row],[DATA]] -> 46126 | C18: =UPPER(TEXT(B18,"dddd")) -> TERÇA-FEIRA | E18: AIANE | J18: =IF(#REF!>0,"BATEU","NÃO ALCANÇADO") -> #REF! | K18: =IF(#REF!>0,"BATEU","NÃO ALCANÇADO") -> #REF! | L18: =IF(#REF!>0,"BATEU","NÃO ALCANÇADO") -> #REF! | M18: =IF(#REF!>0,"BATEU","NÃO ALCANÇADO") -> #REF!
B19: =Tabela37[[#This Row],[DATA]] -> 46127 | C19: =UPPER(TEXT(B19,"dddd")) -> QUARTA-FEIRA | E19: AIANE | I19: % | J19: 0.01 | K19: 0.013 | L19: 0.015 | M19: 0.02
B20: =Tabela37[[#This Row],[DATA]] -> 46128 | C20: =UPPER(TEXT(B20,"dddd")) -> QUINTA-FEIRA | E20: AIANE | I20: COMISSÕES VALORES
B21: =Tabela37[[#This Row],[DATA]] -> 46129 | C21: =UPPER(TEXT(B21,"dddd")) -> SEXTA-FEIRA | E21: AIANE | I21: VENDEDORA | J21: META MÍNIMA | K21: TOP 1 | L21: TOP 2 | M21: MASTER
B22: =Tabela37[[#This Row],[DATA]] -> 46130 | C22: =UPPER(TEXT(B22,"dddd")) -> SÁBADO | E22: AIANE | I22: AIANE | J22: =IF(J15="NÃO ALCANÇADO","NÃO ALCANÇADO",$J$3*$J$19) -> 133.33333 | K22: =IF(K15="NÃO ALCANÇADO","NÃO ALCANÇADO",$K$3*$K$19) -> 216.66667 | L22: =IF(L15="NÃO ALCANÇADO","NÃO ALCANÇADO",$L$3*$L$19) -> 300 | M22: =IF(M15="NÃO ALCANÇADO","NÃO ALCANÇADO",$M$3*$I$20) -> #VALUE!
B23: =Tabela37[[#This Row],[DATA]] -> 46131 | C23: =UPPER(TEXT(B23,"dddd")) -> DOMINGO | E23: AIANE | I23: ALINE | J23: =IF(J16="NÃO ALCANÇADO","NÃO ALCANÇADO",$J$3*$J$19) -> 133.33333 | K23: =IF(K16="NÃO ALCANÇADO","NÃO ALCANÇADO",$K$3*$K$19) -> 216.66667 | L23: =IF(L16="NÃO ALCANÇADO","NÃO ALCANÇADO",$L$3*$L$19) -> 300 | M23: =IF(M16="NÃO ALCANÇADO","NÃO ALCANÇADO",$M$3*$I$20) -> NÃO ALCANÇADO
B24: =Tabela37[[#This Row],[DATA]] -> 46132 | C24: =UPPER(TEXT(B24,"dddd")) -> SEGUNDA-FEIRA | E24: AIANE | J24: =IF(J17="NÃO ALCANÇADO","NÃO ALCANÇADO",$J$3*$J$19) -> 133.33333 | K24: =IF(K17="NÃO ALCANÇADO","NÃO ALCANÇADO",$K$3*$K$19) -> 216.66667 | L24: =IF(L17="NÃO ALCANÇADO","NÃO ALCANÇADO",$L$3*$L$19) -> 300 | M24: =IF(M17="NÃO ALCANÇADO","NÃO ALCANÇADO",$M$3*$I$20) -> #VALUE!
B25: =Tabela37[[#This Row],[DATA]] -> 46133 | C25: =UPPER(TEXT(B25,"dddd")) -> TERÇA-FEIRA | E25: AIANE | J25: =IF(J18="NÃO ALCANÇADO","NÃO ALCANÇADO",$J$3*$J$19) -> #REF! | K25: =IF(K18="NÃO ALCANÇADO","NÃO ALCANÇADO",$K$3*$K$19) -> #REF! | L25: =IF(L18="NÃO ALCANÇADO","NÃO ALCANÇADO",$L$3*$L$19) -> #REF! | M25: =IF(M18="NÃO ALCANÇADO","NÃO ALCANÇADO",$M$3*$I$20) -> #REF!
B26: =Tabela37[[#This Row],[DATA]] -> 46134 | C26: =UPPER(TEXT(B26,"dddd")) -> QUARTA-FEIRA | E26: AIANE
B27: =Tabela37[[#This Row],[DATA]] -> 46135 | C27: =UPPER(TEXT(B27,"dddd")) -> QUINTA-FEIRA | E27: AIANE
B28: =Tabela37[[#This Row],[DATA]] -> 46136 | C28: =UPPER(TEXT(B28,"dddd")) -> SEXTA-FEIRA | E28: AIANE
B29: =Tabela37[[#This Row],[DATA]] -> 46137 | C29: =UPPER(TEXT(B29,"dddd")) -> SÁBADO | E29: AIANE
B30: =Tabela37[[#This Row],[DATA]] -> 46138 | C30: =UPPER(TEXT(B30,"dddd")) -> DOMINGO | E30: AIANE
B31: =Tabela37[[#This Row],[DATA]] -> 46139 | C31: =UPPER(TEXT(B31,"dddd")) -> SEGUNDA-FEIRA | E31: AIANE
B32: =Tabela37[[#This Row],[DATA]] -> 46140 | C32: =UPPER(TEXT(B32,"dddd")) -> TERÇA-FEIRA | E32: AIANE
B33: =Tabela37[[#This Row],[DATA]] -> 46141 | C33: =UPPER(TEXT(B33,"dddd")) -> QUARTA-FEIRA | E33: AIANE
B34: =Tabela37[[#This Row],[DATA]] -> 46142 | C34: =UPPER(TEXT(B34,"dddd")) -> QUINTA-FEIRA | E34: AIANE
B35: =Tabela37[[#This Row],[DATA]] -> 46143 | C35: =UPPER(TEXT(B35,"dddd")) -> SEXTA-FEIRA | E35: AIANE
B36: 45992 | C36: =UPPER(TEXT(B36,"dddd")) -> SEGUNDA-FEIRA | E36: BIANCA
B37: 45993 | C37: =UPPER(TEXT(B37,"dddd")) -> TERÇA-FEIRA | E37: BIANCA
B38: 45994 | C38: =UPPER(TEXT(B38,"dddd")) -> QUARTA-FEIRA | E38: BIANCA
B39: 45995 | C39: =UPPER(TEXT(B39,"dddd")) -> QUINTA-FEIRA | E39: BIANCA
B40: 45996 | C40: =UPPER(TEXT(B40,"dddd")) -> SEXTA-FEIRA | E40: BIANCA
...

Sheet Planilha1
G1: VENDAS - METAS INDIVIDUAIS
D2: Ranking | G2: VENDEDOR | H2: VENDAS | I2: META MÍNIMA | J2: TOP 1 | K2: TOP 2 | L2: MASTER | M2: META MÍNIMA | N2: TOP 1 | O2: TOP 2 | P2: MASTER
B3: =VLOOKUP(C3,$F$3:$G$6,2,0) -> #REF! | C3: =LARGE($H$3:$H$6,1) -> #REF! | D3: 5000 | F3: =H3 -> 39142 | G3: =VENDAS_VENDEDOR!H8 -> AIANE | H3: =VENDAS_VENDEDOR!I8 -> 39142 | I3: =VENDAS_VENDEDOR!J3 -> 13333.333 | J3: =VENDAS_VENDEDOR!K3 -> 16666.667 | K3: =VENDAS_VENDEDOR!L3 -> 20000 | L3: =VENDAS_VENDEDOR!M3 -> 26666.667 | M3: =IF(H3>L3,H3,IF(H3>K3,H3,IF(H3>J3,H3,IF(H3>I3,H3,"")))) -> 39142 | N3: =IF(H3>L3,H3,IF(H3>K3,H3,IF(H3>J3,H3,""))) -> 39142 | O3: =IF(H3>L3,H3,IF(H3>K3,H3,"")) -> 39142 | P3: =IF(H3>L3,H3,"") -> 39142
B4: =VLOOKUP(C4,$F$3:$G$6,2,0) -> #REF! | C4: =LARGE($H$3:$H$6,2) -> #REF! | D4: 5000 | F4: =H4 -> #REF! | G4: =VENDAS_VENDEDOR!#REF! -> #REF! | H4: =VENDAS_VENDEDOR!#REF! -> #REF! | I4: =VENDAS_VENDEDOR!J3 -> 13333.333 | J4: =VENDAS_VENDEDOR!K3 -> 16666.667 | K4: =VENDAS_VENDEDOR!L3 -> 20000 | L4: =VENDAS_VENDEDOR!M3 -> 26666.667 | M4: =IF(H4>L4,H4,IF(H4>K4,H4,IF(H4>J4,H4,IF(H4>I4,H4,"")))) -> #REF! | N4: =IF(H4>L4,H4,IF(H4>K4,H4,IF(H4>J4,H4,""))) -> #REF! | O4: =IF(H4>L4,H4,IF(H4>K4,H4,"")) -> #REF! | P4: =IF(H4>L4,H4,"") -> #REF!
B5: =VLOOKUP(C5,$F$3:$G$6,2,0) -> #REF! | C5: =LARGE($H$3:$H$6,3) -> #REF! | D5: 5000 | F5: =H5 -> 25432 | G5: =VENDAS_VENDEDOR!H9 -> LUCIJANE | H5: =VENDAS_VENDEDOR!I9 -> 25432 | I5: =VENDAS_VENDEDOR!J3 -> 13333.333 | J5: =VENDAS_VENDEDOR!K3 -> 16666.667 | K5: =VENDAS_VENDEDOR!L3 -> 20000 | L5: =VENDAS_VENDEDOR!M3 -> 26666.667 | M5: =IF(H5>L5,H5,IF(H5>K5,H5,IF(H5>J5,H5,IF(H5>I5,H5,"")))) -> 25432 | N5: =IF(H5>L5,H5,IF(H5>K5,H5,IF(H5>J5,H5,""))) -> 25432 | O5: =IF(H5>L5,H5,IF(H5>K5,H5,"")) -> 25432 | P5: =IF(H5>L5,H5,"")
F6: =H6 -> 36555 | G6: =VENDAS_VENDEDOR!H10 -> ALINE | H6: =VENDAS_VENDEDOR!I10 -> 36555 | I6: =VENDAS_VENDEDOR!J3 -> 13333.333 | J6: =VENDAS_VENDEDOR!K3 -> 16666.667 | K6: =VENDAS_VENDEDOR!L3 -> 20000 | L6: =VENDAS_VENDEDOR!M3 -> 26666.667 | M6: =IF(H6>L6,H6,IF(H6>K6,H6,IF(H6>J6,H6,IF(H6>I6,H6,"")))) -> 36555 | N6: =IF(H6>L6,H6,IF(H6>K6,H6,IF(H6>J6,H6,""))) -> 36555 | O6: =IF(H6>L6,H6,IF(H6>K6,H6,"")) -> 36555 | P6: =IF(H6>L6,H6,"") -> 36555
I7: =I6/$L$6 -> 0.5 | J7: =J6/$L$6 -> 0.625 | K7: =K6/$L$6 -> 0.75 | L7: =L6/$L$6 -> 1

Sheet IMAGENS
D3: NOME | E3: FOTO | H3: NOME | I3: FOTO
D4: SHERON | E4: #VALUE! | H4: ALINE | I4: #VALUE!
D5: CRIS | E5: #VALUE! | H5: AIANE | I5: #VALUE!
D6: NARA | E6: #VALUE!

Sheet Detalhes1
A1: Detalhes do Soma de VALOR2 - DIA DA SEMANA: SEGUNDA-FEIRA
A3: DATA | B3: DIA DA SEMANA | C3: VALOR
A4: 45712 | B4: SEGUNDA-FEIRA | C4: 553
A5: 45705 | B5: SEGUNDA-FEIRA | C5: 688
A6: 45691 | B6: SEGUNDA-FEIRA | C6: 1529
A7: 45698 | B7: SEGUNDA-FEIRA | C7: 2398

Sheet ITAPIPOCA
B1: DATA | C1: DIA DA SEMANA | D1: VALOR | F1: ANO | G1: 2026 | J1: MÍNIMA | M1: MÍNIMA | W1: TOP 1 | AG1: TOP 2 | AQ1: MASTER
B2: 46054 | C2: =UPPER(TEXT(B2,"dddd")) -> DOMINGO | D2: =408+284+523 -> 1215 | F2: DIA DA SEMANA | G2: Soma de VALOR2 | H2: % | J2: FATURAMENTO | K2: 40000 | M2: MÊS | N2: ANO | O2: META MENSAL | P2: DIA DA SEMANA | Q2: PERCENTUAL DE REPRESENTATIVIDADE | R2: QUANTIDADE | W2: MÊS | X2: ANO | Y2: META MENSAL | Z2: DIA DA SEMANA | AA2: PERCENTUAL DE REPRESENTATIVIDADE | AB2: QUANTIDADE | AG2: MÊS | AH2: ANO | AI2: META MENSAL | AJ2: DIA DA SEMANA | AK2: PERCENTUAL DE REPRESENTATIVIDADE | AL2: QUANTIDADE | AQ2: MÊS | AR2: ANO | AS2: META MENSAL | AT2: DIA DA SEMANA | AU2: PERCENTUAL DE REPRESENTATIVIDADE | AV2: QUANTIDADE
B3: 46055 | C3: =UPPER(TEXT(B3,"dddd")) -> SEGUNDA-FEIRA | D3: 0 | F3: DOMINGO | G3: 0 | H3: 0 | J3: DIAS ÚTEIS | K3: 26 | M3: 3 | N3: =$G$1 -> 2026 | O3: =$K$2 -> 40000 | P3: DOMINGO | Q3: =$H$3 -> 0 | R3: 4 | W3: =Tabela6[[#This Row],[MÊS]] -> 3 | X3: =Tabela6[[#This Row],[ANO]] -> 2026 | Y3: =$K$7 -> 50000 | Z3: DOMINGO | AA3: =$H$3 -> 0 | AB3: =Tabela6[[#This Row],[QUANTIDADE]] -> 4 | AG3: =Tabela69[[#This Row],[MÊS]] -> 3 | AH3: =Tabela6[[#This Row],[ANO]] -> 2026 | AI3: =$K$13 -> 60000 | AJ3: DOMINGO | AK3: =$H$3 -> 0 | AL3: =Tabela69[[#This Row],[QUANTIDADE]] -> 4 | AQ3: =Tabela6911[[#This Row],[MÊS]] -> 3 | AR3: =Tabela6911[[#This Row],[ANO]] -> 2026 | AS3: =$K$19 -> 80000 | AT3: DOMINGO | AU3: =$H$3 -> 0 | AV3: =Tabela6911[[#This Row],[QUANTIDADE]] -> 4
B4: 46056 | C4: =UPPER(TEXT(B4,"dddd")) -> TERÇA-FEIRA | D4: =255+509+765 -> 1529 | F4: SEGUNDA-FEIRA | G4: 5168 | H4: 0.14633179 | J4: MÉDIA/ DIA | K4: =K2/K3 -> 1538.4615 | M4: 3 | N4: =$G$1 -> 2026 | O4: =$K$2 -> 40000 | P4: SEGUNDA-FEIRA | Q4: =$H$4 -> 0.14633179 | R4: 4 | W4: =Tabela6[[#This Row],[MÊS]] -> 3 | X4: =Tabela6[[#This Row],[ANO]] -> 2026 | Y4: =$K$7 -> 50000 | Z4: SEGUNDA-FEIRA | AA4: =$H$4 -> 0.14633179 | AB4: =Tabela6[[#This Row],[QUANTIDADE]] -> 4 | AG4: =Tabela69[[#This Row],[MÊS]] -> 3 | AH4: =Tabela6[[#This Row],[ANO]] -> 2026 | AI4: =$K$13 -> 60000 | AJ4: SEGUNDA-FEIRA | AK4: =$H$4 -> 0.14633179 | AL4: =Tabela69[[#This Row],[QUANTIDADE]] -> 4 | AQ4: =Tabela6911[[#This Row],[MÊS]] -> 3 | AR4: =Tabela6911[[#This Row],[ANO]] -> 2026 | AS4: =$K$19 -> 80000 | AT4: SEGUNDA-FEIRA | AU4: =$H$4 -> 0.14633179 | AV4: =Tabela6911[[#This Row],[QUANTIDADE]] -> 4
B5: 46057 | C5: =UPPER(TEXT(B5,"dddd")) -> QUARTA-FEIRA | D5: =98+407+35+144+535 -> 1219 | F5: TERÇA-FEIRA | G5: 4533 | H5: 0.12835179 | M5: 3 | N5: =$G$1 -> 2026 | O5: =$K$2 -> 40000 | P5: TERÇA-FEIRA | Q5: =$H$5 -> 0.12835179 | R5: 4 | W5: =Tabela6[[#This Row],[MÊS]] -> 3 | X5: =Tabela6[[#This Row],[ANO]] -> 2026 | Y5: =$K$7 -> 50000 | Z5: TERÇA-FEIRA | AA5: =$H$5 -> 0.12835179 | AB5: =Tabela6[[#This Row],[QUANTIDADE]] -> 4 | AG5: =Tabela69[[#This Row],[MÊS]] -> 3 | AH5: =Tabela6[[#This Row],[ANO]] -> 2026 | AI5: =$K$13 -> 60000 | AJ5: TERÇA-FEIRA | AK5: =$H$5 -> 0.12835179 | AL5: =Tabela69[[#This Row],[QUANTIDADE]] -> 4 | AQ5: =Tabela6911[[#This Row],[MÊS]] -> 3 | AR5: =Tabela6911[[#This Row],[ANO]] -> 2026 | AS5: =$K$19 -> 80000 | AT5: TERÇA-FEIRA | AU5: =$H$5 -> 0.12835179 | AV5: =Tabela6911[[#This Row],[QUANTIDADE]] -> 4
B6: 46058 | C6: =UPPER(TEXT(B6,"dddd")) -> QUINTA-FEIRA | D6: =304+450 -> 754 | F6: QUARTA-FEIRA | G6: 3606 | H6: 0.1021038 | J6: TOP1 | M6: 3 | N6: =$G$1 -> 2026 | O6: =$K$2 -> 40000 | P6: QUARTA-FEIRA | Q6: =$H$6 -> 0.1021038 | R6: 5 | W6: =Tabela6[[#This Row],[MÊS]] -> 3 | X6: =Tabela6[[#This Row],[ANO]] -> 2026 | Y6: =$K$7 -> 50000 | Z6: QUARTA-FEIRA | AA6: =$H$6 -> 0.1021038 | AB6: =Tabela6[[#This Row],[QUANTIDADE]] -> 5 | AG6: =Tabela69[[#This Row],[MÊS]] -> 3 | AH6: =Tabela6[[#This Row],[ANO]] -> 2026 | AI6: =$K$13 -> 60000 | AJ6: QUARTA-FEIRA | AK6: =$H$6 -> 0.1021038 | AL6: =Tabela69[[#This Row],[QUANTIDADE]] -> 5 | AQ6: =Tabela6911[[#This Row],[MÊS]] -> 3 | AR6: =Tabela6911[[#This Row],[ANO]] -> 2026 | AS6: =$K$19 -> 80000 | AT6: QUARTA-FEIRA | AU6: =$H$6 -> 0.1021038 | AV6: =Tabela6911[[#This Row],[QUANTIDADE]] -> 5
B7: 46059 | C7: =UPPER(TEXT(B7,"dddd")) -> SEXTA-FEIRA | D7: =206+1569+358 -> 2133 | F7: QUINTA-FEIRA | G7: 6748 | H7: 0.19106946 | J7: FATURAMENTO | K7: ='ANÁLISE GERAL ITAPIPOCA (2026)'!G21 -> 50000 | M7: 3 | N7: =$G$1 -> 2026 | O7: =$K$2 -> 40000 | P7: QUINTA-FEIRA | Q7: =$H$7 -> 0.19106946 | R7: 5 | W7: =Tabela6[[#This Row],[MÊS]] -> 3 | X7: =Tabela6[[#This Row],[ANO]] -> 2026 | Y7: =$K$7 -> 50000 | Z7: QUINTA-FEIRA | AA7: =$H$7 -> 0.19106946 | AB7: =Tabela6[[#This Row],[QUANTIDADE]] -> 5 | AG7: =Tabela69[[#This Row],[MÊS]] -> 3 | AH7: =Tabela6[[#This Row],[ANO]] -> 2026 | AI7: =$K$13 -> 60000 | AJ7: QUINTA-FEIRA | AK7: =$H$7 -> 0.19106946 | AL7: =Tabela69[[#This Row],[QUANTIDADE]] -> 5 | AQ7: =Tabela6911[[#This Row],[MÊS]] -> 3 | AR7: =Tabela6911[[#This Row],[ANO]] -> 2026 | AS7: =$K$19 -> 80000 | AT7: QUINTA-FEIRA | AU7: =$H$7 -> 0.19106946 | AV7: =Tabela6911[[#This Row],[QUANTIDADE]] -> 5
B8: 46060 | C8: =UPPER(TEXT(B8,"dddd")) -> SÁBADO | D8: =186+1056+1404 -> 2646 | F8: SEXTA-FEIRA | G8: 10218 | H8: 0.28932242 | J8: DIAS ÚTEIS | K8: =K3 -> 26 | M8: 3 | N8: =$G$1 -> 2026 | O8: =$K$2 -> 40000 | P8: SEXTA-FEIRA | Q8: =$H$8 -> 0.28932242 | R8: 4 | W8: =Tabela6[[#This Row],[MÊS]] -> 3 | X8: =Tabela6[[#This Row],[ANO]] -> 2026 | Y8: =$K$7 -> 50000 | Z8: SEXTA-FEIRA | AA8: =$H$8 -> 0.28932242 | AB8: =Tabela6[[#This Row],[QUANTIDADE]] -> 4 | AG8: =Tabela69[[#This Row],[MÊS]] -> 3 | AH8: =Tabela6[[#This Row],[ANO]] -> 2026 | AI8: =$K$13 -> 60000 | AJ8: SEXTA-FEIRA | AK8: =$H$8 -> 0.28932242 | AL8: =Tabela69[[#This Row],[QUANTIDADE]] -> 4 | AQ8: =Tabela6911[[#This Row],[MÊS]] -> 3 | AR8: =Tabela6911[[#This Row],[ANO]] -> 2026 | AS8: =$K$19 -> 80000 | AT8: SEXTA-FEIRA | AU8: =$H$8 -> 0.28932242 | AV8: =Tabela6911[[#This Row],[QUANTIDADE]] -> 4
