Workbook
Name ANALISE2: #REF!
Name ANALISE2: #REF!
Name ANALISE2: #REF!
Name ANALISE2: #REF!
Name ANALISE2: #REF!
Name ANALISE2: #REF!
Name CalendárioAno1: #REF!
Name CalendárioAno1: #REF!
Name CalendárioAno1: #REF!
Name CalendárioAno1: #REF!
Name CalendárioAno10: #REF!
Name CalendárioAno10: #REF!
Name CalendárioAno10: #REF!
Name CalendárioAno10: #REF!
Name CalendárioAno11: #REF!
Name CalendárioAno11: #REF!
Name CalendárioAno11: #REF!
Name CalendárioAno11: #REF!
Name CalendárioAno12: #REF!
Name CalendárioAno12: #REF!
Name CalendárioAno12: #REF!
Name CalendárioAno12: #REF!
Name CalendárioAno2: #REF!
Name CalendárioAno2: #REF!
Name CalendárioAno2: #REF!
Name CalendárioAno2: #REF!
Name CalendárioAno3: #REF!
Name CalendárioAno3: #REF!
Name CalendárioAno3: #REF!
Name CalendárioAno3: #REF!
Name CalendárioAno4: #REF!
Name CalendárioAno4: #REF!
Name CalendárioAno4: #REF!
Name CalendárioAno4: #REF!
Name CalendárioAno5: #REF!
Name CalendárioAno5: #REF!
Name CalendárioAno5: #REF!
Name CalendárioAno5: #REF!
Name CalendárioAno6: #REF!
Name CalendárioAno6: #REF!
Name CalendárioAno6: #REF!
Name CalendárioAno6: #REF!
Name CalendárioAno7: #REF!
Name CalendárioAno7: #REF!
Name CalendárioAno7: #REF!
Name CalendárioAno7: #REF!
Name CalendárioAno8: #REF!
Name CalendárioAno8: #REF!
Name CalendárioAno8: #REF!
Name CalendárioAno8: #REF!
Name CalendárioAno9: #REF!
Name CalendárioAno9: #REF!
Name CalendárioAno9: #REF!
Name CalendárioAno9: #REF!
Name CaléndárioMês1: #REF!
Name CaléndárioMês1: #REF!
Name CaléndárioMês1: #REF!
Name CaléndárioMês1: #REF!
Name CaléndárioMês10: #REF!
Name CaléndárioMês10: #REF!

Sheet METAS -  SOBRAL
B2: VENDAS - METAS INDIVIDUAIS
B3: META MÍNIMA | C3: TOP 1 | D3: TOP 2 | E3: MASTER
B4: =VENDAS_VENDEDOR!J3 -> 20000 | C4: =VENDAS_VENDEDOR!K3 -> 26000 | D4: =VENDAS_VENDEDOR!L3 -> 32000 | E4: =VENDAS_VENDEDOR!M3 -> 36000
B6: VENDAS - ONLINE
B7: META MÍNIMA | C7: TOP 1 | D7: TOP 2 | E7: MASTER
B8: =VENDAS_VENDEDOR!O3 -> 22000 | C8: =VENDAS_VENDEDOR!P3 -> 28000 | D8: =VENDAS_VENDEDOR!Q3 -> 34000 | E8: =VENDAS_VENDEDOR!R3 -> 40000
B10: MÍNIMO
B11: MÍNIMA | C11: =H32 -> TOTAL
B12: SEMANA 1 | E12: SEMANA 2 | H12: SEMANA 3
B13: DOMINGO | C13: =SOBRAL!O37 | E13: DOMINGO | F13: =SOBRAL!R37 | H13: DOMINGO | I13: =SOBRAL!U37
B14: SEGUNDA-FEIRA | C14: =SOBRAL!O38 | E14: SEGUNDA-FEIRA | F14: =SOBRAL!R38 -> 4767.5176 | H14: SEGUNDA-FEIRA | I14: =SOBRAL!U38 -> 4767.5176
B15: TERÇA-FEIRA | C15: =SOBRAL!O39 | E15: TERÇA-FEIRA | F15: =SOBRAL!R39 -> 4768.9338 | H15: TERÇA-FEIRA | I15: =SOBRAL!U39 -> 4768.9338
B16: QUARTA-FEIRA | C16: =SOBRAL!O40 | E16: QUARTA-FEIRA | F16: =SOBRAL!R40 -> 5654.3789 | H16: QUARTA-FEIRA | I16: =SOBRAL!U40 -> 5654.3789
B17: QUINTA-FEIRA | C17: =SOBRAL!O41 | E17: QUINTA-FEIRA | F17: =SOBRAL!R41 -> 7079.689 | H17: QUINTA-FEIRA | I17: =SOBRAL!U41 -> 7079.689
B18: SEXTA-FEIRA | C18: =SOBRAL!O42 | E18: SEXTA-FEIRA | F18: =SOBRAL!R42 -> 6550.0506 | H18: SEXTA-FEIRA | I18: =SOBRAL!U42 -> 6550.0506
B19: SÁBADO | C19: =SOBRAL!O43 -> 4943.544 | E19: SÁBADO | F19: =SOBRAL!R43 -> 4943.544 | H19: SÁBADO | I19: =SOBRAL!U43 -> 4943.544
B21: TOTAL | C21: =SUM(C14:C19) -> 4943.544 | E21: TOTAL | F21: =SUM(F14:F19) -> 33764.114 | H21: TOTAL | I21: =SUM(I14:I19) -> 33764.114
B23: SEMANA 4 | E23: SEMANA 5 | H23: SEMANA 6
B24: DOMINGO | C24: =SOBRAL!O48 -> 0 | E24: DOMINGO | F24: =SOBRAL!R48 -> 0 | H24: DOMINGO | I24: =SOBRAL!U48 -> 0
B25: SEGUNDA-FEIRA | C25: =SOBRAL!O49 -> 4767.5176 | E25: SEGUNDA-FEIRA | F25: =SOBRAL!R49 -> 4767.5176 | H25: SEGUNDA-FEIRA | I25: =SOBRAL!U49
B26: TERÇA-FEIRA | C26: =SOBRAL!O50 -> 4768.9338 | E26: TERÇA-FEIRA | F26: =SOBRAL!R50 -> 4768.9338 | H26: TERÇA-FEIRA | I26: =SOBRAL!U50
B27: QUARTA-FEIRA | C27: =SOBRAL!O51 -> 5654.3789 | E27: QUARTA-FEIRA | F27: =SOBRAL!R51 -> 5654.3789 | H27: QUARTA-FEIRA | I27: =SOBRAL!U51
B28: QUINTA-FEIRA | C28: =SOBRAL!O52 -> 7079.689 | E28: QUINTA-FEIRA | F28: =SOBRAL!R52 -> 7079.689 | H28: QUINTA-FEIRA | I28: =SOBRAL!U52
B29: SEXTA-FEIRA | C29: =SOBRAL!O53 -> 6550.0506 | E29: SEXTA-FEIRA | F29: =SOBRAL!R53 -> 6550.0506 | H29: SEXTA-FEIRA | I29: =SOBRAL!U53
B30: SÁBADO | C30: =SOBRAL!O54 -> 4943.544 | E30: SÁBADO | F30: =SOBRAL!R54 -> 4943.544 | H30: SÁBADO | I30: =SOBRAL!U54
B32: TOTAL | C32: =SUM(C25:C30) -> 33764.114 | E32: TOTAL | F32: =SUM(F25:F30) -> 33764.114 | H32: TOTAL | I32: =SUM(I25:I30) -> 0
H33: TOTAL DO MÊS | I33: =C21+F21+I21+C32+F32+I32 -> 140000
B34: TOP 1
B35: TOP 1 | C35: =H56 -> TOTAL
B36: SEMANA 1 | E36: SEMANA 2 | H36: SEMANA 3
B37: DOMINGO | C37: =SOBRAL!Y37 | E37: DOMINGO | F37: =SOBRAL!AB37 | H37: DOMINGO | I37: =SOBRAL!AE37
B38: SEGUNDA-FEIRA | C38: =SOBRAL!Y38 | E38: SEGUNDA-FEIRA | F38: =SOBRAL!AB38 -> 5789.1286 | H38: SEGUNDA-FEIRA | I38: =SOBRAL!AE38 -> 5789.1286
B39: TERÇA-FEIRA | C39: =SOBRAL!Y39 | E39: TERÇA-FEIRA | F39: =SOBRAL!AB39 -> 5790.8482 | H39: TERÇA-FEIRA | I39: =SOBRAL!AE39 -> 5790.8482
B40: QUARTA-FEIRA | C40: =SOBRAL!Y40 | E40: QUARTA-FEIRA | F40: =SOBRAL!AB40 -> 6866.0315 | H40: QUARTA-FEIRA | I40: =SOBRAL!AE40 -> 6866.0315
B41: QUINTA-FEIRA | C41: =SOBRAL!Y41 | E41: QUINTA-FEIRA | F41: =SOBRAL!AB41 -> 8596.7652 | H41: QUINTA-FEIRA | I41: =SOBRAL!AE41 -> 8596.7652
B42: SEXTA-FEIRA | C42: =SOBRAL!Y42 | E42: SEXTA-FEIRA | F42: =SOBRAL!AB42 -> 7953.6329 | H42: SEXTA-FEIRA | I42: =SOBRAL!AE42 -> 7953.6329
B43: SÁBADO | C43: =SOBRAL!Y43 -> 6002.8749 | E43: SÁBADO | F43: =SOBRAL!AB43 -> 6002.8749 | H43: SÁBADO | I43: =SOBRAL!AE43 -> 6002.8749
B45: TOTAL | C45: =SUM(C38:C43) -> 6002.8749 | E45: TOTAL | F45: =SUM(F38:F43) -> 40999.281 | H45: TOTAL | I45: =SUM(I38:I43) -> 40999.281
B47: SEMANA 4 | E47: SEMANA 5 | H47: SEMANA 6
B48: DOMINGO | C48: =SOBRAL!Y48 | E48: DOMINGO | F48: =SOBRAL!AB48 | H48: DOMINGO | I48: =SOBRAL!AE48 -> 0
...

Sheet METAS -  SOBRAL (P VENDEDOR)
B2: CENÁRIO 1
B3: MÍNIMA | C3: =H22 -> 110000
B4: SEMANA 1 | E4: SEMANA 2 | H4: SEMANA 3
B5: SEGUNDA-FEIRA | E5: SEGUNDA-FEIRA | F5: 1996.5956 | H5: SEGUNDA-FEIRA | I5: 1996.5956
B6: TERÇA-FEIRA | E6: TERÇA-FEIRA | F6: 3171.2935 | H6: TERÇA-FEIRA | I6: 3171.2935
B7: QUARTA-FEIRA | E7: QUARTA-FEIRA | F7: 3430.6474 | H7: QUARTA-FEIRA | I7: 3430.6474
B8: QUINTA-FEIRA | C8: 5310.086 | E8: QUINTA-FEIRA | F8: 5310.086 | H8: QUINTA-FEIRA | I8: 5310.086
B9: SEXTA-FEIRA | C9: 4632.6457 | E9: SEXTA-FEIRA | F9: 4632.6457 | H9: SEXTA-FEIRA | I9: 4632.6457
B10: SÁBADO | C10: 5301.2718 | E10: SÁBADO | F10: 5301.2718 | H10: SÁBADO | I10: 5301.2718
B12: TOTAL | C12: =SUM(C5:C10) -> 15244.003 | E12: TOTAL | F12: =SUM(F5:F10) -> 23842.54 | H12: TOTAL | I12: =SUM(I5:I10) -> 23842.54
B14: SEMANA 4 | E14: SEMANA 5
B15: SEGUNDA-FEIRA | C15: 1996.5956 | E15: SEGUNDA-FEIRA | F15: 1996.5956
B16: TERÇA-FEIRA | C16: 3171.2935 | E16: TERÇA-FEIRA | F16: 3171.2935
B17: QUARTA-FEIRA | C17: 3430.6474 | E17: QUARTA-FEIRA | F17: 3430.6474
B18: QUINTA-FEIRA | C18: 5310.086 | E18: QUINTA-FEIRA | F18: 5310.086
B19: SEXTA-FEIRA | C19: 4632.6457 | E19: SEXTA-FEIRA | F19: 4632.6457
B20: SÁBADO | C20: 5301.2718 | E20: SÁBADO | F20: =5301.27182076037-614.16 -> 4687.1118
H21: TOTAL DO MÊS
B22: TOTAL | C22: =SUM(C15:C20) -> 23842.54 | E22: TOTAL | F22: =SUM(F15:F20) -> 23228.38 | H22: =F22+C22+C12+F12+I12 -> 110000
B24: CENÁRIO 2
B25: TOP 1 | C25: =H44*3 -> #VALUE!
B26: SEMANA 1 | E26: SEMANA 2 | H26: SEMANA 3
B27: SEGUNDA-FEIRA | C27: ='METAS - SOBRAL'!C38/2 -> #VALUE! | E27: SEGUNDA-FEIRA | F27: ='METAS - SOBRAL'!F38/3 -> 1929.7095 | H27: SEGUNDA-FEIRA | I27: ='METAS - SOBRAL'!I38/3 -> 1929.7095
B28: TERÇA-FEIRA | C28: ='METAS - SOBRAL'!C39/2 -> #VALUE! | E28: TERÇA-FEIRA | F28: ='METAS - SOBRAL'!F39/3 -> 1930.2827 | H28: TERÇA-FEIRA | I28: ='METAS - SOBRAL'!I39/3 -> 1930.2827
B29: QUARTA-FEIRA | C29: ='METAS - SOBRAL'!C40/2 -> #VALUE! | E29: QUARTA-FEIRA | F29: ='METAS - SOBRAL'!F40/3 -> 2288.6772 | H29: QUARTA-FEIRA | I29: ='METAS - SOBRAL'!I40/3 -> 2288.6772
B30: QUINTA-FEIRA | C30: ='METAS - SOBRAL'!C41/3 -> #VALUE! | E30: QUINTA-FEIRA | F30: ='METAS - SOBRAL'!F41/3 -> 2865.5884 | H30: QUINTA-FEIRA | I30: ='METAS - SOBRAL'!I41/3 -> 2865.5884
B31: SEXTA-FEIRA | C31: ='METAS - SOBRAL'!C42/3 -> #VALUE! | E31: SEXTA-FEIRA | F31: ='METAS - SOBRAL'!F42/3 -> 2651.211 | H31: SEXTA-FEIRA | I31: ='METAS - SOBRAL'!I42/3 -> 2651.211
B32: SÁBADO | C32: ='METAS - SOBRAL'!C43/3 -> 2000.9583 | E32: SÁBADO | F32: ='METAS - SOBRAL'!F43/3 -> 2000.9583 | H32: SÁBADO | I32: ='METAS - SOBRAL'!I43/3 -> 2000.9583
B34: TOTAL | C34: =SUM(C27:C32) -> #VALUE! | E34: TOTAL | F34: =SUM(F27:F32) -> 13666.427 | H34: TOTAL | I34: =SUM(I27:I32) -> 13666.427
B36: SEMANA 4 | E36: SEMANA 5
B37: SEGUNDA-FEIRA | C37: ='METAS - SOBRAL'!C49/3 -> 1929.7095 | E37: SEGUNDA-FEIRA | F37: ='METAS - SOBRAL'!F49/3 -> 1929.7095
B38: TERÇA-FEIRA | C38: ='METAS - SOBRAL'!C50/3 -> 1930.2827 | E38: TERÇA-FEIRA | F38: ='METAS - SOBRAL'!F50/3 -> 1930.2827
B39: QUARTA-FEIRA | C39: ='METAS - SOBRAL'!C51/3 -> 2288.6772 | E39: QUARTA-FEIRA | F39: ='METAS - SOBRAL'!F51/3 -> 2288.6772
B40: QUINTA-FEIRA | C40: ='METAS - SOBRAL'!C52/3 -> 2865.5884 | E40: QUINTA-FEIRA | F40: ='METAS - SOBRAL'!F52/3 -> 2865.5884
B41: SEXTA-FEIRA | C41: ='METAS - SOBRAL'!C53/3 -> 2651.211 | E41: SEXTA-FEIRA | F41: ='METAS - SOBRAL'!F53/3 -> 2651.211
B42: SÁBADO | C42: ='METAS - SOBRAL'!C54/3 -> 2000.9583 | E42: SÁBADO | F42: ='METAS - SOBRAL'!F54/3 -> 2000.9583
H43: TOTAL DO MÊS
B44: TOTAL | C44: =SUM(C37:C42) -> 13666.427 | E44: TOTAL | F44: =SUM(F37:F42) -> 13666.427 | H44: =F44+C44+C34+F34+I34 -> #VALUE!
B46: CENÁRIO 3
B47: TOP 2 | C47: =H66*3 -> #VALUE!
...

Sheet VENDAS
I1: MÊS | J1: 5
I2: ANO | J2: 2026
L3: METAS POR DIA - DIFERENÇA | S3: VENDAS /SEMANA | Z3: VENDAS /SEMANA - SOBRAL | AG3: Valores > 0 | AH3: Valores realizados sufientes para suprir a meta. O valor negativo significa a diferença superada na semana.
B4: CÓDIGO | C4: DATA | D4: DIA DA SEMANA | E4: VALOR REALIZADO | F4: SEMANA | G4: META MÍNIMA | H4: TOP 1 | I4: TOP 2 | J4: MASTER | L4: DATA | M4: Valor | N4: META MÍNIMA | O4: TOP 1 | P4: TOP2 | Q4: MASTER | S4: SEMANA | T4: VALOR REALIZADO | U4: META MÍNIMA | V4: TOP 1 | W4: TOP2 | X4: MASTER | Z4: SEMANA | AA4: VALOR REALIZADO | AB4: META MÍNIMA | AC4: TOP 1 | AD4: TOP2 | AE4: MASTER
B5: 1 | C5: =DATE($J$2,$J$1,B5) -> 46143 | D5: =UPPER(TEXT(C5,"dddd")) -> SEXTA-FEIRA | F5: ="Semana " & INT((DAY(C5)+WEEKDAY(DATE(YEAR(C5),MONTH(C5),1),1)-2)/7)+1 -> Semana 1 | G5: ='METAS - SOBRAL'!C18 | H5: ='METAS - SOBRAL'!C42 | I5: ='METAS - SOBRAL'!C66 | J5: ='METAS - SOBRAL'!C90 | L5: =Tabela37[[#This Row],[DATA]] -> 46143 | M5: =Tabela37[[#This Row],[VALOR REALIZADO]] -> 0 | N5: =IFERROR(E5-Tabela37[[#This Row],[META MÍNIMA]],"") | O5: =IFERROR(E5-Tabela37[[#This Row],[TOP 1]],"") | P5: =IFERROR(E5-Tabela37[[#This Row],[TOP 2]],"") | Q5: =IFERROR(E5-Tabela37[[#This Row],[MASTER]],"") | S5: Semana 1 | T5: =SUMIF($F$5:$F$35,S5,$E$5:$E$35) -> 0 | U5: =SUM('METAS - SOBRAL'!C14:C19) -> 4943.544 | V5: =SUM('METAS - SOBRAL'!C38:C43) -> 6002.8749 | W5: =SUM('METAS - SOBRAL'!C62:C67) -> 7062.2057 | X5: =SUM('METAS - SOBRAL'!C86:C91) -> 8121.5366 | Z5: 1 | AA5: =T5 -> 0 | AB5: =$T$5-U5 -> -4943.544 | AC5: =$T$5-V5 -> -6002.8749 | AD5: =$T$5-W5 -> -7062.2057 | AE5: =IF(AD5="","",$T$5-X5) -> -8121.5366 | AG5: Valores < 0 | AH5: Valores realizados não sufientes para suprir a meta. O valor positivo significa a diferença não alcançada.
B6: 2 | C6: =DATE($J$2,$J$1,B6) -> 46144 | D6: =UPPER(TEXT(C6,"dddd")) -> SÁBADO | F6: ="Semana " & INT((DAY(C6)+WEEKDAY(DATE(YEAR(C6),MONTH(C6),1),1)-2)/7)+1 -> Semana 1 | G6: ='METAS - SOBRAL'!C19 -> 4943.544 | H6: ='METAS - SOBRAL'!C43 -> 6002.8749 | I6: ='METAS - SOBRAL'!C67 -> 7062.2057 | J6: ='METAS - SOBRAL'!C91 -> 8121.5366 | L6: =Tabela37[[#This Row],[DATA]] -> 46144 | M6: =Tabela37[[#This Row],[VALOR REALIZADO]] -> 0 | N6: =IFERROR(E6-Tabela37[[#This Row],[META MÍNIMA]],"") -> -4943.544 | O6: =IFERROR(E6-Tabela37[[#This Row],[TOP 1]],"") -> -6002.8749 | P6: =IFERROR(E6-Tabela37[[#This Row],[TOP 2]],"") -> -7062.2057 | Q6: =IFERROR(E6-Tabela37[[#This Row],[MASTER]],"") -> -8121.5366 | S6: Semana 2 | T6: =SUMIF($F$5:$F$35,S6,$E$5:$E$35) -> 0 | U6: =SUM('METAS - SOBRAL'!F14:F19) -> 33764.114 | V6: =SUM('METAS - SOBRAL'!F38:F43) -> 40999.281 | W6: =SUM('METAS - SOBRAL'!F62:F67) -> 48234.449 | X6: =SUM('METAS - SOBRAL'!F86:F91) -> 55469.616 | Z6: 2 | AA6: =T6 -> 0 | AB6: =IF(AA6="","",$T$6-U6) -> -33764.114 | AC6: =IF(AB6="","",$T$6-V6) -> -40999.281 | AD6: =IF(AC6="","",$T$6-W6) -> -48234.449 | AE6: =IF(AD6="","",$T$6-X6) -> -55469.616
B7: 3 | C7: =DATE($J$2,$J$1,B7) -> 46145 | D7: =UPPER(TEXT(C7,"dddd")) -> DOMINGO | F7: ="Semana " & INT((DAY(C7)+WEEKDAY(DATE(YEAR(C7),MONTH(C7),1),1)-2)/7)+1 -> Semana 2 | G7: ='METAS - SOBRAL'!F13 | H7: ='METAS - SOBRAL'!F37 | I7: ='METAS - SOBRAL'!F61 | J7: ='METAS - SOBRAL'!F85 | L7: =Tabela37[[#This Row],[DATA]] -> 46145 | M7: =Tabela37[[#This Row],[VALOR REALIZADO]] -> 0 | N7: =IFERROR(E7-Tabela37[[#This Row],[META MÍNIMA]],"") | O7: =IFERROR(E7-Tabela37[[#This Row],[TOP 1]],"") | P7: =IFERROR(E7-Tabela37[[#This Row],[TOP 2]],"") | Q7: =IFERROR(E7-Tabela37[[#This Row],[MASTER]],"") | S7: Semana 3 | T7: =SUMIF($F$5:$F$35,S7,$E$5:$E$35) -> 0 | U7: =SUM('METAS - SOBRAL'!I14:I19) -> 33764.114 | V7: =SUM('METAS - SOBRAL'!I38:I43) -> 40999.281 | W7: =SUM('METAS - SOBRAL'!I62:I67) -> 48234.449 | X7: =SUM('METAS - SOBRAL'!I86:I91) -> 55469.616 | Z7: 3 | AA7: =T7 -> 0 | AB7: =IF(AA7="","",$T$7-U7) -> -33764.114 | AC7: =IF(AB7="","",$T$7-V7) -> -40999.281 | AD7: =IF(AC7="","",$T$7-W7) -> -48234.449 | AE7: =IF(AD7="","",$T$7-X7) -> -55469.616
B8: 4 | C8: =DATE($J$2,$J$1,B8) -> 46146 | D8: =UPPER(TEXT(C8,"dddd")) -> SEGUNDA-FEIRA | F8: ="Semana " & INT((DAY(C8)+WEEKDAY(DATE(YEAR(C8),MONTH(C8),1),1)-2)/7)+1 -> Semana 2 | G8: ='METAS - SOBRAL'!F14 -> 4767.5176 | H8: ='METAS - SOBRAL'!F38 -> 5789.1286 | I8: ='METAS - SOBRAL'!F62 -> 6810.7395 | J8: ='METAS - SOBRAL'!F86 -> 7832.3504 | L8: =Tabela37[[#This Row],[DATA]] -> 46146 | M8: =Tabela37[[#This Row],[VALOR REALIZADO]] -> 0 | N8: =IFERROR(E8-Tabela37[[#This Row],[META MÍNIMA]],"") -> -4767.5176 | O8: =IFERROR(E8-Tabela37[[#This Row],[TOP 1]],"") -> -5789.1286 | P8: =IFERROR(E8-Tabela37[[#This Row],[TOP 2]],"") -> -6810.7395 | Q8: =IFERROR(E8-Tabela37[[#This Row],[MASTER]],"") -> -7832.3504 | S8: Semana 4 | T8: =SUMIF($F$5:$F$35,S8,$E$5:$E$35) -> 0 | U8: =SUM('METAS - SOBRAL'!C25:C30) -> 33764.114 | V8: =SUM('METAS - SOBRAL'!C49:C54) -> 40999.281 | W8: =SUM('METAS - SOBRAL'!C73:C78) -> 48234.449 | X8: =SUM('METAS - SOBRAL'!C97:C102) -> 55469.616 | Z8: 4 | AA8: =T8 -> 0 | AB8: =IF(AA8="","",$T$8-U8) -> -33764.114 | AC8: =IF(AB8="","",$T$8-V8) -> -40999.281 | AD8: =IF(AC8="","",$T$8-W8) -> -48234.449 | AE8: =IF(AD8="","",$T$8-X8) -> -55469.616
B9: 5 | C9: =DATE($J$2,$J$1,B9) -> 46147 | D9: =UPPER(TEXT(C9,"dddd")) -> TERÇA-FEIRA | F9: ="Semana " & INT((DAY(C9)+WEEKDAY(DATE(YEAR(C9),MONTH(C9),1),1)-2)/7)+1 -> Semana 2 | G9: ='METAS - SOBRAL'!F15 -> 4768.9338 | H9: ='METAS - SOBRAL'!F39 -> 5790.8482 | I9: ='METAS - SOBRAL'!F63 -> 6812.7626 | J9: ='METAS - SOBRAL'!F87 -> 7834.677 | L9: =Tabela37[[#This Row],[DATA]] -> 46147 | M9: =Tabela37[[#This Row],[VALOR REALIZADO]] -> 0 | N9: =IFERROR(E9-Tabela37[[#This Row],[META MÍNIMA]],"") -> -4768.9338 | O9: =IFERROR(E9-Tabela37[[#This Row],[TOP 1]],"") -> -5790.8482 | P9: =IFERROR(E9-Tabela37[[#This Row],[TOP 2]],"") -> -6812.7626 | Q9: =IFERROR(E9-Tabela37[[#This Row],[MASTER]],"") -> -7834.677 | S9: Semana 5 | T9: =SUMIF($F$5:$F$35,S9,$E$5:$E$35) -> 0 | U9: =SUM('METAS - SOBRAL'!F25:F30) -> 33764.114 | V9: =SUM('METAS - SOBRAL'!F49:F54) -> 40999.281 | W9: =SUM('METAS - SOBRAL'!F73:F78) -> 48234.449 | X9: =SUM('METAS - SOBRAL'!F97:F102) -> 55469.616 | Z9: 5 | AA9: =T9 -> 0 | AB9: =IF(AA9="","",$T$9-U9) -> -33764.114 | AC9: =IF(AB9="","",$T$9-V9) -> -40999.281 | AD9: =IF(AC9="","",$T$9-W9) -> -48234.449 | AE9: =IF(AD9="","",$T$9-X9) -> -55469.616
B10: 6 | C10: =DATE($J$2,$J$1,B10) -> 46148 | D10: =UPPER(TEXT(C10,"dddd")) -> QUARTA-FEIRA | F10: ="Semana " & INT((DAY(C10)+WEEKDAY(DATE(YEAR(C10),MONTH(C10),1),1)-2)/7)+1 -> Semana 2 | G10: ='METAS - SOBRAL'!F16 -> 5654.3789 | H10: ='METAS - SOBRAL'!F40 -> 6866.0315 | I10: ='METAS - SOBRAL'!F64 -> 8077.6841 | J10: ='METAS - SOBRAL'!F88 -> 9289.3368 | L10: =Tabela37[[#This Row],[DATA]] -> 46148 | M10: =Tabela37[[#This Row],[VALOR REALIZADO]] -> 0 | N10: =IFERROR(E10-Tabela37[[#This Row],[META MÍNIMA]],"") -> -5654.3789 | O10: =IFERROR(E10-Tabela37[[#This Row],[TOP 1]],"") -> -6866.0315 | P10: =IFERROR(E10-Tabela37[[#This Row],[TOP 2]],"") -> -8077.6841 | Q10: =IFERROR(E10-Tabela37[[#This Row],[MASTER]],"") -> -9289.3368
B11: 7 | C11: =DATE($J$2,$J$1,B11) -> 46149 | D11: =UPPER(TEXT(C11,"dddd")) -> QUINTA-FEIRA | F11: ="Semana " & INT((DAY(C11)+WEEKDAY(DATE(YEAR(C11),MONTH(C11),1),1)-2)/7)+1 -> Semana 2 | G11: ='METAS - SOBRAL'!F17 -> 7079.689 | H11: ='METAS - SOBRAL'!F41 -> 8596.7652 | I11: ='METAS - SOBRAL'!F65 -> 10113.841 | J11: ='METAS - SOBRAL'!F89 -> 11630.918 | L11: =Tabela37[[#This Row],[DATA]] -> 46149 | M11: =Tabela37[[#This Row],[VALOR REALIZADO]] -> 0 | N11: =IFERROR(E11-Tabela37[[#This Row],[META MÍNIMA]],"") -> -7079.689 | O11: =IFERROR(E11-Tabela37[[#This Row],[TOP 1]],"") -> -8596.7652 | P11: =IFERROR(E11-Tabela37[[#This Row],[TOP 2]],"") -> -10113.841 | Q11: =IFERROR(E11-Tabela37[[#This Row],[MASTER]],"") -> -11630.918
B12: 8 | C12: =DATE($J$2,$J$1,B12) -> 46150 | D12: =UPPER(TEXT(C12,"dddd")) -> SEXTA-FEIRA | F12: ="Semana " & INT((DAY(C12)+WEEKDAY(DATE(YEAR(C12),MONTH(C12),1),1)-2)/7)+1 -> Semana 2 | G12: ='METAS - SOBRAL'!F18 -> 6550.0506 | H12: ='METAS - SOBRAL'!F42 -> 7953.6329 | I12: ='METAS - SOBRAL'!F66 -> 9357.2152 | J12: ='METAS - SOBRAL'!F90 -> 10760.797 | L12: =Tabela37[[#This Row],[DATA]] -> 46150 | M12: =Tabela37[[#This Row],[VALOR REALIZADO]] -> 0 | N12: =IFERROR(E12-Tabela37[[#This Row],[META MÍNIMA]],"") -> -6550.0506 | O12: =IFERROR(E12-Tabela37[[#This Row],[TOP 1]],"") -> -7953.6329 | P12: =IFERROR(E12-Tabela37[[#This Row],[TOP 2]],"") -> -9357.2152 | Q12: =IFERROR(E12-Tabela37[[#This Row],[MASTER]],"") -> -10760.797
B13: 9 | C13: =DATE($J$2,$J$1,B13) -> 46151 | D13: =UPPER(TEXT(C13,"dddd")) -> SÁBADO | F13: ="Semana " & INT((DAY(C13)+WEEKDAY(DATE(YEAR(C13),MONTH(C13),1),1)-2)/7)+1 -> Semana 2 | G13: ='METAS - SOBRAL'!F19 -> 4943.544 | H13: ='METAS - SOBRAL'!F43 -> 6002.8749 | I13: ='METAS - SOBRAL'!F67 -> 7062.2057 | J13: ='METAS - SOBRAL'!F91 -> 8121.5366 | L13: =Tabela37[[#This Row],[DATA]] -> 46151 | M13: =Tabela37[[#This Row],[VALOR REALIZADO]] -> 0 | N13: =IFERROR(E13-Tabela37[[#This Row],[META MÍNIMA]],"") -> -4943.544 | O13: =IFERROR(E13-Tabela37[[#This Row],[TOP 1]],"") -> -6002.8749 | P13: =IFERROR(E13-Tabela37[[#This Row],[TOP 2]],"") -> -7062.2057 | Q13: =IFERROR(E13-Tabela37[[#This Row],[MASTER]],"") -> -8121.5366
B14: 10 | C14: =DATE($J$2,$J$1,B14) -> 46152 | D14: =UPPER(TEXT(C14,"dddd")) -> DOMINGO | F14: ="Semana " & INT((DAY(C14)+WEEKDAY(DATE(YEAR(C14),MONTH(C14),1),1)-2)/7)+1 -> Semana 3 | G14: ='METAS - SOBRAL'!I13 | H14: ='METAS - SOBRAL'!I37 | I14: ='METAS - SOBRAL'!I61 | J14: ='METAS - SOBRAL'!I85 | L14: =Tabela37[[#This Row],[DATA]] -> 46152 | M14: =Tabela37[[#This Row],[VALOR REALIZADO]] -> 0 | N14: =IFERROR(E14-Tabela37[[#This Row],[META MÍNIMA]],"") | O14: =IFERROR(E14-Tabela37[[#This Row],[TOP 1]],"") | P14: =IFERROR(E14-Tabela37[[#This Row],[TOP 2]],"") | Q14: =IFERROR(E14-Tabela37[[#This Row],[MASTER]],"")
B15: 11 | C15: =DATE($J$2,$J$1,B15) -> 46153 | D15: =UPPER(TEXT(C15,"dddd")) -> SEGUNDA-FEIRA | F15: ="Semana " & INT((DAY(C15)+WEEKDAY(DATE(YEAR(C15),MONTH(C15),1),1)-2)/7)+1 -> Semana 3 | G15: ='METAS - SOBRAL'!I14 -> 4767.5176 | H15: ='METAS - SOBRAL'!I38 -> 5789.1286 | I15: ='METAS - SOBRAL'!I62 -> 6810.7395 | J15: ='METAS - SOBRAL'!I86 -> 7832.3504 | L15: =Tabela37[[#This Row],[DATA]] -> 46153 | M15: =Tabela37[[#This Row],[VALOR REALIZADO]] -> 0 | N15: =IFERROR(E15-Tabela37[[#This Row],[META MÍNIMA]],"") -> -4767.5176 | O15: =IFERROR(E15-Tabela37[[#This Row],[TOP 1]],"") -> -5789.1286 | P15: =IFERROR(E15-Tabela37[[#This Row],[TOP 2]],"") -> -6810.7395 | Q15: =IFERROR(E15-Tabela37[[#This Row],[MASTER]],"") -> -7832.3504
B16: 12 | C16: =DATE($J$2,$J$1,B16) -> 46154 | D16: =UPPER(TEXT(C16,"dddd")) -> TERÇA-FEIRA | F16: ="Semana " & INT((DAY(C16)+WEEKDAY(DATE(YEAR(C16),MONTH(C16),1),1)-2)/7)+1 -> Semana 3 | G16: ='METAS - SOBRAL'!I15 -> 4768.9338 | H16: ='METAS - SOBRAL'!I39 -> 5790.8482 | I16: ='METAS - SOBRAL'!I63 -> 6812.7626 | J16: ='METAS - SOBRAL'!I87 -> 7834.677 | L16: =Tabela37[[#This Row],[DATA]] -> 46154 | M16: =Tabela37[[#This Row],[VALOR REALIZADO]] -> 0 | N16: =IFERROR(E16-Tabela37[[#This Row],[META MÍNIMA]],"") -> -4768.9338 | O16: =IFERROR(E16-Tabela37[[#This Row],[TOP 1]],"") -> -5790.8482 | P16: =IFERROR(E16-Tabela37[[#This Row],[TOP 2]],"") -> -6812.7626 | Q16: =IFERROR(E16-Tabela37[[#This Row],[MASTER]],"") -> -7834.677
B17: 13 | C17: =DATE($J$2,$J$1,B17) -> 46155 | D17: =UPPER(TEXT(C17,"dddd")) -> QUARTA-FEIRA | F17: ="Semana " & INT((DAY(C17)+WEEKDAY(DATE(YEAR(C17),MONTH(C17),1),1)-2)/7)+1 -> Semana 3 | G17: ='METAS - SOBRAL'!I16 -> 5654.3789 | H17: ='METAS - SOBRAL'!I40 -> 6866.0315 | I17: ='METAS - SOBRAL'!I64 -> 8077.6841 | J17: ='METAS - SOBRAL'!I88 -> 9289.3368 | L17: =Tabela37[[#This Row],[DATA]] -> 46155 | M17: =Tabela37[[#This Row],[VALOR REALIZADO]] -> 0 | N17: =IFERROR(E17-Tabela37[[#This Row],[META MÍNIMA]],"") -> -5654.3789 | O17: =IFERROR(E17-Tabela37[[#This Row],[TOP 1]],"") -> -6866.0315 | P17: =IFERROR(E17-Tabela37[[#This Row],[TOP 2]],"") -> -8077.6841 | Q17: =IFERROR(E17-Tabela37[[#This Row],[MASTER]],"") -> -9289.3368
B18: 14 | C18: =DATE($J$2,$J$1,B18) -> 46156 | D18: =UPPER(TEXT(C18,"dddd")) -> QUINTA-FEIRA | F18: ="Semana " & INT((DAY(C18)+WEEKDAY(DATE(YEAR(C18),MONTH(C18),1),1)-2)/7)+1 -> Semana 3 | G18: ='METAS - SOBRAL'!I17 -> 7079.689 | H18: ='METAS - SOBRAL'!I41 -> 8596.7652 | I18: ='METAS - SOBRAL'!I65 -> 10113.841 | J18: ='METAS - SOBRAL'!I89 -> 11630.918 | L18: =Tabela37[[#This Row],[DATA]] -> 46156 | M18: =Tabela37[[#This Row],[VALOR REALIZADO]] -> 0 | N18: =IFERROR(E18-Tabela37[[#This Row],[META MÍNIMA]],"") -> -7079.689 | O18: =IFERROR(E18-Tabela37[[#This Row],[TOP 1]],"") -> -8596.7652 | P18: =IFERROR(E18-Tabela37[[#This Row],[TOP 2]],"") -> -10113.841 | Q18: =IFERROR(E18-Tabela37[[#This Row],[MASTER]],"") -> -11630.918
B19: 15 | C19: =DATE($J$2,$J$1,B19) -> 46157 | D19: =UPPER(TEXT(C19,"dddd")) -> SEXTA-FEIRA | F19: ="Semana " & INT((DAY(C19)+WEEKDAY(DATE(YEAR(C19),MONTH(C19),1),1)-2)/7)+1 -> Semana 3 | G19: ='METAS - SOBRAL'!I18 -> 6550.0506 | H19: ='METAS - SOBRAL'!I42 -> 7953.6329 | I19: ='METAS - SOBRAL'!I66 -> 9357.2152 | J19: ='METAS - SOBRAL'!I90 -> 10760.797 | L19: =Tabela37[[#This Row],[DATA]] -> 46157 | M19: =Tabela37[[#This Row],[VALOR REALIZADO]] -> 0 | N19: =IFERROR(E19-Tabela37[[#This Row],[META MÍNIMA]],"") -> -6550.0506 | O19: =IFERROR(E19-Tabela37[[#This Row],[TOP 1]],"") -> -7953.6329 | P19: =IFERROR(E19-Tabela37[[#This Row],[TOP 2]],"") -> -9357.2152 | Q19: =IFERROR(E19-Tabela37[[#This Row],[MASTER]],"") -> -10760.797
B20: 16 | C20: =DATE($J$2,$J$1,B20) -> 46158 | D20: =UPPER(TEXT(C20,"dddd")) -> SÁBADO | F20: ="Semana " & INT((DAY(C20)+WEEKDAY(DATE(YEAR(C20),MONTH(C20),1),1)-2)/7)+1 -> Semana 3 | G20: ='METAS - SOBRAL'!I19 -> 4943.544 | H20: ='METAS - SOBRAL'!I43 -> 6002.8749 | I20: ='METAS - SOBRAL'!I67 -> 7062.2057 | J20: ='METAS - SOBRAL'!I91 -> 8121.5366 | L20: =Tabela37[[#This Row],[DATA]] -> 46158 | M20: =Tabela37[[#This Row],[VALOR REALIZADO]] -> 0 | N20: =IFERROR(E20-Tabela37[[#This Row],[META MÍNIMA]],"") -> -4943.544 | O20: =IFERROR(E20-Tabela37[[#This Row],[TOP 1]],"") -> -6002.8749 | P20: =IFERROR(E20-Tabela37[[#This Row],[TOP 2]],"") -> -7062.2057 | Q20: =IFERROR(E20-Tabela37[[#This Row],[MASTER]],"") -> -8121.5366
B21: 17 | C21: =DATE($J$2,$J$1,B21) -> 46159 | D21: =UPPER(TEXT(C21,"dddd")) -> DOMINGO | F21: ="Semana " & INT((DAY(C21)+WEEKDAY(DATE(YEAR(C21),MONTH(C21),1),1)-2)/7)+1 -> Semana 4 | G21: ='METAS - SOBRAL'!C24 -> 0 | H21: ='METAS - SOBRAL'!C48 | I21: ='METAS - SOBRAL'!C72 | J21: ='METAS - SOBRAL'!C96 | L21: =Tabela37[[#This Row],[DATA]] -> 46159 | M21: =Tabela37[[#This Row],[VALOR REALIZADO]] -> 0 | N21: =IFERROR(E21-Tabela37[[#This Row],[META MÍNIMA]],"") -> 0 | O21: =IFERROR(E21-Tabela37[[#This Row],[TOP 1]],"") | P21: =IFERROR(E21-Tabela37[[#This Row],[TOP 2]],"") | Q21: =IFERROR(E21-Tabela37[[#This Row],[MASTER]],"")
B22: 18 | C22: =DATE($J$2,$J$1,B22) -> 46160 | D22: =UPPER(TEXT(C22,"dddd")) -> SEGUNDA-FEIRA | F22: ="Semana " & INT((DAY(C22)+WEEKDAY(DATE(YEAR(C22),MONTH(C22),1),1)-2)/7)+1 -> Semana 4 | G22: ='METAS - SOBRAL'!C25 -> 4767.5176 | H22: ='METAS - SOBRAL'!C49 -> 5789.1286 | I22: ='METAS - SOBRAL'!C73 -> 6810.7395 | J22: ='METAS - SOBRAL'!C97 -> 7832.3504 | L22: =Tabela37[[#This Row],[DATA]] -> 46160 | M22: =Tabela37[[#This Row],[VALOR REALIZADO]] -> 0 | N22: =IFERROR(E22-Tabela37[[#This Row],[META MÍNIMA]],"") -> -4767.5176 | O22: =IFERROR(E22-Tabela37[[#This Row],[TOP 1]],"") -> -5789.1286 | P22: =IFERROR(E22-Tabela37[[#This Row],[TOP 2]],"") -> -6810.7395 | Q22: =IFERROR(E22-Tabela37[[#This Row],[MASTER]],"") -> -7832.3504
B23: 19 | C23: =DATE($J$2,$J$1,B23) -> 46161 | D23: =UPPER(TEXT(C23,"dddd")) -> TERÇA-FEIRA | F23: ="Semana " & INT((DAY(C23)+WEEKDAY(DATE(YEAR(C23),MONTH(C23),1),1)-2)/7)+1 -> Semana 4 | G23: ='METAS - SOBRAL'!C26 -> 4768.9338 | H23: ='METAS - SOBRAL'!C50 -> 5790.8482 | I23: ='METAS - SOBRAL'!C74 -> 6812.7626 | J23: ='METAS - SOBRAL'!C98 -> 7834.677 | L23: =Tabela37[[#This Row],[DATA]] -> 46161 | M23: =Tabela37[[#This Row],[VALOR REALIZADO]] -> 0 | N23: =IFERROR(E23-Tabela37[[#This Row],[META MÍNIMA]],"") -> -4768.9338 | O23: =IFERROR(E23-Tabela37[[#This Row],[TOP 1]],"") -> -5790.8482 | P23: =IFERROR(E23-Tabela37[[#This Row],[TOP 2]],"") -> -6812.7626 | Q23: =IFERROR(E23-Tabela37[[#This Row],[MASTER]],"") -> -7834.677
B24: 20 | C24: =DATE($J$2,$J$1,B24) -> 46162 | D24: =UPPER(TEXT(C24,"dddd")) -> QUARTA-FEIRA | F24: ="Semana " & INT((DAY(C24)+WEEKDAY(DATE(YEAR(C24),MONTH(C24),1),1)-2)/7)+1 -> Semana 4 | G24: ='METAS - SOBRAL'!C27 -> 5654.3789 | H24: ='METAS - SOBRAL'!C51 -> 6866.0315 | I24: ='METAS - SOBRAL'!C75 -> 8077.6841 | J24: ='METAS - SOBRAL'!C99 -> 9289.3368 | L24: =Tabela37[[#This Row],[DATA]] -> 46162 | M24: =Tabela37[[#This Row],[VALOR REALIZADO]] -> 0 | N24: =IFERROR(E24-Tabela37[[#This Row],[META MÍNIMA]],"") -> -5654.3789 | O24: =IFERROR(E24-Tabela37[[#This Row],[TOP 1]],"") -> -6866.0315 | P24: =IFERROR(E24-Tabela37[[#This Row],[TOP 2]],"") -> -8077.6841 | Q24: =IFERROR(E24-Tabela37[[#This Row],[MASTER]],"") -> -9289.3368
B25: 21 | C25: =DATE($J$2,$J$1,B25) -> 46163 | D25: =UPPER(TEXT(C25,"dddd")) -> QUINTA-FEIRA | F25: ="Semana " & INT((DAY(C25)+WEEKDAY(DATE(YEAR(C25),MONTH(C25),1),1)-2)/7)+1 -> Semana 4 | G25: ='METAS - SOBRAL'!C28 -> 7079.689 | H25: ='METAS - SOBRAL'!C52 -> 8596.7652 | I25: ='METAS - SOBRAL'!C76 -> 10113.841 | J25: ='METAS - SOBRAL'!C100 -> 11630.918 | L25: =Tabela37[[#This Row],[DATA]] -> 46163 | M25: =Tabela37[[#This Row],[VALOR REALIZADO]] -> 0 | N25: =IFERROR(E25-Tabela37[[#This Row],[META MÍNIMA]],"") -> -7079.689 | O25: =IFERROR(E25-Tabela37[[#This Row],[TOP 1]],"") -> -8596.7652 | P25: =IFERROR(E25-Tabela37[[#This Row],[TOP 2]],"") -> -10113.841 | Q25: =IFERROR(E25-Tabela37[[#This Row],[MASTER]],"") -> -11630.918
B26: 22 | C26: =DATE($J$2,$J$1,B26) -> 46164 | D26: =UPPER(TEXT(C26,"dddd")) -> SEXTA-FEIRA | F26: ="Semana " & INT((DAY(C26)+WEEKDAY(DATE(YEAR(C26),MONTH(C26),1),1)-2)/7)+1 -> Semana 4 | G26: ='METAS - SOBRAL'!C29 -> 6550.0506 | H26: ='METAS - SOBRAL'!C53 -> 7953.6329 | I26: ='METAS - SOBRAL'!C77 -> 9357.2152 | J26: ='METAS - SOBRAL'!C101 -> 10760.797 | L26: =Tabela37[[#This Row],[DATA]] -> 46164 | M26: =Tabela37[[#This Row],[VALOR REALIZADO]] -> 0 | N26: =IFERROR(E26-Tabela37[[#This Row],[META MÍNIMA]],"") -> -6550.0506 | O26: =IFERROR(E26-Tabela37[[#This Row],[TOP 1]],"") -> -7953.6329 | P26: =IFERROR(E26-Tabela37[[#This Row],[TOP 2]],"") -> -9357.2152 | Q26: =IFERROR(E26-Tabela37[[#This Row],[MASTER]],"") -> -10760.797
B27: 23 | C27: =DATE($J$2,$J$1,B27) -> 46165 | D27: =UPPER(TEXT(C27,"dddd")) -> SÁBADO | F27: ="Semana " & INT((DAY(C27)+WEEKDAY(DATE(YEAR(C27),MONTH(C27),1),1)-2)/7)+1 -> Semana 4 | G27: ='METAS - SOBRAL'!C30 -> 4943.544 | H27: ='METAS - SOBRAL'!C54 -> 6002.8749 | I27: ='METAS - SOBRAL'!C78 -> 7062.2057 | J27: ='METAS - SOBRAL'!C102 -> 8121.5366 | L27: =Tabela37[[#This Row],[DATA]] -> 46165 | M27: =Tabela37[[#This Row],[VALOR REALIZADO]] -> 0 | N27: =IFERROR(E27-Tabela37[[#This Row],[META MÍNIMA]],"") -> -4943.544 | O27: =IFERROR(E27-Tabela37[[#This Row],[TOP 1]],"") -> -6002.8749 | P27: =IFERROR(E27-Tabela37[[#This Row],[TOP 2]],"") -> -7062.2057 | Q27: =IFERROR(E27-Tabela37[[#This Row],[MASTER]],"") -> -8121.5366
B28: 24 | C28: =DATE($J$2,$J$1,B28) -> 46166 | D28: =UPPER(TEXT(C28,"dddd")) -> DOMINGO | F28: ="Semana " & INT((DAY(C28)+WEEKDAY(DATE(YEAR(C28),MONTH(C28),1),1)-2)/7)+1 -> Semana 5 | G28: ='METAS - SOBRAL'!F24 -> 0 | H28: ='METAS - SOBRAL'!F48 | I28: ='METAS - SOBRAL'!F72 | J28: ='METAS - SOBRAL'!F96 | L28: =Tabela37[[#This Row],[DATA]] -> 46166 | M28: =Tabela37[[#This Row],[VALOR REALIZADO]] -> 0 | N28: =IFERROR(E28-Tabela37[[#This Row],[META MÍNIMA]],"") -> 0 | O28: =IFERROR(E28-Tabela37[[#This Row],[TOP 1]],"") | P28: =IFERROR(E28-Tabela37[[#This Row],[TOP 2]],"") | Q28: =IFERROR(E28-Tabela37[[#This Row],[MASTER]],"")
B29: 25 | C29: =DATE($J$2,$J$1,B29) -> 46167 | D29: =UPPER(TEXT(C29,"dddd")) -> SEGUNDA-FEIRA | F29: ="Semana " & INT((DAY(C29)+WEEKDAY(DATE(YEAR(C29),MONTH(C29),1),1)-2)/7)+1 -> Semana 5 | G29: ='METAS - SOBRAL'!F25 -> 4767.5176 | H29: ='METAS - SOBRAL'!F49 -> 5789.1286 | I29: ='METAS - SOBRAL'!F73 -> 6810.7395 | J29: ='METAS - SOBRAL'!F97 -> 7832.3504 | L29: =Tabela37[[#This Row],[DATA]] -> 46167 | M29: =Tabela37[[#This Row],[VALOR REALIZADO]] -> 0 | N29: =IFERROR(E29-Tabela37[[#This Row],[META MÍNIMA]],"") -> -4767.5176 | O29: =IFERROR(E29-Tabela37[[#This Row],[TOP 1]],"") -> -5789.1286 | P29: =IFERROR(E29-Tabela37[[#This Row],[TOP 2]],"") -> -6810.7395 | Q29: =IFERROR(E29-Tabela37[[#This Row],[MASTER]],"") -> -7832.3504
B30: 26 | C30: =DATE($J$2,$J$1,B30) -> 46168 | D30: =UPPER(TEXT(C30,"dddd")) -> TERÇA-FEIRA | F30: ="Semana " & INT((DAY(C30)+WEEKDAY(DATE(YEAR(C30),MONTH(C30),1),1)-2)/7)+1 -> Semana 5 | G30: ='METAS - SOBRAL'!F26 -> 4768.9338 | H30: ='METAS - SOBRAL'!F50 -> 5790.8482 | I30: ='METAS - SOBRAL'!F74 -> 6812.7626 | J30: ='METAS - SOBRAL'!F98 -> 7834.677 | L30: =Tabela37[[#This Row],[DATA]] -> 46168 | M30: =Tabela37[[#This Row],[VALOR REALIZADO]] -> 0 | N30: =IFERROR(E30-Tabela37[[#This Row],[META MÍNIMA]],"") -> -4768.9338 | O30: =IFERROR(E30-Tabela37[[#This Row],[TOP 1]],"") -> -5790.8482 | P30: =IFERROR(E30-Tabela37[[#This Row],[TOP 2]],"") -> -6812.7626 | Q30: =IFERROR(E30-Tabela37[[#This Row],[MASTER]],"") -> -7834.677
B31: 27 | C31: =DATE($J$2,$J$1,B31) -> 46169 | D31: =UPPER(TEXT(C31,"dddd")) -> QUARTA-FEIRA | F31: ="Semana " & INT((DAY(C31)+WEEKDAY(DATE(YEAR(C31),MONTH(C31),1),1)-2)/7)+1 -> Semana 5 | G31: ='METAS - SOBRAL'!F27 -> 5654.3789 | H31: ='METAS - SOBRAL'!F51 -> 6866.0315 | I31: ='METAS - SOBRAL'!F75 -> 8077.6841 | J31: ='METAS - SOBRAL'!F99 -> 9289.3368 | L31: =Tabela37[[#This Row],[DATA]] -> 46169 | M31: =Tabela37[[#This Row],[VALOR REALIZADO]] -> 0 | N31: =IFERROR(E31-Tabela37[[#This Row],[META MÍNIMA]],"") -> -5654.3789 | O31: =IFERROR(E31-Tabela37[[#This Row],[TOP 1]],"") -> -6866.0315 | P31: =IFERROR(E31-Tabela37[[#This Row],[TOP 2]],"") -> -8077.6841 | Q31: =IFERROR(E31-Tabela37[[#This Row],[MASTER]],"") -> -9289.3368
B32: 28 | C32: =DATE($J$2,$J$1,B32) -> 46170 | D32: =UPPER(TEXT(C32,"dddd")) -> QUINTA-FEIRA | F32: ="Semana " & INT((DAY(C32)+WEEKDAY(DATE(YEAR(C32),MONTH(C32),1),1)-2)/7)+1 -> Semana 5 | G32: ='METAS - SOBRAL'!F28 -> 7079.689 | H32: ='METAS - SOBRAL'!F52 -> 8596.7652 | I32: ='METAS - SOBRAL'!F76 -> 10113.841 | J32: ='METAS - SOBRAL'!F100 -> 11630.918 | L32: =Tabela37[[#This Row],[DATA]] -> 46170 | M32: =Tabela37[[#This Row],[VALOR REALIZADO]] -> 0 | N32: =IFERROR(E32-Tabela37[[#This Row],[META MÍNIMA]],"") -> -7079.689 | O32: =IFERROR(E32-Tabela37[[#This Row],[TOP 1]],"") -> -8596.7652 | P32: =IFERROR(E32-Tabela37[[#This Row],[TOP 2]],"") -> -10113.841 | Q32: =IFERROR(E32-Tabela37[[#This Row],[MASTER]],"") -> -11630.918
B33: 29 | C33: =DATE($J$2,$J$1,B33) -> 46171 | D33: =UPPER(TEXT(C33,"dddd")) -> SEXTA-FEIRA | F33: ="Semana " & INT((DAY(C33)+WEEKDAY(DATE(YEAR(C33),MONTH(C33),1),1)-2)/7)+1 -> Semana 5 | G33: ='METAS - SOBRAL'!F29 -> 6550.0506 | H33: ='METAS - SOBRAL'!F53 -> 7953.6329 | I33: ='METAS - SOBRAL'!F77 -> 9357.2152 | J33: ='METAS - SOBRAL'!F101 -> 10760.797 | L33: =Tabela37[[#This Row],[DATA]] -> 46171 | M33: =Tabela37[[#This Row],[VALOR REALIZADO]] -> 0 | N33: =IFERROR(E33-Tabela37[[#This Row],[META MÍNIMA]],"") -> -6550.0506 | O33: =IFERROR(E33-Tabela37[[#This Row],[TOP 1]],"") -> -7953.6329 | P33: =IFERROR(E33-Tabela37[[#This Row],[TOP 2]],"") -> -9357.2152 | Q33: =IFERROR(E33-Tabela37[[#This Row],[MASTER]],"") -> -10760.797
B34: 30 | C34: =DATE($J$2,$J$1,B34) -> 46172 | D34: =UPPER(TEXT(C34,"dddd")) -> SÁBADO | F34: ="Semana " & INT((DAY(C34)+WEEKDAY(DATE(YEAR(C34),MONTH(C34),1),1)-2)/7)+1 -> Semana 5 | G34: ='METAS - SOBRAL'!F30 -> 4943.544 | H34: ='METAS - SOBRAL'!F54 -> 6002.8749 | I34: ='METAS - SOBRAL'!F78 -> 7062.2057 | J34: ='METAS - SOBRAL'!F102 -> 8121.5366 | L34: =Tabela37[[#This Row],[DATA]] -> 46172 | M34: =Tabela37[[#This Row],[VALOR REALIZADO]] -> 0 | N34: =IFERROR(E34-Tabela37[[#This Row],[META MÍNIMA]],"") -> -4943.544 | O34: =IFERROR(E34-Tabela37[[#This Row],[TOP 1]],"") -> -6002.8749 | P34: =IFERROR(E34-Tabela37[[#This Row],[TOP 2]],"") -> -7062.2057 | Q34: =IFERROR(E34-Tabela37[[#This Row],[MASTER]],"") -> -8121.5366
B35: 31 | C35: =DATE($J$2,$J$1,B35) -> 46173 | D35: =UPPER(TEXT(C35,"dddd")) -> DOMINGO | F35: ="Semana " & INT((DAY(C35)+WEEKDAY(DATE(YEAR(C35),MONTH(C35),1),1)-2)/7)+1 -> Semana 6 | L35: =Tabela37[[#This Row],[DATA]] -> 46173 | M35: =Tabela37[[#This Row],[VALOR REALIZADO]] -> 0 | N35: =IFERROR(E35-Tabela37[[#This Row],[META MÍNIMA]],"") -> 0 | O35: =IFERROR(E35-Tabela37[[#This Row],[TOP 1]],"") -> 0 | P35: =IFERROR(E35-Tabela37[[#This Row],[TOP 2]],"") -> 0 | Q35: =IFERROR(E35-Tabela37[[#This Row],[MASTER]],"") -> 0
C36: Total | E36: =SUBTOTAL(109,Tabela37[VALOR REALIZADO]) -> 0 | G36: =SUBTOTAL(109,Tabela37[META MÍNIMA]) -> 140000 | H36: =SUBTOTAL(109,Tabela37[TOP 1]) -> 170000 | I36: =SUBTOTAL(109,Tabela37[TOP 2]) -> 200000 | J36: =SUBTOTAL(109,Tabela37[MASTER]) -> 230000
F37: Concluído | G37: =Tabela37[[#Totals],[VALOR REALIZADO]]/Tabela37[[#Totals],[META MÍNIMA]] -> 0 | H37: =Tabela37[[#Totals],[VALOR REALIZADO]]/Tabela37[[#Totals],[TOP 1]] -> 0 | I37: =Tabela37[[#Totals],[VALOR REALIZADO]]/Tabela37[[#Totals],[TOP 2]] -> 0 | J37: =Tabela37[[#Totals],[VALOR REALIZADO]]/Tabela37[[#Totals],[MASTER]] -> 0

Sheet Detalhes2
A1: Detalhes do Valor Total
A3: DATA | B3: DIA DA SEMANA | C3: VALOR
A4: 45809 | B4: DOMINGO | C4: 0
A5: 45816 | B5: DOMINGO | C5: 0
A6: 45823 | B6: DOMINGO | C6: 0
A7: 45830 | B7: DOMINGO | C7: 0
A8: 45837 | B8: DOMINGO | C8: 0
A9: 45810 | B9: SEGUNDA-FEIRA | C9: 3898
A10: 45817 | B10: SEGUNDA-FEIRA | C10: 5775
A11: 45824 | B11: SEGUNDA-FEIRA | C11: 5795.6
A12: 45831 | B12: SEGUNDA-FEIRA | C12: 6519.07
A13: 45838 | B13: SEGUNDA-FEIRA | C13: 669
A14: 45811 | B14: TERÇA-FEIRA | C14: 3090
A15: 45818 | B15: TERÇA-FEIRA | C15: 10648
... A33: 45836 | B33: SÁBADO | C33: 6585.3

Sheet SOBRAL
B1: DATA | C1: DIA DA SEMANA | D1: VALOR | F1: ANO | G1: 2026 | J1: MÍNIMA | M1: MÍNIMA | W1: TOP 1 | AG1: TOP 2 | AQ1: MASTER
B2: 46054 | C2: =UPPER(TEXT(B2,"dddd")) -> DOMINGO | D2: 0 | F2: DIA DA SEMANA | G2: Valor Total | H2: % | J2: FATURAMENTO | K2: 140000 | M2: MÊS | N2: ANO | O2: META MENSAL | P2: DIA DA SEMANA | Q2: PERCENTUAL DE REPRESENTATIVIDADE | R2: QUANTIDADE | W2: MÊS | X2: ANO | Y2: META MENSAL | Z2: DIA DA SEMANA | AA2: PERCENTUAL DE REPRESENTATIVIDADE | AB2: QUANTIDADE | AG2: MÊS | AH2: ANO | AI2: META MENSAL | AJ2: DIA DA SEMANA | AK2: PERCENTUAL DE REPRESENTATIVIDADE | AL2: QUANTIDADE | AQ2: MÊS | AR2: ANO | AS2: META MENSAL | AT2: DIA DA SEMANA | AU2: PERCENTUAL DE REPRESENTATIVIDADE | AV2: QUANTIDADE
B3: 46055 | C3: =UPPER(TEXT(B3,"dddd")) -> SEGUNDA-FEIRA | D3: 3898 | F3: DOMINGO | G3: 0 | H3: 0 | J3: DIAS ÚTEIS | K3: 25 | M3: 5 | N3: =$G$1 -> 2026 | O3: =$K$2 -> 140000 | P3: DOMINGO | Q3: =$H$3 -> 0 | R3: 5 | W3: =Tabela6[[#This Row],[MÊS]] -> 5 | X3: =Tabela6[[#This Row],[ANO]] -> 2026 | Y3: =$K$7 -> 170000 | Z3: DOMINGO | AA3: =$H$3 -> 0 | AB3: =Tabela6[[#This Row],[QUANTIDADE]] -> 5 | AG3: =Tabela69[[#This Row],[MÊS]] -> 5 | AH3: =Tabela6[[#This Row],[ANO]] -> 2026 | AI3: =$K$13 -> 200000 | AJ3: DOMINGO | AK3: =$H$3 -> 0 | AL3: 4 | AQ3: =Tabela6911[[#This Row],[MÊS]] -> 5 | AR3: =Tabela6911[[#This Row],[ANO]] -> 2026 | AS3: =$K$19 -> 230000 | AT3: DOMINGO | AU3: =$H$3 -> 0 | AV3: =Tabela6911[[#This Row],[QUANTIDADE]] -> 4
B4: 46056 | C4: =UPPER(TEXT(B4,"dddd")) -> TERÇA-FEIRA | D4: =265+387+1082+1356 -> 3090 | F4: SEGUNDA-FEIRA | G4: 22656.67 | H4: 0.13621479 | J4: MÉDIA/ DIA | K4: =K2/K3 -> 5600 | M4: 5 | N4: =$G$1 -> 2026 | O4: =$K$2 -> 140000 | P4: SEGUNDA-FEIRA | Q4: =$H$4 -> 0.13621479 | R4: 4 | W4: =Tabela6[[#This Row],[MÊS]] -> 5 | X4: =Tabela6[[#This Row],[ANO]] -> 2026 | Y4: =$K$7 -> 170000 | Z4: SEGUNDA-FEIRA | AA4: =$H$4 -> 0.13621479 | AB4: =Tabela6[[#This Row],[QUANTIDADE]] -> 4 | AG4: =Tabela69[[#This Row],[MÊS]] -> 5 | AH4: =Tabela6[[#This Row],[ANO]] -> 2026 | AI4: =$K$13 -> 200000 | AJ4: SEGUNDA-FEIRA | AK4: =$H$4 -> 0.13621479 | AL4: =Tabela69[[#This Row],[QUANTIDADE]] -> 4 | AQ4: =Tabela6911[[#This Row],[MÊS]] -> 5 | AR4: =Tabela6911[[#This Row],[ANO]] -> 2026 | AS4: =$K$19 -> 230000 | AT4: SEGUNDA-FEIRA | AU4: =$H$4 -> 0.13621479 | AV4: =Tabela6911[[#This Row],[QUANTIDADE]] -> 4
B5: 46057 | C5: =UPPER(TEXT(B5,"dddd")) -> QUARTA-FEIRA | D5: =40+2384+0+1395 -> 3819 | F5: TERÇA-FEIRA | G5: 22663.4 | H5: 0.13625525 | M5: 5 | N5: =$G$1 -> 2026 | O5: =$K$2 -> 140000 | P5: TERÇA-FEIRA | Q5: =$H$5 -> 0.13625525 | R5: 4 | W5: =Tabela6[[#This Row],[MÊS]] -> 5 | X5: =Tabela6[[#This Row],[ANO]] -> 2026 | Y5: =$K$7 -> 170000 | Z5: TERÇA-FEIRA | AA5: =$H$5 -> 0.13625525 | AB5: =Tabela6[[#This Row],[QUANTIDADE]] -> 4 | AG5: =Tabela69[[#This Row],[MÊS]] -> 5 | AH5: =Tabela6[[#This Row],[ANO]] -> 2026 | AI5: =$K$13 -> 200000 | AJ5: TERÇA-FEIRA | AK5: =$H$5 -> 0.13625525 | AL5: =Tabela69[[#This Row],[QUANTIDADE]] -> 4 | AQ5: =Tabela6911[[#This Row],[MÊS]] -> 5 | AR5: =Tabela6911[[#This Row],[ANO]] -> 2026 | AS5: =$K$19 -> 230000 | AT5: TERÇA-FEIRA | AU5: =$H$5 -> 0.13625525 | AV5: =Tabela6911[[#This Row],[QUANTIDADE]] -> 4
B6: 46058 | C6: =UPPER(TEXT(B6,"dddd")) -> QUINTA-FEIRA | D6: =1010+4829+3394.9 -> 9233.9 | F6: QUARTA-FEIRA | G6: 26871.3 | H6: 0.16155368 | J6: TOP1 | M6: 5 | N6: =$G$1 -> 2026 | O6: =$K$2 -> 140000 | P6: QUARTA-FEIRA | Q6: =$H$6 -> 0.16155368 | R6: 4 | W6: =Tabela6[[#This Row],[MÊS]] -> 5 | X6: =Tabela6[[#This Row],[ANO]] -> 2026 | Y6: =$K$7 -> 170000 | Z6: QUARTA-FEIRA | AA6: =$H$6 -> 0.16155368 | AB6: =Tabela6[[#This Row],[QUANTIDADE]] -> 4 | AG6: =Tabela69[[#This Row],[MÊS]] -> 5 | AH6: =Tabela6[[#This Row],[ANO]] -> 2026 | AI6: =$K$13 -> 200000 | AJ6: QUARTA-FEIRA | AK6: =$H$6 -> 0.16155368 | AL6: =Tabela69[[#This Row],[QUANTIDADE]] -> 4 | AQ6: =Tabela6911[[#This Row],[MÊS]] -> 5 | AR6: =Tabela6911[[#This Row],[ANO]] -> 2026 | AS6: =$K$19 -> 230000 | AT6: QUARTA-FEIRA | AU6: =$H$6 -> 0.16155368 | AV6: =Tabela6911[[#This Row],[QUANTIDADE]] -> 4
B7: 46059 | C7: =UPPER(TEXT(B7,"dddd")) -> SEXTA-FEIRA | D7: =506+4209.7-1+4858.6 -> 9573.3 | F7: QUINTA-FEIRA | G7: 33644.8 | H7: 0.20227683 | J7: FATURAMENTO | K7: 170000 | M7: 5 | N7: =$G$1 -> 2026 | O7: =$K$2 -> 140000 | P7: QUINTA-FEIRA | Q7: =$H$7 -> 0.20227683 | R7: 4 | W7: =Tabela6[[#This Row],[MÊS]] -> 5 | X7: =Tabela6[[#This Row],[ANO]] -> 2026 | Y7: =$K$7 -> 170000 | Z7: QUINTA-FEIRA | AA7: =$H$7 -> 0.20227683 | AB7: =Tabela6[[#This Row],[QUANTIDADE]] -> 4 | AG7: =Tabela69[[#This Row],[MÊS]] -> 5 | AH7: =Tabela6[[#This Row],[ANO]] -> 2026 | AI7: =$K$13 -> 200000 | AJ7: QUINTA-FEIRA | AK7: =$H$7 -> 0.20227683 | AL7: =Tabela69[[#This Row],[QUANTIDADE]] -> 4 | AQ7: =Tabela6911[[#This Row],[MÊS]] -> 5 | AR7: =Tabela6911[[#This Row],[ANO]] -> 2026 | AS7: =$K$19 -> 230000 | AT7: QUINTA-FEIRA | AU7: =$H$7 -> 0.20227683 | AV7: =Tabela6911[[#This Row],[QUANTIDADE]] -> 4
B8: 46060 | C8: =UPPER(TEXT(B8,"dddd")) -> SÁBADO | D8: =249+5161+2114 -> 7524 | F8: SEXTA-FEIRA | G8: 31127.8 | H8: 0.1871443 | J8: DIAS ÚTEIS | K8: =K3 -> 25 | M8: 5 | N8: =$G$1 -> 2026 | O8: =$K$2 -> 140000 | P8: SEXTA-FEIRA | Q8: =$H$8 -> 0.1871443 | R8: 4 | W8: =Tabela6[[#This Row],[MÊS]] -> 5 | X8: =Tabela6[[#This Row],[ANO]] -> 2026 | Y8: =$K$7 -> 170000 | Z8: SEXTA-FEIRA | AA8: =$H$8 -> 0.1871443 | AB8: =Tabela6[[#This Row],[QUANTIDADE]] -> 4 | AG8: =Tabela69[[#This Row],[MÊS]] -> 5 | AH8: =Tabela6[[#This Row],[ANO]] -> 2026 | AI8: =$K$13 -> 200000 | AJ8: SEXTA-FEIRA | AK8: =$H$8 -> 0.1871443 | AL8: =Tabela69[[#This Row],[QUANTIDADE]] -> 4 | AQ8: =Tabela6911[[#This Row],[MÊS]] -> 5 | AR8: =Tabela6911[[#This Row],[ANO]] -> 2026 | AS8: =$K$19 -> 230000 | AT8: SEXTA-FEIRA | AU8: =$H$8 -> 0.1871443 | AV8: =Tabela6911[[#This Row],[QUANTIDADE]] -> 4
B9: 46061 | C9: =UPPER(TEXT(B9,"dddd")) -> DOMINGO | D9: 0 | F9: SÁBADO | G9: 29366.5 | H9: 0.17655514 | J9: MÉDIA/ DIA | K9: =K7/K8 -> 6800 | M9: 5 | N9: =$G$1 -> 2026 | O9: =$K$2 -> 140000 | P9: SÁBADO | Q9: =H9 -> 0.17655514 | R9: 5 | W9: =Tabela6[[#This Row],[MÊS]] -> 5 | X9: =Tabela6[[#This Row],[ANO]] -> 2026 | Y9: =$K$7 -> 170000 | Z9: SÁBADO | AA9: =$H$9 -> 0.17655514 | AB9: =Tabela6[[#This Row],[QUANTIDADE]] -> 5 | AG9: =Tabela69[[#This Row],[MÊS]] -> 5 | AH9: =Tabela6[[#This Row],[ANO]] -> 2026 | AI9: =$K$13 -> 200000 | AJ9: SÁBADO | AK9: =$H$9 -> 0.17655514 | AL9: =Tabela69[[#This Row],[QUANTIDADE]] -> 5 | AQ9: =Tabela6911[[#This Row],[MÊS]] -> 5 | AR9: =Tabela6911[[#This Row],[ANO]] -> 2026 | AS9: =$K$19 -> 230000 | AT9: SÁBADO | AU9: =$H$9 -> 0.17655514 | AV9: =Tabela6911[[#This Row],[QUANTIDADE]] -> 5
B10: 46062 | C10: =UPPER(TEXT(B10,"dddd")) -> SEGUNDA-FEIRA | D10: =303+3742+0+1730 -> 5775 | F10: Total Geral | G10: 166330.47 | H10: 1 | M10: 5 | N10: =$G$1 -> 2026 | O10: =$K$2 -> 140000 | Q10: =H10 -> 1 | W10: Total | AA10: =SUBTOTAL(109,Tabela69[PERCENTUAL DE REPRESENTATIVIDADE]) -> 1 | AB10: =SUBTOTAL(109,Tabela69[QUANTIDADE]) -> 30 | AG10: Total | AK10: =SUBTOTAL(109,Tabela6911[PERCENTUAL DE REPRESENTATIVIDADE]) -> 1 | AL10: =SUBTOTAL(109,Tabela6911[QUANTIDADE]) -> 29 | AQ10: Total | AU10: =SUBTOTAL(109,Tabela691113[PERCENTUAL DE REPRESENTATIVIDADE]) -> 1 | AV10: =SUBTOTAL(109,Tabela691113[QUANTIDADE]) -> 29
B11: 46063 | C11: =UPPER(TEXT(B11,"dddd")) -> TERÇA-FEIRA | D11: =1451+5070+4127 -> 10648 | M11: Total | Q11: =SUBTOTAL(109,Tabela6[PERCENTUAL DE REPRESENTATIVIDADE]) -> 2 | R11: =SUBTOTAL(109,Tabela6[QUANTIDADE]) -> 30
B12: 46064 | C12: =UPPER(TEXT(B12,"dddd")) -> QUARTA-FEIRA | D12: =137+5003+5046 -> 10186 | J12: TOP 2
B13: 46065 | C13: =UPPER(TEXT(B13,"dddd")) -> QUINTA-FEIRA | D13: =1154+4083+6627 -> 11864 | J13: FATURAMENTO | K13: 200000 | M13: MÊS | N13: ANO | O13: META MENSAL | P13: DIA DA SEMANA | Q13: VALOR DO DIA DA SEMANA | R13: QUANTIDADE | W13: MÊS | X13: ANO | Y13: META MENSAL | Z13: DIA DA SEMANA | AA13: VALOR DO DIA DA SEMANA | AB13: QUANTIDADE | AG13: MÊS | AH13: ANO | AI13: META MENSAL | AJ13: DIA DA SEMANA | AK13: VALOR DO DIA DA SEMANA | AL13: QUANTIDADE | AQ13: MÊS | AR13: ANO | AS13: META MENSAL | AT13: DIA DA SEMANA | AU13: VALOR DO DIA DA SEMANA | AV13: QUANTIDADE
B14: 46066 | C14: =UPPER(TEXT(B14,"dddd")) -> SEXTA-FEIRA | D14: =906+3292+5104 -> 9302 | J14: DIAS ÚTEIS | K14: =K8 -> 25 | M14: =M3 -> 5 | N14: =N3 -> 2026 | O14: =O3 -> 140000 | P14: DOMINGO | Q14: =(O3*Q3)/Tabela68[[#This Row],[QUANTIDADE]] -> 0 | R14: =R3 -> 5 | W14: =W3 -> 5 | X14: =X3 -> 2026 | Y14: =Y3 -> 170000 | Z14: DOMINGO | AA14: =(Y3*AA3)/Tabela6810[[#This Row],[QUANTIDADE]] -> 0 | AB14: =AB3 -> 5 | AG14: =AG3 -> 5 | AH14: =AH3 -> 2026 | AI14: =AI3 -> 200000 | AJ14: DOMINGO | AK14: =(AI3*AK3)/Tabela681012[[#This Row],[QUANTIDADE]] -> 0 | AL14: =AL3 -> 4 | AQ14: =AQ3 -> 5 | AR14: =AR3 -> 2026 | AS14: =AS3 -> 230000 | AT14: DOMINGO | AU14: =(AS3*AU3)/Tabela68101214[[#This Row],[QUANTIDADE]] -> 0 | AV14: =AV3 -> 4
B15: 46067 | C15: =UPPER(TEXT(B15,"dddd")) -> SÁBADO | D15: =22+6365-10+1836 -> 8213 | J15: MÉDIA/ DIA | K15: =K13/K14 -> 8000 | M15: =M4 -> 5 | N15: =N4 -> 2026 | O15: =O4 -> 140000 | P15: SEGUNDA-FEIRA | Q15: =(O4*Q4)/Tabela68[[#This Row],[QUANTIDADE]] -> 4767.5176 | R15: =R4 -> 4 | W15: =W4 -> 5 | X15: =X4 -> 2026 | Y15: =Y4 -> 170000 | Z15: SEGUNDA-FEIRA | AA15: =(Y4*AA4)/Tabela6810[[#This Row],[QUANTIDADE]] -> 5789.1286 | AB15: =AB4 -> 4 | AG15: =AG4 -> 5 | AH15: =AH4 -> 2026 | AI15: =AI4 -> 200000 | AJ15: SEGUNDA-FEIRA | AK15: =(AI4*AK4)/Tabela681012[[#This Row],[QUANTIDADE]] -> 6810.7395 | AL15: =AL4 -> 4 | AQ15: =AQ4 -> 5 | AR15: =AR4 -> 2026 | AS15: =AS4 -> 230000 | AT15: SEGUNDA-FEIRA | AU15: =(AS4*AU4)/Tabela68101214[[#This Row],[QUANTIDADE]] -> 7832.3504 | AV15: =AV4 -> 4
B16: 46068 | C16: =UPPER(TEXT(B16,"dddd")) -> DOMINGO | D16: 0 | M16: =M5 -> 5 | N16: =N5 -> 2026 | O16: =O5 -> 140000 | P16: TERÇA-FEIRA | Q16: =(O5*Q5)/Tabela68[[#This Row],[QUANTIDADE]] -> 4768.9338 | R16: =R5 -> 4 | W16: =W5 -> 5 | X16: =X5 -> 2026 | Y16: =Y5 -> 170000 | Z16: TERÇA-FEIRA | AA16: =(Y5*AA5)/Tabela6810[[#This Row],[QUANTIDADE]] -> 5790.8482 | AB16: =AB5 -> 4 | AG16: =AG5 -> 5 | AH16: =AH5 -> 2026 | AI16: =AI5 -> 200000 | AJ16: TERÇA-FEIRA | AK16: =(AI5*AK5)/Tabela681012[[#This Row],[QUANTIDADE]] -> 6812.7626 | AL16: =AL5 -> 4 | AQ16: =AQ5 -> 5 | AR16: =AR5 -> 2026 | AS16: =AS5 -> 230000 | AT16: TERÇA-FEIRA | AU16: =(AS5*AU5)/Tabela68101214[[#This Row],[QUANTIDADE]] -> 7834.677 | AV16: =AV5 -> 4
B17: 46069 | C17: =UPPER(TEXT(B17,"dddd")) -> SEGUNDA-FEIRA | D17: =1188+2793+1814.6 -> 5795.6 | M17: =M6 -> 5 | N17: =N6 -> 2026 | O17: =O6 -> 140000 | P17: QUARTA-FEIRA | Q17: =(O6*Q6)/Tabela68[[#This Row],[QUANTIDADE]] -> 5654.3789 | R17: =R6 -> 4 | W17: =W6 -> 5 | X17: =X6 -> 2026 | Y17: =Y6 -> 170000 | Z17: QUARTA-FEIRA | AA17: =(Y6*AA6)/Tabela6810[[#This Row],[QUANTIDADE]] -> 6866.0315 | AB17: =AB6 -> 4 | AG17: =AG6 -> 5 | AH17: =AH6 -> 2026 | AI17: =AI6 -> 200000 | AJ17: QUARTA-FEIRA | AK17: =(AI6*AK6)/Tabela681012[[#This Row],[QUANTIDADE]] -> 8077.6841 | AL17: =AL6 -> 4 | AQ17: =AQ6 -> 5 | AR17: =AR6 -> 2026 | AS17: =AS6 -> 230000 | AT17: QUARTA-FEIRA | AU17: =(AS6*AU6)/Tabela68101214[[#This Row],[QUANTIDADE]] -> 9289.3368 | AV17: =AV6 -> 4
B18: 46070 | C18: =UPPER(TEXT(B18,"dddd")) -> TERÇA-FEIRA | D18: =1355+1508.7+0+420 -> 3283.7 | J18: MASTER | M18: =M7 -> 5 | N18: =N7 -> 2026 | O18: =O7 -> 140000 | P18: QUINTA-FEIRA | Q18: =(O7*Q7)/Tabela68[[#This Row],[QUANTIDADE]] -> 7079.689 | R18: =R7 -> 4 | W18: =W7 -> 5 | X18: =X7 -> 2026 | Y18: =Y7 -> 170000 | Z18: QUINTA-FEIRA | AA18: =(Y7*AA7)/Tabela6810[[#This Row],[QUANTIDADE]] -> 8596.7652 | AB18: =AB7 -> 4 | AG18: =AG7 -> 5 | AH18: =AH7 -> 2026 | AI18: =AI7 -> 200000 | AJ18: QUINTA-FEIRA | AK18: =(AI7*AK7)/Tabela681012[[#This Row],[QUANTIDADE]] -> 10113.841 | AL18: =AL7 -> 4 | AQ18: =AQ7 -> 5 | AR18: =AR7 -> 2026 | AS18: =AS7 -> 230000 | AT18: QUINTA-FEIRA | AU18: =(AS7*AU7)/Tabela68101214[[#This Row],[QUANTIDADE]] -> 11630.918 | AV18: =AV7 -> 4
B19: 46071 | C19: =UPPER(TEXT(B19,"dddd")) -> QUARTA-FEIRA | D19: =1332.2+3138+3051.5 -> 7521.7 | J19: FATURAMENTO | K19: 230000 | M19: =M8 -> 5 | N19: =N8 -> 2026 | O19: =O8 -> 140000 | P19: SEXTA-FEIRA | Q19: =(O8*Q8)/Tabela68[[#This Row],[QUANTIDADE]] -> 6550.0506 | R19: =R8 -> 4 | W19: =W8 -> 5 | X19: =X8 -> 2026 | Y19: =Y8 -> 170000 | Z19: SEXTA-FEIRA | AA19: =(Y8*AA8)/Tabela6810[[#This Row],[QUANTIDADE]] -> 7953.6329 | AB19: =AB8 -> 4 | AG19: =AG8 -> 5 | AH19: =AH8 -> 2026 | AI19: =AI8 -> 200000 | AJ19: SEXTA-FEIRA | AK19: =(AI8*AK8)/Tabela681012[[#This Row],[QUANTIDADE]] -> 9357.2152 | AL19: =AL8 -> 4 | AQ19: =AQ8 -> 5 | AR19: =AR8 -> 2026 | AS19: =AS8 -> 230000 | AT19: SEXTA-FEIRA | AU19: =(AS8*AU8)/Tabela68101214[[#This Row],[QUANTIDADE]] -> 10760.797 | AV19: =AV8 -> 4
B20: 46072 | C20: =UPPER(TEXT(B20,"dddd")) -> QUINTA-FEIRA | D20: =1319+1872+535 -> 3726 | J20: DIAS ÚTEIS | K20: =K14 -> 25 | M20: =M9 -> 5 | N20: =N9 -> 2026 | O20: =O9 -> 140000 | P20: SÁBADO | Q20: =(O9*Q9)/Tabela68[[#This Row],[QUANTIDADE]] -> 4943.544 | R20: =R9 -> 5 | W20: =W9 -> 5 | X20: =X9 -> 2026 | Y20: =Y9 -> 170000 | Z20: SÁBADO | AA20: =(Y9*AA9)/Tabela6810[[#This Row],[QUANTIDADE]] -> 6002.8749 | AB20: =AB9 -> 5 | AG20: =AG9 -> 5 | AH20: =AH9 -> 2026 | AI20: =AI9 -> 200000 | AJ20: SÁBADO | AK20: =(AI9*AK9)/Tabela681012[[#This Row],[QUANTIDADE]] -> 7062.2057 | AL20: =AL9 -> 5 | AQ20: =AQ9 -> 5 | AR20: =AR9 -> 2026 | AS20: =AS9 -> 230000 | AT20: SÁBADO | AU20: =(AS9*AU9)/Tabela68101214[[#This Row],[QUANTIDADE]] -> 8121.5366 | AV20: =AV9 -> 5
B21: 46073 | C21: =UPPER(TEXT(B21,"dddd")) -> SEXTA-FEIRA | D21: =329+3856+2484 -> 6669 | J21: MÉDIA/ DIA | K21: =K19/K20 -> 9200
B22: 46074 | C22: =UPPER(TEXT(B22,"dddd")) -> SÁBADO | D22: =663+4025+0+2356.2 -> 7044.2
B23: 46075 | C23: =UPPER(TEXT(B23,"dddd")) -> DOMINGO | D23: 0
B24: 46076 | C24: =UPPER(TEXT(B24,"dddd")) -> SEGUNDA-FEIRA | D24: =3967+2552.07 -> 6519.07
B25: 46077 | C25: =UPPER(TEXT(B25,"dddd")) -> TERÇA-FEIRA | D25: =228+3599+1814.7 -> 5641.7
B26: 46078 | C26: =UPPER(TEXT(B26,"dddd")) -> QUARTA-FEIRA | D26: =3209+2135.6 -> 5344.6
B27: 46079 | C27: =UPPER(TEXT(B27,"dddd")) -> QUINTA-FEIRA | D27: =602+4957+0+3261.9 -> 8820.9
B28: 46080 | C28: =UPPER(TEXT(B28,"dddd")) -> SEXTA-FEIRA | D28: =306.5+3874+1403 -> 5583.5
B29: 46081 | C29: =UPPER(TEXT(B29,"dddd")) -> SÁBADO | D29: =527+4230+0+1828.3 -> 6585.3
C30: =UPPER(TEXT(B30,"dddd")) -> SÁBADO | D30: 0
C31: =UPPER(TEXT(B31,"dddd")) -> SÁBADO | D31: 669
C32: =UPPER(TEXT(B32,"dddd")) -> SÁBADO
D33: =SUM(D2:D32) -> 166330.47 | M33: DISTRIBUIÇÃO DA META | W33: DISTRIBUIÇÃO DA META | AG33: DISTRIBUIÇÃO DA META | AQ33: DISTRIBUIÇÃO DA META
N36: SEMANA 1 | Q36: SEMANA 2 | T36: SEMANA 3 | X36: SEMANA 1 | AA36: SEMANA 2 | AD36: SEMANA 3 | AH36: SEMANA 1 | AK36: SEMANA 2 | AN36: SEMANA 3 | AR36: SEMANA 1 | AU36: SEMANA 2 | AX36: SEMANA 3
M37: NÃO | N37: DOMINGO | O37: =IF(M37="SIM",$Q$14,"") | P37: NÃO | Q37: DOMINGO | R37: =IF(P37="SIM",$Q$14,"") | S37: NÃO | T37: DOMINGO | U37: =IF(S37="SIM",$Q$14,"") | W37: =M37 -> NÃO | X37: DOMINGO | Y37: =IF(W37="SIM",$AA$14,"") | Z37: =P37 -> NÃO | AA37: DOMINGO | AB37: =IF(Z37="SIM",$AA$14,"") | AC37: =S37 -> NÃO | AD37: DOMINGO | AE37: =IF(AC37="SIM",$Q$14,"") | AG37: =W37 -> NÃO | AH37: DOMINGO | AI37: =IF(AG37="SIM",$AK$14,"") | AJ37: =Z37 -> NÃO | AK37: DOMINGO | AL37: =IF(AJ37="SIM",$AK$14,"") | AM37: =AC37 -> NÃO | AN37: DOMINGO | AO37: =IF(AM37="SIM",$AK$14,"") | AQ37: =AG37 -> NÃO | AR37: DOMINGO | AS37: =IF(AQ37="SIM",$AU$14,"") | AT37: =AJ37 -> NÃO | AU37: DOMINGO | AV37: =IF(AT37="SIM",$AU$14,"") | AW37: =AM37 -> NÃO | AX37: DOMINGO | AY37: =IF(AW37="SIM",$AU$14,"")
M38: NÃO | N38: SEGUNDA-FEIRA | O38: =IF(M38="SIM",$Q$15,"") | P38: SIM | Q38: SEGUNDA-FEIRA | R38: =IF(P38="SIM",$Q$15,"") -> 4767.5176 | S38: SIM | T38: SEGUNDA-FEIRA | U38: =IF(S38="SIM",$Q$15,"") -> 4767.5176 | W38: =M38 -> NÃO | X38: SEGUNDA-FEIRA | Y38: =IF(W38="SIM",$AA$15,"") | Z38: =P38 -> SIM | AA38: SEGUNDA-FEIRA | AB38: =IF(Z38="SIM",$AA$15,"") -> 5789.1286 | AC38: =S38 -> SIM | AD38: SEGUNDA-FEIRA | AE38: =IF(AC38="SIM",$AA$15,"") -> 5789.1286 | AG38: =W38 -> NÃO | AH38: SEGUNDA-FEIRA | AI38: =IF(AG38="SIM",$AK$15,"") | AJ38: =Z38 -> SIM | AK38: SEGUNDA-FEIRA | AL38: =IF(AJ38="SIM",$AK$15,"") -> 6810.7395 | AM38: =AC38 -> SIM | AN38: SEGUNDA-FEIRA | AO38: =IF(AM38="SIM",$AK$15,"") -> 6810.7395 | AQ38: =AG38 -> NÃO | AR38: SEGUNDA-FEIRA | AS38: =IF(AQ38="SIM",$AU$15,"") | AT38: =AJ38 -> SIM | AU38: SEGUNDA-FEIRA | AV38: =IF(AT38="SIM",$AU$15,"") -> 7832.3504 | AW38: =AM38 -> SIM | AX38: SEGUNDA-FEIRA | AY38: =IF(AW38="SIM",$AU$15,"") -> 7832.3504
M39: NÃO | N39: TERÇA-FEIRA | O39: =IF(M39="SIM",$Q$16,"") | P39: SIM | Q39: TERÇA-FEIRA | R39: =IF(P39="SIM",$Q$16,"") -> 4768.9338 | S39: SIM | T39: TERÇA-FEIRA | U39: =IF(S39="SIM",$Q$16,"") -> 4768.9338 | W39: =M39 -> NÃO | X39: TERÇA-FEIRA | Y39: =IF(W39="SIM",$AA$16,"") | Z39: =P39 -> SIM | AA39: TERÇA-FEIRA | AB39: =IF(Z39="SIM",$AA$16,"") -> 5790.8482 | AC39: =S39 -> SIM | AD39: TERÇA-FEIRA | AE39: =IF(AC39="SIM",$AA$16,"") -> 5790.8482 | AG39: =W39 -> NÃO | AH39: TERÇA-FEIRA | AI39: =IF(AG39="SIM",$AK$16,"") | AJ39: =Z39 -> SIM | AK39: TERÇA-FEIRA | AL39: =IF(AJ39="SIM",$AK$16,"") -> 6812.7626 | AM39: =AC39 -> SIM | AN39: TERÇA-FEIRA | AO39: =IF(AM39="SIM",$AK$16,"") -> 6812.7626 | AQ39: =AG39 -> NÃO | AR39: TERÇA-FEIRA | AS39: =IF(AQ39="SIM",$AU$16,"") | AT39: =AJ39 -> SIM | AU39: TERÇA-FEIRA | AV39: =IF(AT39="SIM",$AU$16,"") -> 7834.677 | AW39: =AM39 -> SIM | AX39: TERÇA-FEIRA | AY39: =IF(AW39="SIM",$AU$16,"") -> 7834.677
M40: NÃO | N40: QUARTA-FEIRA | O40: =IF(M40="SIM",$Q$17,"") | P40: SIM | Q40: QUARTA-FEIRA | R40: =IF(P40="SIM",$Q$17,"") -> 5654.3789 | S40: SIM | T40: QUARTA-FEIRA | U40: =IF(S40="SIM",$Q$17,"") -> 5654.3789 | W40: =M40 -> NÃO | X40: QUARTA-FEIRA | Y40: =IF(W40="SIM",$AA$17,"") | Z40: =P40 -> SIM | AA40: QUARTA-FEIRA | AB40: =IF(Z40="SIM",$AA$17,"") -> 6866.0315 | AC40: =S40 -> SIM | AD40: QUARTA-FEIRA | AE40: =IF(AC40="SIM",$AA$17,"") -> 6866.0315 | AG40: =W40 -> NÃO | AH40: QUARTA-FEIRA | AI40: =IF(AG40="SIM",$AK$17,"") | AJ40: =Z40 -> SIM | AK40: QUARTA-FEIRA | AL40: =IF(AJ40="SIM",$AK$17,"") -> 8077.6841 | AM40: =AC40 -> SIM | AN40: QUARTA-FEIRA | AO40: =IF(AM40="SIM",$AK$17,"") -> 8077.6841 | AQ40: =AG40 -> NÃO | AR40: QUARTA-FEIRA | AS40: =IF(AQ40="SIM",$AU$17,"") | AT40: =AJ40 -> SIM | AU40: QUARTA-FEIRA | AV40: =IF(AT40="SIM",$AU$17,"") -> 9289.3368 | AW40: =AM40 -> SIM | AX40: QUARTA-FEIRA | AY40: =IF(AW40="SIM",$AU$17,"") -> 9289.3368
M41: NÃO | N41: QUINTA-FEIRA | O41: =IF(M41="SIM",$Q$18,"") | P41: SIM | Q41: QUINTA-FEIRA | R41: =IF(P41="SIM",$Q$18,"") -> 7079.689 | S41: SIM | T41: QUINTA-FEIRA | U41: =IF(S41="SIM",$Q$18,"") -> 7079.689 | W41: =M41 -> NÃO | X41: QUINTA-FEIRA | Y41: =IF(W41="SIM",$AA$18,"") | Z41: =P41 -> SIM | AA41: QUINTA-FEIRA | AB41: =IF(Z41="SIM",$AA$18,"") -> 8596.7652 | AC41: =S41 -> SIM | AD41: QUINTA-FEIRA | AE41: =IF(AC41="SIM",$AA$18,"") -> 8596.7652 | AG41: =W41 -> NÃO | AH41: QUINTA-FEIRA | AI41: =IF(AG41="SIM",$AK$18,"") | AJ41: =Z41 -> SIM | AK41: QUINTA-FEIRA | AL41: =IF(AJ41="SIM",$AK$18,"") -> 10113.841 | AM41: =AC41 -> SIM | AN41: QUINTA-FEIRA | AO41: =IF(AM41="SIM",$AK$18,"") -> 10113.841 | AQ41: =AG41 -> NÃO | AR41: QUINTA-FEIRA | AS41: =IF(AQ41="SIM",$AU$18,"") | AT41: =AJ41 -> SIM | AU41: QUINTA-FEIRA | AV41: =IF(AT41="SIM",$AU$18,"") -> 11630.918 | AW41: =AM41 -> SIM | AX41: QUINTA-FEIRA | AY41: =IF(AW41="SIM",$AU$18,"") -> 11630.918
M42: NÃO | N42: SEXTA-FEIRA | O42: =IF(M42="SIM",$Q$19,"") | P42: SIM | Q42: SEXTA-FEIRA | R42: =IF(P42="SIM",$Q$19,"") -> 6550.0506 | S42: SIM | T42: SEXTA-FEIRA | U42: =IF(S42="SIM",$Q$19,"") -> 6550.0506 | W42: =M42 -> NÃO | X42: SEXTA-FEIRA | Y42: =IF(W42="SIM",$AA$19,"") | Z42: =P42 -> SIM | AA42: SEXTA-FEIRA | AB42: =IF(Z42="SIM",$AA$19,"") -> 7953.6329 | AC42: =S42 -> SIM | AD42: SEXTA-FEIRA | AE42: =IF(AC42="SIM",$AA$19,"") -> 7953.6329 | AG42: =W42 -> NÃO | AH42: SEXTA-FEIRA | AI42: =IF(AG42="SIM",$AK$19,"") | AJ42: =Z42 -> SIM | AK42: SEXTA-FEIRA | AL42: =IF(AJ42="SIM",$AK$19,"") -> 9357.2152 | AM42: =AC42 -> SIM | AN42: SEXTA-FEIRA | AO42: =IF(AM42="SIM",$AK$19,"") -> 9357.2152 | AQ42: =AG42 -> NÃO | AR42: SEXTA-FEIRA | AS42: =IF(AQ42="SIM",$AU$19,"") | AT42: =AJ42 -> SIM | AU42: SEXTA-FEIRA | AV42: =IF(AT42="SIM",$AU$19,"") -> 10760.797 | AW42: =AM42 -> SIM | AX42: SEXTA-FEIRA | AY42: =IF(AW42="SIM",$AU$19,"") -> 10760.797
...

Sheet VENDAS_VENDEDOR
J1: VENDAS - METAS INDIVIDUAIS | O1: VENDAS - ONLINE | T1: QUANTIDADE DE VENDEDORAS | U1: % ONLINE
J2: META MÍNIMA | K2: TOP 1 | L2: TOP 2 | M2: MASTER | O2: META MÍNIMA | P2: TOP 1 | Q2: TOP 2 | R2: MASTER | T2: 4 | U2: 0.2
B3: METAS POR DIA | G3: RAISSA | J3: =Q6 -> 20000 | K3: =Q7 -> 26000 | L3: =Q8 -> 32000 | M3: =Q9 -> 36000 | O3: =R6 -> 22000 | P3: =R7 -> 28000 | Q3: =R8 -> 34000 | R3: =R9 -> 40000
B4: DATA | C4: DIA DA SEMANA | D4: VALOR REALIZADO | E4: VENDEDOR | G4: RAMLIZ
B5: =Tabela37[[#This Row],[DATA]] -> 46143 | C5: =UPPER(TEXT(B5,"dddd")) -> SEXTA-FEIRA | E5: RAISSA | G5: JULIA | Q5: META VENDEDORA | R5: ONLINE
B6: =Tabela37[[#This Row],[DATA]] -> 46144 | C6: =UPPER(TEXT(B6,"dddd")) -> SÁBADO | E6: RAISSA | G6: LETÍCIA | H6: VENDAS /MÊS DIFERENÇA | P6: MÍNIMA | Q6: ='ANÁLISE GERAL SOBRAL (2026)'!H21/(VENDAS_VENDEDOR!$T$2+1) -> 20000 | R6: ='ANÁLISE GERAL SOBRAL (2026)'!F21*VENDAS_VENDEDOR!$U$2 -> 22000
B7: =Tabela37[[#This Row],[DATA]] -> 46145 | C7: =UPPER(TEXT(B7,"dddd")) -> DOMINGO | E7: RAISSA | G7: LOJA | H7: VENDEDORA | I7: VALOR REALIZADO | J7: META MÍNIMA | K7: TOP 1 | L7: TOP 2 | M7: MASTER | P7: TOP 1 | Q7: ='ANÁLISE GERAL SOBRAL (2026)'!H22/(VENDAS_VENDEDOR!$T$2+1) -> 26000 | R7: ='ANÁLISE GERAL SOBRAL (2026)'!F22*VENDAS_VENDEDOR!$U$2 -> 28000
B8: =Tabela37[[#This Row],[DATA]] -> 46146 | C8: =UPPER(TEXT(B8,"dddd")) -> SEGUNDA-FEIRA | E8: RAISSA | G8: KETHLLEN | H8: RAISSA | I8: =SUMIFS($D$5:$D$151,$E$5:$E$151,H8) -> 0 | J8: =I8-$J$3 -> -20000 | K8: =I8-$K$3 -> -26000 | L8: =I8-$L$3 -> -32000 | M8: =I8-$M$3 -> -36000 | P8: TOP 2 | Q8: ='ANÁLISE GERAL SOBRAL (2026)'!H23/(VENDAS_VENDEDOR!$T$2+1) -> 32000 | R8: ='ANÁLISE GERAL SOBRAL (2026)'!F23*VENDAS_VENDEDOR!$U$2 -> 34000
B9: =Tabela37[[#This Row],[DATA]] -> 46147 | C9: =UPPER(TEXT(B9,"dddd")) -> TERÇA-FEIRA | E9: RAISSA | H9: RAMLIZ | I9: =SUMIFS($D$5:$D$151,$E$5:$E$151,H9) -> 0 | J9: =I9-$J$3 -> -20000 | K9: =I9-$K$3 -> -26000 | L9: =I9-$L$3 -> -32000 | M9: =I9-$M$3 -> -36000 | P9: MASTER | Q9: ='ANÁLISE GERAL SOBRAL (2026)'!H24/(VENDAS_VENDEDOR!$T$2+1) -> 36000 | R9: ='ANÁLISE GERAL SOBRAL (2026)'!F24*VENDAS_VENDEDOR!$U$2 -> 40000
B10: =Tabela37[[#This Row],[DATA]] -> 46148 | C10: =UPPER(TEXT(B10,"dddd")) -> QUARTA-FEIRA | E10: RAISSA | H10: LETÍCIA | I10: =SUMIFS($D$5:$D$151,$E$5:$E$151,H10) -> 0 | J10: =I10-$J$3 -> -20000 | K10: =I10-$K$3 -> -26000 | L10: =I10-$L$3 -> -32000 | M10: =I10-$M$3 -> -36000
B11: =Tabela37[[#This Row],[DATA]] -> 46149 | C11: =UPPER(TEXT(B11,"dddd")) -> QUINTA-FEIRA | E11: RAISSA | H11: KETHLLEN | I11: =SUMIFS($D$5:$D$151,$E$5:$E$151,H11) -> 0 | J11: =I11-$O$3 -> -22000 | K11: =I11-$P$3 -> -28000 | L11: =I11-$Q$3 -> -34000 | M11: =I11-$R$3 -> -40000
B12: =Tabela37[[#This Row],[DATA]] -> 46150 | C12: =UPPER(TEXT(B12,"dddd")) -> SEXTA-FEIRA | E12: RAISSA | H12: JULIA | I12: =SUMIFS($D$5:$D$151,$E$5:$E$151,H12) -> 0 | J12: =I12-$J$3 -> -20000 | K12: =I12-$K$3 -> -26000 | L12: =I12-$L$3 -> -32000 | M12: =I12-$M$3 -> -36000
B13: =Tabela37[[#This Row],[DATA]] -> 46151 | C13: =UPPER(TEXT(B13,"dddd")) -> SÁBADO | E13: RAISSA
B14: =Tabela37[[#This Row],[DATA]] -> 46152 | C14: =UPPER(TEXT(B14,"dddd")) -> DOMINGO | E14: RAISSA | I14: STATUS META
B15: =Tabela37[[#This Row],[DATA]] -> 46153 | C15: =UPPER(TEXT(B15,"dddd")) -> SEGUNDA-FEIRA | E15: RAISSA | I15: VENDEDORA | J15: META MÍNIMA | K15: TOP 1 | L15: TOP 2 | M15: MASTER
B16: =Tabela37[[#This Row],[DATA]] -> 46154 | C16: =UPPER(TEXT(B16,"dddd")) -> TERÇA-FEIRA | E16: RAISSA | I16: RAISSA | J16: =IF(J8>0,"BATEU","NÃO ALCANÇADO") -> NÃO ALCANÇADO | K16: =IF(K8>0,"BATEU","NÃO ALCANÇADO") -> NÃO ALCANÇADO | L16: =IF(L8>0,"BATEU","NÃO ALCANÇADO") -> NÃO ALCANÇADO | M16: =IF(M8>0,"BATEU","NÃO ALCANÇADO") -> NÃO ALCANÇADO
